Workbook

Sheet ABA
A1: Abacus | B1: Actuals 2025 | O1: 2026 Actual / Forecast | AC1: 2027 Forecast | AK1: YoY | AL1: YoY
B2: Jan | C2: Feb | D2: Mar | E2: Apr | F2: May | G2: Jun | H2: Jul | I2: Aug | J2: Sep | K2: Oct | L2: Nov | M2: Dec | N2: FY2025 Total | O2: Jan | P2: Feb | Q2: Mar | R2: Apr | S2: May | T2: Jun | U2: Jul | V2: Aug | W2: Sep | X2: Oct | Y2: Nov | Z2: Dec | AA2: YTD | AB2: FY2026 Outlook | AC2: Jan | AD2: Feb | AE2: Mar | AF2: Apr | AG2: May | AH2: Jun | AI2: Jul-Dec Proj. | AJ2: FY2027 | AK2: 25→26 % | AL2: 26→27 %
A3: INCOME
A4: Fee Income Regular | B4: 45121.08 | C4: 48317.09 | D4: 59604 | E4: 58999.57 | F4: 54973.4 | G4: 54200.75 | H4: 68470.83 | I4: 57893.73 | J4: 46302.96 | K4: 47210.81 | L4: 44551.63 | M4: 58823.32 | N4: =SUM(B4:M4) | O4: 51261.86 | P4: 47040 | Q4: 62383.2 | R4: 65608.49 | S4: 54732.77 | T4: 63533.84 | U4: 77254.32 | AA4: =SUM(O4:U4) | AB4: =SUM(O4:Z4) | AC4: 105589.88 | AD4: 122011.99 | AE4: 95286.97 | AF4: 109311.06 | AG4: 116010.76 | AH4: 110257.62 | AI4: =SUM(AC4:AH4) | AJ4: =SUM(AC4:AH4)+AI4 | AK4: =IF(N4<>0,(AB4-N4)/ABS(N4),0) | AL4: =IF(AB4<>0,(AJ4-AB4)/ABS(AB4),0)
A5: EEEF Embedded | B5: 11395.45 | C5: 30240.26 | D5: 33852.92 | E5: 11973.37 | F5: 11973.37 | G5: 44731.22 | H5: 40794.17 | I5: 0 | J5: 12746.69 | K5: 34548.74 | L5: 34548.75 | M5: 37093.27 | N5: =SUM(B5:M5) | O5: 16246.68 | P5: 45919.86 | Q5: 45919.86 | R5: 36357.78 | S5: 36357.78 | T5: 37136.04 | U5: 39324.86 | AA5: =SUM(O5:U5) | AB5: =SUM(O5:Z5) | AC5: 0 | AD5: 0 | AE5: 0 | AF5: 0 | AG5: 0 | AH5: 0 | AI5: =SUM(AC5:AH5) | AJ5: =SUM(AC5:AH5)+AI5 | AK5: =IF(N5<>0,(AB5-N5)/ABS(N5),0) | AL5: =IF(AB5<>0,(AJ5-AB5)/ABS(AB5),0)
A6: Other Income | B6: 1000 | C6: 0 | D6: 0 | E6: 240 | F6: 150 | G6: 150 | H6: 150 | I6: 150 | J6: 150 | K6: 150 | L6: 150 | M6: 150 | N6: =SUM(B6:M6) | O6: 650 | P6: 150 | Q6: 150 | R6: 150 | S6: 150 | T6: 150 | U6: 150 | AA6: =SUM(O6:U6) | AB6: =SUM(O6:Z6) | AC6: 0 | AD6: 0 | AE6: 0 | AF6: 0 | AG6: 0 | AH6: 0 | AI6: =SUM(AC6:AH6) | AJ6: =SUM(AC6:AH6)+AI6 | AK6: =IF(N6<>0,(AB6-N6)/ABS(N6),0) | AL6: =IF(AB6<>0,(AJ6-AB6)/ABS(AB6),0)
A7: Total Income | B7: =B4+B5+B6 | C7: =C4+C5+C6 | D7: =D4+D5+D6 | E7: =E4+E5+E6 | F7: =F4+F5+F6 | G7: =G4+G5+G6 | H7: =H4+H5+H6 | I7: =I4+I5+I6 | ... AJ7: =AJ4+AJ5+AJ6 | AK7: =IF(N7<>0,(AB7-N7)/ABS(N7),0) | AL7: =IF(AB7<>0,(AJ7-AB7)/ABS(AB7),0)
A9: DIRECT COSTS
A10: Personnel
A11: Nursery Salaries | B11: 31316.14 | C11: 32272.71 | D11: 33507.52 | E11: 35857.02 | F11: 36300.07 | G11: 37005.6 | H11: 38811.34 | I11: 36024.66 | J11: 35973.55 | K11: 34210.75 | L11: 33941.4 | M11: 34611.41 | N11: =SUM(B11:M11) | O11: 33098.55 | P11: 37530.83 | Q11: 38072.4 | R11: 42905.75 | S11: 44862.47 | T11: 42474.52 | U11: 44079.43 | AA11: =SUM(O11:U11) | AB11: =SUM(O11:Z11) | AC11: 44079.43 | AD11: 44079.43 | AE11: 44079.43 | AF11: 44079.43 | AG11: 44079.43 | AH11: 44079.43 | AI11: =SUM(AC11:AH11) | AJ11: =SUM(AC11:AH11)+AI11 | AK11: =IF(N11<>0,(AB11-N11)/ABS(N11),0) | AL11: =IF(AB11<>0,(AJ11-AB11)/ABS(AB11),0)
A12: Nursery NI | B12: 2200.8 | C12: 2181.6 | D12: 2265.66 | E12: 3434.81 | F12: 3452.56 | G12: 3639.83 | H12: 4034.6 | I12: 3525.03 | J12: 3409.27 | K12: 3148 | L12: 3079.55 | M12: 3438.39 | N12: =SUM(B12:M12) | O12: 3146.95 | P12: 3574.88 | Q12: 3481.84 | R12: 3882.54 | S12: 4221.13 | T12: 4123.59 | U12: 4289.92 | AA12: =SUM(O12:U12) | AB12: =SUM(O12:Z12) | AC12: 4289.92 | AD12: 4289.92 | AE12: 4289.92 | AF12: 4289.92 | AG12: 4289.92 | AH12: 4289.92 | AI12: =SUM(AC12:AH12) | AJ12: =SUM(AC12:AH12)+AI12 | AK12: =IF(N12<>0,(AB12-N12)/ABS(N12),0) | AL12: =IF(AB12<>0,(AJ12-AB12)/ABS(AB12),0)
A13: Nursery Pension | B13: 609.12 | C13: 604.7 | D13: 593.33 | E13: 633.2 | F13: 631.9 | G13: 716.47 | H13: 746.36 | I13: 648.61 | J13: 678.39 | K13: 624.58 | L13: 612.97 | M13: 624.69 | N13: =SUM(B13:M13) | O13: 571.62 | P13: 534.23 | Q13: 534.37 | R13: 564.58 | S13: 653.95 | T13: 674.11 | U13: 706.29 | AA13: =SUM(O13:U13) | AB13: =SUM(O13:Z13) | AC13: 706.29 | AD13: 706.29 | AE13: 706.29 | AF13: 706.29 | AG13: 706.29 | AH13: 706.29 | AI13: =SUM(AC13:AH13) | AJ13: =SUM(AC13:AH13)+AI13 | AK13: =IF(N13<>0,(AB13-N13)/ABS(N13),0) | AL13: =IF(AB13<>0,(AJ13-AB13)/ABS(AB13),0)
A14: Uniform | B14: 86.04 | C14: 0 | D14: 181.94 | E14: 0 | F14: 251.04 | G14: 85.92 | H14: 0 | I14: 0 | J14: 105.66 | K14: 0 | L14: 0 | M14: 0 | N14: =SUM(B14:M14) | O14: 371.7 | P14: 98.82 | Q14: 0 | R14: 203.82 | S14: 98.82 | T14: 263.64 | U14: 100.81 | AA14: =SUM(O14:U14) | AB14: =SUM(O14:Z14) | AC14: 173 | AD14: 173 | AE14: 173 | AF14: 173 | AG14: 173 | AH14: 173 | AI14: =SUM(AC14:AH14) | AJ14: =SUM(AC14:AH14)+AI14 | AK14: =IF(N14<>0,(AB14-N14)/ABS(N14),0) | AL14: =IF(AB14<>0,(AJ14-AB14)/ABS(AB14),0)
A15: Training | B15: 270 | C15: 66 | D15: 145 | E15: 29.43 | F15: 291.7 | G15: 0 | H15: 298.2 | I15: 0 | J15: 0 | K15: 123.5 | L15: 247.5 | M15: 176.67 | N15: =SUM(B15:M15) | O15: 295.67 | P15: 29.94 | Q15: 177.97 | R15: 857.74 | S15: 106 | T15: 468.5 | U15: 579.1 | AA15: =SUM(O15:U15) | AB15: =SUM(O15:Z15) | AC15: 323 | AD15: 323 | AE15: 323 | AF15: 323 | AG15: 323 | AH15: 323 | AI15: =SUM(AC15:AH15) | AJ15: =SUM(AC15:AH15)+AI15 | AK15: =IF(N15<>0,(AB15-N15)/ABS(N15),0) | AL15: =IF(AB15<>0,(AJ15-AB15)/ABS(AB15),0)
A16: Staff Welfare | B16: 92.7 | C16: 249.13 | D16: 279.46 | E16: 346.01 | F16: 289.41 | G16: 78.07 | H16: 604.42 | I16: 209.95 | J16: 136.72 | K16: 248.7 | L16: 246.42 | M16: 79.21 | N16: =SUM(B16:M16) | O16: 150.67 | P16: 252.42 | Q16: 238.57 | R16: 211.38 | S16: 213.69 | T16: 198.14 | U16: 358.37 | AA16: =SUM(O16:U16) | AB16: =SUM(O16:Z16) | AC16: 211 | AD16: 211 | AE16: 211 | AF16: 211 | AG16: 211 | AH16: 211 | AI16: =SUM(AC16:AH16) | AJ16: =SUM(AC16:AH16)+AI16 | AK16: =IF(N16<>0,(AB16-N16)/ABS(N16),0) | AL16: =IF(AB16<>0,(AJ16-AB16)/ABS(AB16),0)
A17: Recruitment | B17: 0 | C17: 0 | D17: 0 | E17: 0 | F17: 0 | G17: 0 | H17: 0 | I17: 0 | J17: 0 | K17: 0 | L17: 0 | M17: 0 | N17: =SUM(B17:M17) | O17: 0 | P17: 0 | Q17: 0 | R17: 0 | S17: 0 | T17: 0 | U17: 0 | V17: 0 | W17: 0 | X17: 0 | Y17: 0 | Z17: 0 | AA17: =SUM(O17:U17) | AB17: =SUM(O17:Z17) | AC17: 0 | AD17: 0 | AE17: 0 | AF17: 0 | AG17: 0 | AH17: 0 | AI17: =SUM(AC17:AH17) | AJ17: =SUM(AC17:AH17)+AI17 | AK17: =IF(N17<>0,(AB17-N17)/ABS(N17),0) | AL17: =IF(AB17<>0,(AJ17-AB17)/ABS(AB17),0)
A18: Rewards & Recognition | B18: 0 | C18: 0 | D18: 0 | E18: 0 | F18: 0 | G18: 0 | H18: 330 | I18: 25 | J18: 0 | K18: 48.95 | L18: 21.64 | M18: 218.89 | N18: =SUM(B18:M18) | O18: 106.69 | P18: 67.96 | Q18: 139.8 | R18: 111.47 | S18: 216.45 | T18: 83.25 | U18: 113.9 | AA18: =SUM(O18:U18) | AB18: =SUM(O18:Z18) | AC18: 121 | AD18: 121 | AE18: 121 | AF18: 121 | AG18: 121 | AH18: 121 | AI18: =SUM(AC18:AH18) | AJ18: =SUM(AC18:AH18)+AI18 | AK18: =IF(N18<>0,(AB18-N18)/ABS(N18),0) | AL18: =IF(AB18<>0,(AJ18-AB18)/ABS(AB18),0)
A19: Temps | B19: 0 | C19: 0 | D19: 0 | E19: 0 | F19: 0 | G19: 0 | H19: 0 | I19: 0 | J19: 0 | K19: 0 | L19: 0 | M19: 0 | N19: =SUM(B19:M19) | O19: 0 | P19: 0 | Q19: 0 | R19: 0 | S19: 0 | T19: 0 | U19: 0 | V19: 0 | W19: 0 | X19: 0 | Y19: 0 | Z19: 0 | AA19: =SUM(O19:U19) | AB19: =SUM(O19:Z19) | AC19: 0 | AD19: 0 | AE19: 0 | AF19: 0 | AG19: 0 | AH19: 0 | AI19: =SUM(AC19:AH19) | AJ19: =SUM(AC19:AH19)+AI19 | AK19: =IF(N19<>0,(AB19-N19)/ABS(N19),0) | AL19: =IF(AB19<>0,(AJ19-AB19)/ABS(AB19),0)
A20: Total Personnel | B20: =B11+B12+B13+B14+B15+B16+B17+B18+B19 | C20: =C11+C12+C13+C14+C15+C16+C17+C18+C19 | D20: =D11+D12+D13+D14+D15+D16+D17+D18+D19 | E20: =E11+E12+E13+E14+E15+E16+E17+E18+E19 | F20: =F11+F12+F13+F14+F15+F16+F17+F18+F19 | G20: =G11+G12+G13+G14+G15+G16+G17+G18+G19 | H20: =H11+H12+H13+H14+H15+H16+H17+H18+H19 | I20: =I11+I12+I13+I14+I15+I16+I17+I18+I19 | ... AJ20: =AJ11+AJ12+AJ13+AJ14+AJ15+AJ16+AJ17+AJ18+AJ19 | AK20: =IF(N20<>0,(AB20-N20)/ABS(N20),0) | AL20: =IF(AB20<>0,(AJ20-AB20)/ABS(AB20),0)
A21: Sal:Rev | B21: =IF(B7>0,B20/B7,0) | C21: =IF(C7>0,C20/C7,0) | D21: =IF(D7>0,D20/D7,0) | E21: =IF(E7>0,E20/E7,0) | F21: =IF(F7>0,F20/F7,0) | G21: =IF(G7>0,G20/G7,0) | H21: =IF(H7>0,H20/H7,0) | I21: =IF(I7>0,I20/I7,0) | ... AJ21: =IF(AJ7>0,AJ20/AJ7,0)
A23: Childcare
A24: Catering Costs | N24: =SUM(B24:M24) | O24: 1508.1 | P24: 1785.93 | Q24: 1663.75 | R24: 1925.35 | S24: 1813.7 | T24: 2243.37 | U24: 1983.4 | V24: 2224.935 | W24: 3005.0682 | X24: 3228.8766 | Y24: 3386.9226 | Z24: 3287.8974 | AA24: =SUM(O24:U24) | AB24: =SUM(O24:Z24) | AC24: 3357.7582 | AD24: 3879.9813 | AE24: 3030.1256 | AF24: 3476.0917 | AG24: 3689.1422 | AH24: 3506.1923 | AI24: =SUM(AC24:AH24) | AJ24: =SUM(AC24:AH24)+AI24 | AK24: =IF(N24<>0,(AB24-N24)/ABS(N24),0) | AL24: =IF(AB24<>0,(AJ24-AB24)/ABS(AB24),0)
A25: Toys and Games | B25: 91.51 | C25: 452.3 | D25: 327.22 | E25: 103.6 | F25: 851.51 | G25: 37.37 | H25: 2634.18 | I25: 1272.86 | J25: -132.59 | K25: 313.94 | L25: 334.54 | M25: 543.53 | N25: =SUM(B25:M25) | O25: 100.23 | P25: 133.83 | Q25: 501.26 | R25: 235.26 | S25: 513.58 | T25: 239.97 | U25: 555.67 | AA25: =SUM(O25:U25) | AB25: =SUM(O25:Z25) | AC25: 100 | AD25: 100 | AE25: 100 | AF25: 100 | AG25: 100 | AH25: 100 | AI25: =SUM(AC25:AH25) | AJ25: =SUM(AC25:AH25)+AI25 | AK25: =IF(N25<>0,(AB25-N25)/ABS(N25),0) | AL25: =IF(AB25<>0,(AJ25-AB25)/ABS(AB25),0)
A26: Art Materials | N26: =SUM(B26:M26) | O26: 303.04 | P26: 223.68 | Q26: 252.26 | R26: 79.11 | S26: 149.63 | T26: 291.66 | U26: 81 | V26: 296.658 | W26: 400.67576 | X26: 430.51688 | Y26: 451.58968 | Z26: 438.38632 | AA26: =SUM(O26:U26) | AB26: =SUM(O26:Z26) | AC26: 447.70109 | AD26: 517.33084 | AE26: 404.01675 | AF26: 463.47889 | AG26: 491.88562 | AH26: 467.49231 | AI26: =SUM(AC26:AH26) | AJ26: =SUM(AC26:AH26)+AI26 | AK26: =IF(N26<>0,(AB26-N26)/ABS(N26),0) | AL26: =IF(AB26<>0,(AJ26-AB26)/ABS(AB26),0)
A27: Nursery Stationery | B27: 94.15 | C27: 42.29 | D27: 57.79 | E27: 75.59 | F27: 44.53 | G27: 83.45 | H27: 34.42 | I27: 28.37 | J27: 31.5 | K27: 12.34 | L27: 338.1 | M27: 33.94 | N27: =SUM(B27:M27) | O27: 168.45 | P27: 260.32 | Q27: 107.71 | R27: 152.41 | S27: 36.04 | T27: 155.55 | U27: 55.27 | AA27: =SUM(O27:U27) | AB27: =SUM(O27:Z27) | AC27: 100 | AD27: 100 | AE27: 100 | AF27: 100 | AG27: 100 | AH27: 100 | AI27: =SUM(AC27:AH27) | AJ27: =SUM(AC27:AH27)+AI27 | AK27: =IF(N27<>0,(AB27-N27)/ABS(N27),0) | AL27: =IF(AB27<>0,(AJ27-AB27)/ABS(AB27),0)
A28: Nursery Equipment | B28: 189.9 | C28: 131.91 | D28: 63.11 | E28: 17.99 | F28: 140.72 | G28: 671.26 | H28: 453.3 | I28: 32.21 | J28: 25.47 | K28: 59.66 | L28: 94.7 | M28: 57.97 | N28: =SUM(B28:M28) | O28: 275.4 | P28: 107.01 | Q28: 152.55 | R28: 51.51 | S28: 816.79 | T28: 427.2 | U28: 120.7 | AA28: =SUM(O28:U28) | AB28: =SUM(O28:Z28) | AC28: 100 | AD28: 100 | AE28: 100 | AF28: 100 | AG28: 100 | AH28: 100 | AI28: =SUM(AC28:AH28) | AJ28: =SUM(AC28:AH28)+AI28 | AK28: =IF(N28<>0,(AB28-N28)/ABS(N28),0) | AL28: =IF(AB28<>0,(AJ28-AB28)/ABS(AB28),0)
A29: Nursery Consumables | N29: =SUM(B29:M29) | O29: 382.52 | P29: 459.73 | Q29: 663.45 | R29: 360.23 | S29: 640.16 | T29: 717.62 | U29: 558.66 | V29: 436.59102 | W29: 589.67376 | X29: 633.59088 | Y29: 664.60368 | Z29: 645.17232 | AA29: =SUM(O29:U29) | AB29: =SUM(O29:Z29) | AC29: 658.88085 | AD29: 761.35482 | AE29: 594.59069 | AF29: 682.10101 | AG29: 723.90714 | AH29: 688.00755 | AI29: =SUM(AC29:AH29) | AJ29: =SUM(AC29:AH29)+AI29 | AK29: =IF(N29<>0,(AB29-N29)/ABS(N29),0) | AL29: =IF(AB29<>0,(AJ29-AB29)/ABS(AB29),0)
A30: Total Childcare Costs | B30: =B24+B25+B26+B27+B28+B29 | C30: =C24+C25+C26+C27+C28+C29 | D30: =D24+D25+D26+D27+D28+D29 | E30: =E24+E25+E26+E27+E28+E29 | F30: =F24+F25+F26+F27+F28+F29 | G30: =G24+G25+G26+G27+G28+G29 | H30: =H24+H25+H26+H27+H28+H29 | I30: =I24+I25+I26+I27+I28+I29 | ... AJ30: =AJ24+AJ25+AJ26+AJ27+AJ28+AJ29 | AK30: =IF(N30<>0,(AB30-N30)/ABS(N30),0) | AL30: =IF(AB30<>0,(AJ30-AB30)/ABS(AB30),0)
A32: Premises & Admin
A33: Rent | B33: 0 | C33: 0 | D33: 0 | E33: 0 | F33: 0 | G33: 0 | H33: 0 | I33: 0 | J33: 0 | K33: 0 | L33: 0 | M33: 0 | N33: =SUM(B33:M33) | O33: 0 | P33: 0 | Q33: 0 | R33: 0 | S33: 0 | T33: 0 | U33: 0 | V33: 0 | W33: 0 | X33: 0 | Y33: 0 | Z33: 0 | AA33: =SUM(O33:U33) | AB33: =SUM(O33:Z33) | AC33: 0 | AD33: 0 | AE33: 0 | AF33: 0 | AG33: 0 | AH33: 0 | AI33: =SUM(AC33:AH33) | AJ33: =SUM(AC33:AH33)+AI33 | AK33: =IF(N33<>0,(AB33-N33)/ABS(N33),0) | AL33: =IF(AB33<>0,(AJ33-AB33)/ABS(AB33),0)
A34: Business Rates | B34: 1704.92 | C34: 1704.92 | D34: 1704.92 | E34: 1704.92 | F34: 1704.92 | G34: 1704.92 | H34: 1704.92 | I34: 1704.92 | J34: 1704.92 | K34: 1704.92 | L34: 1704.92 | M34: 1704.92 | N34: =SUM(B34:M34) | O34: 1704.91 | P34: 1704.91 | Q34: 1704.9 | R34: 1823.25 | S34: 1823.25 | T34: 1823.25 | U34: 1823.25 | AA34: =SUM(O34:U34) | AB34: =SUM(O34:Z34) | AC34: 1823.25 | AD34: 1823.25 | AE34: 1823.25 | AF34: 1823.25 | AG34: 1823.25 | AH34: 1823.25 | AI34: =SUM(AC34:AH34) | AJ34: =SUM(AC34:AH34)+AI34 | AK34: =IF(N34<>0,(AB34-N34)/ABS(N34),0) | AL34: =IF(AB34<>0,(AJ34-AB34)/ABS(AB34),0)
A35: Utilities | B35: 895.97 | C35: 27.47 | D35: 1315.56 | E35: 712.07 | F35: 4544.52 | G35: 684.57 | H35: 627.64 | I35: 514.2 | J35: -607.48 | K35: 4237.07 | L35: 769.03 | M35: 2369.66 | N35: =SUM(B35:M35) | O35: 899.42 | P35: 3128.63 | Q35: 1798.29 | R35: 1482.2 | S35: 906.43 | T35: 319.81 | U35: 724.03 | AA35: =SUM(O35:U35) | AB35: =SUM(O35:Z35) | AC35: 1429 | AD35: 1429 | AE35: 1429 | AF35: 1429 | AG35: 1429 | AH35: 1429 | AI35: =SUM(AC35:AH35) | AJ35: =SUM(AC35:AH35)+AI35 | AK35: =IF(N35<>0,(AB35-N35)/ABS(N35),0) | AL35: =IF(AB35<>0,(AJ35-AB35)/ABS(AB35),0)
A36: Repairs & Maintenance | B36: 46.95 | C36: 4832.91 | D36: 603.49 | E36: 179.64 | F36: 504.08 | G36: 1430 | H36: 0 | I36: 5.99 | J36: 14 | K36: 0 | L36: 55.29 | M36: 225.21 | N36: =SUM(B36:M36) | O36: 0 | P36: 57.06 | Q36: 9.14 | R36: 10.19 | S36: 141.97 | T36: 150.64 | U36: 415.34 | AA36: =SUM(O36:U36) | AB36: =SUM(O36:Z36) | AC36: 0 | AD36: 0 | AE36: 0 | AF36: 0 | AG36: 0 | AH36: 0 | AI36: =SUM(AC36:AH36) | AJ36: =SUM(AC36:AH36)+AI36 | AK36: =IF(N36<>0,(AB36-N36)/ABS(N36),0) | AL36: =IF(AB36<>0,(AJ36-AB36)/ABS(AB36),0)
A37: Cleaning | B37: 1610.41 | C37: 1341.28 | D37: 618.85 | E37: 1357.49 | F37: 1371.67 | G37: 703.42 | H37: 477.23 | I37: 1549.67 | J37: 1414.78 | K37: 1644.37 | L37: 1432.79 | M37: 1367.21 | N37: =SUM(B37:M37) | O37: 1432.83 | P37: 1526.79 | Q37: 1392.29 | R37: 1387.82 | S37: 235.62 | T37: 321.07 | U37: 332.24 | AA37: =SUM(O37:U37) | AB37: =SUM(O37:Z37) | AC37: 400 | AD37: 400 | AE37: 400 | AF37: 400 | AG37: 400 | AH37: 400 | AI37: =SUM(AC37:AH37) | AJ37: =SUM(AC37:AH37)+AI37 | AK37: =IF(N37<>0,(AB37-N37)/ABS(N37),0) | AL37: =IF(AB37<>0,(AJ37-AB37)/ABS(AB37),0)
A38: Waste Disposal | B38: 384.51 | C38: 339.51 | D38: 605.71 | E38: 354.44 | F38: 460.69 | G38: 328.31 | H38: 432.13 | I38: 328.31 | J38: 474.42 | K38: 328.32 | L38: 445.29 | M38: 381.72 | N38: =SUM(B38:M38) | O38: 335.82 | P38: 454.31 | Q38: 484.3 | R38: 586.95 | S38: 531.72 | T38: 247.26 | U38: 599.65 | AA38: =SUM(O38:U38) | AB38: =SUM(O38:Z38) | AC38: 400 | AD38: 400 | AE38: 400 | AF38: 400 | AG38: 400 | AH38: 400 | AI38: =SUM(AC38:AH38) | AJ38: =SUM(AC38:AH38)+AI38 | AK38: =IF(N38<>0,(AB38-N38)/ABS(N38),0) | AL38: =IF(AB38<>0,(AJ38-AB38)/ABS(AB38),0)
A39: Postage/Printing/Stationery | B39: 137.34 | C39: 73.97 | D39: 80.18 | E39: 84.23 | F39: 71.16 | G39: 66.28 | H39: 105.45 | I39: 71.08 | J39: 92.42 | K39: 81.83 | L39: 67.49 | M39: 78.18 | N39: =SUM(B39:M39) | O39: 56.7 | P39: 92.7 | Q39: 63.53 | R39: 87.16 | S39: 87.41 | T39: 180.51 | U39: 100.82 | AA39: =SUM(O39:U39) | AB39: =SUM(O39:Z39) | AC39: 106 | AD39: 106 | AE39: 106 | AF39: 106 | AG39: 106 | AH39: 106 | AI39: =SUM(AC39:AH39) | AJ39: =SUM(AC39:AH39)+AI39 | AK39: =IF(N39<>0,(AB39-N39)/ABS(N39),0) | AL39: =IF(AB39<>0,(AJ39-AB39)/ABS(AB39),0)
A40: Telephone | B40: 0 | C40: 0 | D40: 0 | E40: 0 | F40: 0 | G40: 0 | H40: 0 | I40: 0 | J40: 0 | K40: 0 | L40: 0 | M40: 0 | N40: =SUM(B40:M40) | O40: 0 | P40: 0 | Q40: 390 | R40: 0 | S40: 0 | T40: 0 | U40: 0 | AA40: =SUM(O40:U40) | AB40: =SUM(O40:Z40) | AC40: 0 | AD40: 0 | AE40: 0 | AF40: 0 | AG40: 0 | AH40: 0 | AI40: =SUM(AC40:AH40) | AJ40: =SUM(AC40:AH40)+AI40 | AK40: =IF(N40<>0,(AB40-N40)/ABS(N40),0) | AL40: =IF(AB40<>0,(AJ40-AB40)/ABS(AB40),0)
A41: Marketing | B41: 0 | C41: 0 | D41: 588.81 | E41: 0 | F41: 0 | G41: 45 | H41: 0 | I41: 45 | J41: 0 | K41: 0 | L41: 0 | M41: 0 | N41: =SUM(B41:M41) | O41: 135 | P41: 0 | Q41: 0 | R41: 147 | S41: 6.99 | T41: 220 | U41: 0 | AA41: =SUM(O41:U41) | AB41: =SUM(O41:Z41) | AC41: 106 | AD41: 106 | AE41: 106 | AF41: 106 | AG41: 106 | AH41: 106 | AI41: =SUM(AC41:AH41) | AJ41: =SUM(AC41:AH41)+AI41 | AK41: =IF(N41<>0,(AB41-N41)/ABS(N41),0) | AL41: =IF(AB41<>0,(AJ41-AB41)/ABS(AB41),0)
A42: Total Premises & Admin | B42: =B33+B34+B35+B36+B37+B38+B39+B40+B41 | C42: =C33+C34+C35+C36+C37+C38+C39+C40+C41 | D42: =D33+D34+D35+D36+D37+D38+D39+D40+D41 | E42: =E33+E34+E35+E36+E37+E38+E39+E40+E41 | F42: =F33+F34+F35+F36+F37+F38+F39+F40+F41 | G42: =G33+G34+G35+G36+G37+G38+G39+G40+G41 | H42: =H33+H34+H35+H36+H37+H38+H39+H40+H41 | I42: =I33+I34+I35+I36+I37+I38+I39+I40+I41 | ... AJ42: =AJ33+AJ34+AJ35+AJ36+AJ37+AJ38+AJ39+AJ40+AJ41 | AK42: =IF(N42<>0,(AB42-N42)/ABS(N42),0) | AL42: =IF(AB42<>0,(AJ42-AB42)/ABS(AB42),0)
A44: Total Direct Costs | AK44: =IF(N44<>0,(AB44-N44)/ABS(N44),0) | AL44: =IF(AB44<>0,(AJ44-AB44)/ABS(AB44),0)
...

Sheet BK
A1: Bees Knees | B1: Actuals 2025 | O1: 2026 Actual / Forecast | AC1: 2027 Forecast | AK1: YoY | AL1: YoY
B2: Jan | C2: Feb | D2: Mar | E2: Apr | F2: May | G2: Jun | H2: Jul | I2: Aug | J2: Sep | K2: Oct | L2: Nov | M2: Dec | N2: FY2025 Total | O2: Jan | P2: Feb | Q2: Mar | R2: Apr | S2: May | T2: Jun | U2: Jul | V2: Aug | W2: Sep | X2: Oct | Y2: Nov | Z2: Dec | AA2: YTD | AB2: FY2026 Outlook | AC2: Jan | AD2: Feb | AE2: Mar | AF2: Apr | AG2: May | AH2: Jun | AI2: Jul-Dec Proj. | AJ2: FY2027 | AK2: 25→26 % | AL2: 26→27 %
A3: INCOME
A4: Fee Income Regular | B4: 28822.91 | C4: 27527.48 | D4: 31969.83 | E4: 35157.71 | F4: 28423.99 | G4: 26822.46 | H4: 35071.73 | I4: 29292.16 | J4: 20414.75 | K4: 19819.13 | L4: 18348.67 | M4: 27249.99 | N4: =SUM(B4:M4) | O4: 23326.9 | P4: 20657.48 | Q4: 21148.33 | R4: 24565.23 | S4: 21826.64 | T4: 23094.61 | U4: 27100.72 | AA4: =SUM(O4:U4) | AB4: =SUM(O4:Z4) | AC4: 33849.27 | AD4: 40863.29 | AE4: 33168.87 | AF4: 37302.1 | AG4: 39624.94 | AH4: 49227.72 | AI4: =SUM(AC4:AH4) | AJ4: =SUM(AC4:AH4)+AI4 | AK4: =IF(N4<>0,(AB4-N4)/ABS(N4),0) | AL4: =IF(AB4<>0,(AJ4-AB4)/ABS(AB4),0)
A5: EEEF Embedded | B5: 8562.4 | C5: 8562.4 | D5: 33256.45 | E5: 10591.2 | F5: 10591.2 | G5: 21480.3 | H5: 21480.3 | I5: 0 | J5: 15872.22 | K5: 15872.22 | L5: 18615.75 | M5: 19798.35 | N5: =SUM(B5:M5) | O5: 18772.32 | P5: 23544.12 | Q5: 23544.12 | R5: 16732.05 | S5: 16732.05 | T5: 18043.28 | U5: 18043.28 | AA5: =SUM(O5:U5) | AB5: =SUM(O5:Z5) | AC5: 0 | AD5: 0 | AE5: 0 | AF5: 0 | AG5: 0 | AH5: 0 | AI5: =SUM(AC5:AH5) | AJ5: =SUM(AC5:AH5)+AI5 | AK5: =IF(N5<>0,(AB5-N5)/ABS(N5),0) | AL5: =IF(AB5<>0,(AJ5-AB5)/ABS(AB5),0)
A6: Other Income | B6: 100 | C6: 0 | D6: 100 | E6: 300 | F6: 0 | G6: 300 | H6: 0 | I6: 2568.76 | J6: 450 | K6: 150 | L6: 300 | M6: 300 | N6: =SUM(B6:M6) | O6: 650 | P6: 150 | Q6: 300 | R6: 150 | S6: 150 | T6: 0 | U6: 300 | AA6: =SUM(O6:U6) | AB6: =SUM(O6:Z6) | AC6: 0 | AD6: 0 | AE6: 0 | AF6: 0 | AG6: 0 | AH6: 0 | AI6: =SUM(AC6:AH6) | AJ6: =SUM(AC6:AH6)+AI6 | AK6: =IF(N6<>0,(AB6-N6)/ABS(N6),0) | AL6: =IF(AB6<>0,(AJ6-AB6)/ABS(AB6),0)
A7: Total Income | B7: =B4+B5+B6 | C7: =C4+C5+C6 | D7: =D4+D5+D6 | E7: =E4+E5+E6 | F7: =F4+F5+F6 | G7: =G4+G5+G6 | H7: =H4+H5+H6 | I7: =I4+I5+I6 | ... AJ7: =AJ4+AJ5+AJ6 | AK7: =IF(N7<>0,(AB7-N7)/ABS(N7),0) | AL7: =IF(AB7<>0,(AJ7-AB7)/ABS(AB7),0)
A9: DIRECT COSTS
A10: Personnel
A11: Nursery Salaries | B11: 17812.5 | C11: 17339.68 | D11: 20177.72 | E11: 22232.54 | F11: 22270.94 | G11: 23588.71 | H11: 23343.5 | I11: 23511.85 | J11: 20681.56 | K11: 22301.58 | L11: 19748.45 | M11: 21714.13 | N11: =SUM(B11:M11) | O11: 22032.4 | P11: 23448.09 | Q11: 21766.47 | R11: 24395.78 | S11: 23187.74 | T11: 23614.63 | U11: 23226.6 | AA11: =SUM(O11:U11) | AB11: =SUM(O11:Z11) | AC11: 23226.6 | AD11: 23226.6 | AE11: 23226.6 | AF11: 23226.6 | AG11: 23226.6 | AH11: 23226.6 | AI11: =SUM(AC11:AH11) | AJ11: =SUM(AC11:AH11)+AI11 | AK11: =IF(N11<>0,(AB11-N11)/ABS(N11),0) | AL11: =IF(AB11<>0,(AJ11-AB11)/ABS(AB11),0)
A12: Nursery NI | B12: 1475.26 | C12: 1417.07 | D12: 1686.46 | E12: 2563.92 | F12: 2567.89 | G12: 2767.34 | H12: 2749.77 | I12: 2755.82 | J12: 2340.87 | K12: 2518.95 | L12: 2309.57 | M12: 2480.48 | N12: =SUM(B12:M12) | O12: 2577.7 | P12: 2679.93 | Q12: 2363.36 | R12: 2662.5 | S12: 2390.53 | T12: 2246.22 | U12: 2177.1 | AA12: =SUM(O12:U12) | AB12: =SUM(O12:Z12) | AC12: 2177.1 | AD12: 2177.1 | AE12: 2177.1 | AF12: 2177.1 | AG12: 2177.1 | AH12: 2177.1 | AI12: =SUM(AC12:AH12) | AJ12: =SUM(AC12:AH12)+AI12 | AK12: =IF(N12<>0,(AB12-N12)/ABS(N12),0) | AL12: =IF(AB12<>0,(AJ12-AB12)/ABS(AB12),0)
A13: Nursery Pension | B13: 347.13 | C13: 330.13 | D13: 333.41 | E13: 342.51 | F13: 397.67 | G13: 473.08 | H13: 489.34 | I13: 523.31 | J13: 440.32 | K13: 418.9 | L13: 382.73 | M13: 421.57 | N13: =SUM(B13:M13) | O13: 404.05 | P13: 451.49 | Q13: 394.61 | R13: 507.74 | S13: 453.36 | T13: 427.58 | U13: 413.76 | AA13: =SUM(O13:U13) | AB13: =SUM(O13:Z13) | AC13: 413.76 | AD13: 413.76 | AE13: 413.76 | AF13: 413.76 | AG13: 413.76 | AH13: 413.76 | AI13: =SUM(AC13:AH13) | AJ13: =SUM(AC13:AH13)+AI13 | AK13: =IF(N13<>0,(AB13-N13)/ABS(N13),0) | AL13: =IF(AB13<>0,(AJ13-AB13)/ABS(AB13),0)
A14: Uniform | B14: 0 | C14: 59.28 | D14: 0 | E14: 105.18 | F14: 155.4 | G14: 104.69 | H14: 11.99 | I14: 0 | J14: 0 | K14: 0 | L14: 0 | M14: 401.76 | N14: =SUM(B14:M14) | O14: 0 | P14: 38.12 | Q14: 85.02 | R14: 51.5 | S14: 0 | T14: 0 | U14: 110.94 | AA14: =SUM(O14:U14) | AB14: =SUM(O14:Z14) | AC14: 50 | AD14: 50 | AE14: 50 | AF14: 50 | AG14: 50 | AH14: 50 | AI14: =SUM(AC14:AH14) | AJ14: =SUM(AC14:AH14)+AI14 | AK14: =IF(N14<>0,(AB14-N14)/ABS(N14),0) | AL14: =IF(AB14<>0,(AJ14-AB14)/ABS(AB14),0)
A15: Training | B15: 57 | C15: 0 | D15: 0 | E15: 0 | F15: 0 | G15: 24 | H15: 0 | I15: 33 | J15: 0 | K15: 684 | L15: 172.6 | M15: 384 | N15: =SUM(B15:M15) | O15: 0 | P15: 114 | Q15: 480 | R15: 0 | S15: 0 | T15: 0 | U15: 83.88 | AA15: =SUM(O15:U15) | AB15: =SUM(O15:Z15) | AC15: 0 | AD15: 0 | AE15: 0 | AF15: 0 | AG15: 0 | AH15: 0 | AI15: =SUM(AC15:AH15) | AJ15: =SUM(AC15:AH15)+AI15 | AK15: =IF(N15<>0,(AB15-N15)/ABS(N15),0) | AL15: =IF(AB15<>0,(AJ15-AB15)/ABS(AB15),0)
A16: Staff Welfare | B16: 53.68 | C16: 350.21 | D16: 17.06 | E16: 46.05 | F16: 300.11 | G16: 272.05 | H16: 224.64 | I16: 246.79 | J16: 129.2 | K16: 88.43 | L16: 342.9 | M16: 243.13 | N16: =SUM(B16:M16) | O16: 727.69 | P16: 91.99 | Q16: 354.17 | R16: 348.94 | S16: 77.08 | T16: 154.95 | U16: 550.89 | AA16: =SUM(O16:U16) | AB16: =SUM(O16:Z16) | AC16: 80 | AD16: 80 | AE16: 80 | AF16: 80 | AG16: 80 | AH16: 80 | AI16: =SUM(AC16:AH16) | AJ16: =SUM(AC16:AH16)+AI16 | AK16: =IF(N16<>0,(AB16-N16)/ABS(N16),0) | AL16: =IF(AB16<>0,(AJ16-AB16)/ABS(AB16),0)
A17: Recruitment | B17: 0 | C17: 0 | D17: 0 | E17: 0 | F17: 0 | G17: 0 | H17: 0 | I17: 0 | J17: 3861 | K17: 0 | L17: 0 | M17: 0 | N17: =SUM(B17:M17) | O17: 0 | P17: 0 | Q17: 0 | R17: 0 | S17: 0 | T17: 0 | U17: 0 | V17: 0 | W17: 0 | X17: 0 | Y17: 0 | Z17: 0 | AA17: =SUM(O17:U17) | AB17: =SUM(O17:Z17) | AC17: 0 | AD17: 0 | AE17: 0 | AF17: 0 | AG17: 0 | AH17: 0 | AI17: =SUM(AC17:AH17) | AJ17: =SUM(AC17:AH17)+AI17 | AK17: =IF(N17<>0,(AB17-N17)/ABS(N17),0) | AL17: =IF(AB17<>0,(AJ17-AB17)/ABS(AB17),0)
A18: Rewards & Recognition | B18: 0 | C18: 0 | D18: 0 | E18: 0 | F18: 0 | G18: 0 | H18: 12.8 | I18: 0 | J18: 22.88 | K18: 0 | L18: 50.97 | M18: 88.44 | N18: =SUM(B18:M18) | O18: 0 | P18: 0 | Q18: 0 | R18: 55.97 | S18: 47.98 | T18: 7.99 | U18: 38.98 | AA18: =SUM(O18:U18) | AB18: =SUM(O18:Z18) | AC18: 33 | AD18: 33 | AE18: 33 | AF18: 33 | AG18: 33 | AH18: 33 | AI18: =SUM(AC18:AH18) | AJ18: =SUM(AC18:AH18)+AI18 | AK18: =IF(N18<>0,(AB18-N18)/ABS(N18),0) | AL18: =IF(AB18<>0,(AJ18-AB18)/ABS(AB18),0)
A19: Temps | B19: 0 | C19: 0 | D19: 0 | E19: 0 | F19: 0 | G19: 0 | H19: 0 | I19: 0 | J19: 0 | K19: 475.44 | L19: 0 | M19: 0 | N19: =SUM(B19:M19) | O19: 0 | P19: 0 | Q19: 0 | R19: 0 | S19: 0 | T19: 0 | U19: 0 | V19: 0 | W19: 0 | X19: 0 | Y19: 0 | Z19: 0 | AA19: =SUM(O19:U19) | AB19: =SUM(O19:Z19) | AC19: 0 | AD19: 0 | AE19: 0 | AF19: 0 | AG19: 0 | AH19: 0 | AI19: =SUM(AC19:AH19) | AJ19: =SUM(AC19:AH19)+AI19 | AK19: =IF(N19<>0,(AB19-N19)/ABS(N19),0) | AL19: =IF(AB19<>0,(AJ19-AB19)/ABS(AB19),0)
A20: Total Personnel | B20: =B11+B12+B13+B14+B15+B16+B17+B18+B19 | C20: =C11+C12+C13+C14+C15+C16+C17+C18+C19 | D20: =D11+D12+D13+D14+D15+D16+D17+D18+D19 | E20: =E11+E12+E13+E14+E15+E16+E17+E18+E19 | F20: =F11+F12+F13+F14+F15+F16+F17+F18+F19 | G20: =G11+G12+G13+G14+G15+G16+G17+G18+G19 | H20: =H11+H12+H13+H14+H15+H16+H17+H18+H19 | I20: =I11+I12+I13+I14+I15+I16+I17+I18+I19 | ... AJ20: =AJ11+AJ12+AJ13+AJ14+AJ15+AJ16+AJ17+AJ18+AJ19 | AK20: =IF(N20<>0,(AB20-N20)/ABS(N20),0) | AL20: =IF(AB20<>0,(AJ20-AB20)/ABS(AB20),0)
A21: Sal:Rev | B21: =IF(B7>0,B20/B7,0) | C21: =IF(C7>0,C20/C7,0) | D21: =IF(D7>0,D20/D7,0) | E21: =IF(E7>0,E20/E7,0) | F21: =IF(F7>0,F20/F7,0) | G21: =IF(G7>0,G20/G7,0) | H21: =IF(H7>0,H20/H7,0) | I21: =IF(I7>0,I20/I7,0) | ... AJ21: =IF(AJ7>0,AJ20/AJ7,0)
A23: Childcare
A24: Catering Costs | N24: =SUM(B24:M24) | O24: 930.57 | P24: 1165.35 | Q24: 1341.06 | R24: 1180.59 | S24: 1129.19 | T24: 1238.46 | U24: 1343.35 | V24: 710.6112 | W24: 1009.2582 | X24: 1029.8808 | Y24: 989.6952 | Z24: 926.5464 | AA24: =SUM(O24:U24) | AB24: =SUM(O24:Z24) | AC24: 1056.0972 | AD24: 1274.9346 | AE24: 1034.8687 | AF24: 1163.8255 | AG24: 1236.2981 | AH24: 1535.9049 | AI24: =SUM(AC24:AH24) | AJ24: =SUM(AC24:AH24)+AI24 | AK24: =IF(N24<>0,(AB24-N24)/ABS(N24),0) | AL24: =IF(AB24<>0,(AJ24-AB24)/ABS(AB24),0)
A25: Toys and Games | B25: 85.72 | C25: 41.49 | D25: 55.22 | E25: 133.77 | F25: 115.2 | G25: 40.97 | H25: 119.18 | I25: 0 | J25: 937.39 | K25: 75.82 | L25: 34 | M25: 44.21 | N25: =SUM(B25:M25) | O25: 158.33 | P25: 73.69 | Q25: 139.02 | R25: 64.23 | S25: 65.86 | T25: 40.92 | U25: 61.05 | AA25: =SUM(O25:U25) | AB25: =SUM(O25:Z25) | AC25: 50 | AD25: 50 | AE25: 50 | AF25: 50 | AG25: 50 | AH25: 50 | AI25: =SUM(AC25:AH25) | AJ25: =SUM(AC25:AH25)+AI25 | AK25: =IF(N25<>0,(AB25-N25)/ABS(N25),0) | AL25: =IF(AB25<>0,(AJ25-AB25)/ABS(AB25),0)
A26: Art Materials | N26: =SUM(B26:M26) | O26: 36.95 | P26: 132.23 | Q26: 184.1 | R26: 15.97 | S26: 0 | T26: 39.16 | U26: 29.81 | V26: 94.74816 | W26: 134.56776 | X26: 137.31744 | Y26: 131.95936 | Z26: 123.53952 | AA26: =SUM(O26:U26) | AB26: =SUM(O26:Z26) | AC26: 140.81296 | AD26: 169.99129 | AE26: 137.9825 | AF26: 155.17674 | AG26: 164.83975 | AH26: 204.78732 | AI26: =SUM(AC26:AH26) | AJ26: =SUM(AC26:AH26)+AI26 | AK26: =IF(N26<>0,(AB26-N26)/ABS(N26),0) | AL26: =IF(AB26<>0,(AJ26-AB26)/ABS(AB26),0)
A27: Nursery Stationery | B27: 7.64 | C27: 23.2 | D27: 31.14 | E27: 14.94 | F27: 11.95 | G27: 23.88 | H27: 107.69 | I27: 201.64 | J27: 13.58 | K27: 61.35 | L27: 13.78 | M27: 158.03 | N27: =SUM(B27:M27) | O27: 72.57 | P27: 85.8 | Q27: 0 | R27: 49.71 | S27: 47.25 | T27: 25.12 | U27: 15.98 | AA27: =SUM(O27:U27) | AB27: =SUM(O27:Z27) | AC27: 50 | AD27: 50 | AE27: 50 | AF27: 50 | AG27: 50 | AH27: 50 | AI27: =SUM(AC27:AH27) | AJ27: =SUM(AC27:AH27)+AI27 | AK27: =IF(N27<>0,(AB27-N27)/ABS(N27),0) | AL27: =IF(AB27<>0,(AJ27-AB27)/ABS(AB27),0)
A28: Nursery Equipment | B28: 7.99 | C28: 25.96 | D28: 0 | E28: 57.87 | F28: 0 | G28: 152.18 | H28: 18.98 | I28: 40.86 | J28: 0 | K28: 337.45 | L28: 777.25 | M28: 160.58 | N28: =SUM(B28:M28) | O28: 42.68 | P28: 26.97 | Q28: 40.95 | R28: 46.3 | S28: 49.99 | T28: 44.99 | U28: 0 | AA28: =SUM(O28:U28) | AB28: =SUM(O28:Z28) | AC28: 50 | AD28: 50 | AE28: 50 | AF28: 50 | AG28: 50 | AH28: 50 | AI28: =SUM(AC28:AH28) | AJ28: =SUM(AC28:AH28)+AI28 | AK28: =IF(N28<>0,(AB28-N28)/ABS(N28),0) | AL28: =IF(AB28<>0,(AJ28-AB28)/ABS(AB28),0)
A29: Nursery Consumables | N29: =SUM(B29:M29) | O29: 175.68 | P29: 336.46 | Q29: 254.99 | R29: 144.3 | S29: 200.22 | T29: 395.74 | U29: 20.35 | V29: 94.74816 | W29: 134.56776 | X29: 137.31744 | Y29: 131.95936 | Z29: 123.53952 | AA29: =SUM(O29:U29) | AB29: =SUM(O29:Z29) | AC29: 140.81296 | AD29: 169.99129 | AE29: 137.9825 | AF29: 155.17674 | AG29: 164.83975 | AH29: 204.78732 | AI29: =SUM(AC29:AH29) | AJ29: =SUM(AC29:AH29)+AI29 | AK29: =IF(N29<>0,(AB29-N29)/ABS(N29),0) | AL29: =IF(AB29<>0,(AJ29-AB29)/ABS(AB29),0)
A30: Total Childcare Costs | B30: =B24+B25+B26+B27+B28+B29 | C30: =C24+C25+C26+C27+C28+C29 | D30: =D24+D25+D26+D27+D28+D29 | E30: =E24+E25+E26+E27+E28+E29 | F30: =F24+F25+F26+F27+F28+F29 | G30: =G24+G25+G26+G27+G28+G29 | H30: =H24+H25+H26+H27+H28+H29 | I30: =I24+I25+I26+I27+I28+I29 | ... AJ30: =AJ24+AJ25+AJ26+AJ27+AJ28+AJ29 | AK30: =IF(N30<>0,(AB30-N30)/ABS(N30),0) | AL30: =IF(AB30<>0,(AJ30-AB30)/ABS(AB30),0)
A32: Premises & Admin
A33: Rent | B33: 0 | C33: 0 | D33: 0 | E33: 0 | F33: 0 | G33: 0 | H33: 0 | I33: 0 | J33: 0 | K33: 0 | L33: 0 | M33: 0 | N33: =SUM(B33:M33) | O33: 0 | P33: 0 | Q33: 0 | R33: 0 | S33: 0 | T33: 0 | U33: 0 | V33: 0 | W33: 0 | X33: 0 | Y33: 0 | Z33: 0 | AA33: =SUM(O33:U33) | AB33: =SUM(O33:Z33) | AC33: 0 | AD33: 0 | AE33: 0 | AF33: 0 | AG33: 0 | AH33: 0 | AI33: =SUM(AC33:AH33) | AJ33: =SUM(AC33:AH33)+AI33 | AK33: =IF(N33<>0,(AB33-N33)/ABS(N33),0) | AL33: =IF(AB33<>0,(AJ33-AB33)/ABS(AB33),0)
A34: Business Rates | B34: 1060.38 | C34: 1060.38 | D34: 1060.38 | E34: 1060.38 | F34: 1060.38 | G34: 1060.38 | H34: 1060.38 | I34: 1060.38 | J34: 1060.38 | K34: 1060.38 | L34: 1060.38 | M34: 1060.38 | N34: =SUM(B34:M34) | O34: 1060.36 | P34: 1060.36 | Q34: 1060.36 | R34: 1178.67 | S34: 1178.67 | T34: 1178.67 | U34: 1178.67 | AA34: =SUM(O34:U34) | AB34: =SUM(O34:Z34) | AC34: 1178.6667 | AD34: 1178.6667 | AE34: 1178.6667 | AF34: 1178.6667 | AG34: 1178.6667 | AH34: 1178.6667 | AI34: =SUM(AC34:AH34) | AJ34: =SUM(AC34:AH34)+AI34 | AK34: =IF(N34<>0,(AB34-N34)/ABS(N34),0) | AL34: =IF(AB34<>0,(AJ34-AB34)/ABS(AB34),0)
A35: Utilities | B35: 1084.35 | C35: 1856.09 | D35: 680.11 | E35: 1041.36 | F35: 1404.7 | G35: 49.78 | H35: 566.46 | I35: 748.44 | J35: 123.63 | K35: 557.7 | L35: 914.73 | M35: 843.45 | N35: =SUM(B35:M35) | O35: 976.88 | P35: 1232.13 | Q35: 699.24 | R35: 870 | S35: 652.42 | T35: 416.51 | U35: 537.13 | AA35: =SUM(O35:U35) | AB35: =SUM(O35:Z35) | AC35: 808 | AD35: 808 | AE35: 808 | AF35: 808 | AG35: 808 | AH35: 808 | AI35: =SUM(AC35:AH35) | AJ35: =SUM(AC35:AH35)+AI35 | AK35: =IF(N35<>0,(AB35-N35)/ABS(N35),0) | AL35: =IF(AB35<>0,(AJ35-AB35)/ABS(AB35),0)
A36: Repairs & Maintenance | B36: 1970.4 | C36: 4574.36 | D36: 3343.43 | E36: 2248.52 | F36: 1000.26 | G36: 36.5 | H36: 1663.64 | I36: 470.86 | J36: 14.64 | K36: 856.82 | L36: 36 | M36: 171.36 | N36: =SUM(B36:M36) | O36: 0 | P36: 0 | Q36: 9.98 | R36: 0 | S36: 29.27 | T36: 121.79 | U36: 108 | AA36: =SUM(O36:U36) | AB36: =SUM(O36:Z36) | AC36: 0 | AD36: 0 | AE36: 0 | AF36: 0 | AG36: 0 | AH36: 0 | AI36: =SUM(AC36:AH36) | AJ36: =SUM(AC36:AH36)+AI36 | AK36: =IF(N36<>0,(AB36-N36)/ABS(N36),0) | AL36: =IF(AB36<>0,(AJ36-AB36)/ABS(AB36),0)
A37: Cleaning | B37: 188.6 | C37: 249.73 | D37: 292.16 | E37: 49.57 | F37: 542.98 | G37: 335.03 | H37: 284.16 | I37: 299.86 | J37: 559.89 | K37: 291.24 | L37: 101.59 | M37: 113.21 | N37: =SUM(B37:M37) | O37: 203.38 | P37: 611.38 | Q37: 303.73 | R37: 143.24 | S37: 217.05 | T37: 365.89 | U37: 206.52 | AA37: =SUM(O37:U37) | AB37: =SUM(O37:Z37) | AC37: 310 | AD37: 310 | AE37: 310 | AF37: 310 | AG37: 310 | AH37: 310 | AI37: =SUM(AC37:AH37) | AJ37: =SUM(AC37:AH37)+AI37 | AK37: =IF(N37<>0,(AB37-N37)/ABS(N37),0) | AL37: =IF(AB37<>0,(AJ37-AB37)/ABS(AB37),0)
A38: Waste Disposal | B38: 332.71 | C38: 364.75 | D38: 380.11 | E38: 561.51 | F38: 426.52 | G38: 400.96 | H38: 339.75 | I38: 354.05 | J38: 630.66 | K38: 354.05 | L38: 404.45 | M38: 415.26 | N38: =SUM(B38:M38) | O38: 354.05 | P38: 363.36 | Q38: 474.96 | R38: 471.4 | S38: 390.36 | T38: 255.3 | U38: 494.27 | AA38: =SUM(O38:U38) | AB38: =SUM(O38:Z38) | AC38: 385 | AD38: 385 | AE38: 385 | AF38: 385 | AG38: 385 | AH38: 385 | AI38: =SUM(AC38:AH38) | AJ38: =SUM(AC38:AH38)+AI38 | AK38: =IF(N38<>0,(AB38-N38)/ABS(N38),0) | AL38: =IF(AB38<>0,(AJ38-AB38)/ABS(AB38),0)
A39: Postage/Printing/Stationery | B39: 52.03 | C39: 23.34 | D39: 21.74 | E39: 61.92 | F39: 81.43 | G39: 32.69 | H39: 84.15 | I39: 53.12 | J39: 75.13 | K39: 81.79 | L39: 68.57 | M39: 86.96 | N39: =SUM(B39:M39) | O39: 87.21 | P39: 82.62 | Q39: 91.56 | R39: 93.77 | S39: 73.19 | T39: 98.51 | U39: 78.42 | AA39: =SUM(O39:U39) | AB39: =SUM(O39:Z39) | AC39: 0 | AD39: 0 | AE39: 0 | AF39: 0 | AG39: 0 | AH39: 0 | AI39: =SUM(AC39:AH39) | AJ39: =SUM(AC39:AH39)+AI39 | AK39: =IF(N39<>0,(AB39-N39)/ABS(N39),0) | AL39: =IF(AB39<>0,(AJ39-AB39)/ABS(AB39),0)
A40: Telephone | B40: 0 | C40: 0 | D40: 0 | E40: 0 | F40: 0 | G40: 0 | H40: 0 | I40: 0 | J40: 0 | K40: 0 | L40: 0 | M40: 0 | N40: =SUM(B40:M40) | O40: 0 | P40: 0 | Q40: 0 | R40: 0 | S40: 0 | T40: 22 | U40: 0 | AA40: =SUM(O40:U40) | AB40: =SUM(O40:Z40) | AC40: 0 | AD40: 0 | AE40: 0 | AF40: 0 | AG40: 0 | AH40: 0 | AI40: =SUM(AC40:AH40) | AJ40: =SUM(AC40:AH40)+AI40 | AK40: =IF(N40<>0,(AB40-N40)/ABS(N40),0) | AL40: =IF(AB40<>0,(AJ40-AB40)/ABS(AB40),0)
A41: Marketing | B41: 14.58 | C41: 14.58 | D41: 149.79 | E41: 234.58 | F41: 1.59 | G41: 46.59 | H41: -1.3 | I41: 45 | J41: 0 | K41: 0 | L41: 0 | M41: 0 | N41: =SUM(B41:M41) | O41: 66 | P41: 0 | Q41: 0 | R41: 72 | S41: 0 | T41: 0 | U41: 4.99 | AA41: =SUM(O41:U41) | AB41: =SUM(O41:Z41) | AC41: 100 | AD41: 100 | AE41: 100 | AF41: 100 | AG41: 100 | AH41: 100 | AI41: =SUM(AC41:AH41) | AJ41: =SUM(AC41:AH41)+AI41 | AK41: =IF(N41<>0,(AB41-N41)/ABS(N41),0) | AL41: =IF(AB41<>0,(AJ41-AB41)/ABS(AB41),0)
A42: Total Premises & Admin | B42: =B33+B34+B35+B36+B37+B38+B39+B40+B41 | C42: =C33+C34+C35+C36+C37+C38+C39+C40+C41 | D42: =D33+D34+D35+D36+D37+D38+D39+D40+D41 | E42: =E33+E34+E35+E36+E37+E38+E39+E40+E41 | F42: =F33+F34+F35+F36+F37+F38+F39+F40+F41 | G42: =G33+G34+G35+G36+G37+G38+G39+G40+G41 | H42: =H33+H34+H35+H36+H37+H38+H39+H40+H41 | I42: =I33+I34+I35+I36+I37+I38+I39+I40+I41 | ... AJ42: =AJ33+AJ34+AJ35+AJ36+AJ37+AJ38+AJ39+AJ40+AJ41 | AK42: =IF(N42<>0,(AB42-N42)/ABS(N42),0) | AL42: =IF(AB42<>0,(AJ42-AB42)/ABS(AB42),0)
A44: Total Direct Costs | AK44: =IF(N44<>0,(AB44-N44)/ABS(N44),0) | AL44: =IF(AB44<>0,(AJ44-AB44)/ABS(AB44),0)
...

Sheet BW
A1: Bramley Wood | B1: Actuals 2025 | O1: 2026 Actual / Forecast | AC1: 2027 Forecast | AK1: YoY | AL1: YoY
B2: Jan | C2: Feb | D2: Mar | E2: Apr | F2: May | G2: Jun | H2: Jul | I2: Aug | J2: Sep | K2: Oct | L2: Nov | M2: Dec | N2: FY2025 Total | O2: Jan | P2: Feb | Q2: Mar | R2: Apr | S2: May | T2: Jun | U2: Jul | V2: Aug | W2: Sep | X2: Oct | Y2: Nov | Z2: Dec | AA2: YTD | AB2: FY2026 Outlook | AC2: Jan | AD2: Feb | AE2: Mar | AF2: Apr | AG2: May | AH2: Jun | AI2: Jul-Dec Proj. | AJ2: FY2027 | AK2: 25→26 % | AL2: 26→27 %
A3: INCOME
A4: Fee Income Regular | B4: 122156.52 | C4: 106947.36 | D4: 128166.24 | E4: 139357.58 | F4: 114644.73 | G4: 108480.27 | H4: 145137.16 | I4: 119462.05 | J4: 97287.09 | K4: 96101.48 | L4: 84850.06 | M4: 119634.28 | N4: =SUM(B4:M4) | O4: 92712.5 | P4: 82084.3 | Q4: 99688.3 | R4: 113186 | S4: 93282.1 | T4: 104024 | U4: 127224 | AA4: =SUM(O4:U4) | AB4: =SUM(O4:Z4) | AC4: 144535.68 | AD4: 132031.1 | AE4: 158165.89 | AF4: 141527.16 | AG4: 148240.86 | AH4: 153396.96 | AI4: =SUM(AC4:AH4) | AJ4: =SUM(AC4:AH4)+AI4 | AK4: =IF(N4<>0,(AB4-N4)/ABS(N4),0) | AL4: =IF(AB4<>0,(AJ4-AB4)/ABS(AB4),0)
A5: EEEF Embedded | B5: 33585.45 | C5: 66581.12 | D5: 66581.12 | E5: 28706.8 | F5: 28706.8 | G5: 67317.07 | H5: 67317.05 | I5: 0 | J5: 35210.21 | K5: 33827.21 | L5: 97735.45 | M5: 101444.41 | N5: =SUM(B5:M5) | O5: 44989.2 | P5: 94001.8 | Q5: 103241 | R5: 48659.8 | S5: 48659.8 | T5: 112571 | U5: 69963.4 | AA5: =SUM(O5:U5) | AB5: =SUM(O5:Z5) | AC5: 0 | AD5: 0 | AE5: 0 | AF5: 0 | AG5: 0 | AH5: 0 | AI5: =SUM(AC5:AH5) | AJ5: =SUM(AC5:AH5)+AI5 | AK5: =IF(N5<>0,(AB5-N5)/ABS(N5),0) | AL5: =IF(AB5<>0,(AJ5-AB5)/ABS(AB5),0)
A6: Other Income | B6: 200 | C6: 200 | D6: 250 | E6: 150 | F6: 150 | G6: 150 | H6: 150 | I6: 12901.66 | J6: 150 | K6: 150 | L6: 150 | M6: 150 | N6: =SUM(B6:M6) | O6: 150 | P6: 150 | Q6: 150 | R6: 150 | S6: 150 | T6: 450 | U6: 150 | AA6: =SUM(O6:U6) | AB6: =SUM(O6:Z6) | AC6: 0 | AD6: 0 | AE6: 0 | AF6: 0 | AG6: 0 | AH6: 0 | AI6: =SUM(AC6:AH6) | AJ6: =SUM(AC6:AH6)+AI6 | AK6: =IF(N6<>0,(AB6-N6)/ABS(N6),0) | AL6: =IF(AB6<>0,(AJ6-AB6)/ABS(AB6),0)
A7: Total Income | B7: =B4+B5+B6 | C7: =C4+C5+C6 | D7: =D4+D5+D6 | E7: =E4+E5+E6 | F7: =F4+F5+F6 | G7: =G4+G5+G6 | H7: =H4+H5+H6 | I7: =I4+I5+I6 | ... AJ7: =AJ4+AJ5+AJ6 | AK7: =IF(N7<>0,(AB7-N7)/ABS(N7),0) | AL7: =IF(AB7<>0,(AJ7-AB7)/ABS(AB7),0)
A9: DIRECT COSTS
A10: Personnel
A11: Nursery Salaries | B11: 68586.24 | C11: 60676.75 | D11: 61011.57 | E11: 67443.19 | F11: 72917.98 | G11: 67825.41 | H11: 75334.7 | I11: 72777.63 | J11: 80807.62 | K11: 70161.91 | L11: 67160.5 | M11: 64917.87 | N11: =SUM(B11:M11) | O11: 67397.79 | P11: 65169.32 | Q11: 57920.38 | R11: 61937.98 | S11: 66920.32 | T11: 67131.93 | U11: 67043.3 | AA11: =SUM(O11:U11) | AB11: =SUM(O11:Z11) | AC11: 67043.3 | AD11: 67043.3 | AE11: 67043.3 | AF11: 67043.3 | AG11: 67043.3 | AH11: 67043.3 | AI11: =SUM(AC11:AH11) | AJ11: =SUM(AC11:AH11)+AI11 | AK11: =IF(N11<>0,(AB11-N11)/ABS(N11),0) | AL11: =IF(AB11<>0,(AJ11-AB11)/ABS(AB11),0)
A12: Nursery NI | B12: 5300.22 | C12: 4463.01 | D12: 4517.4 | E12: 6985.94 | F12: 7294.24 | G12: 6627.99 | H12: 7346.36 | I12: 7134.49 | J12: 9821.09 | K12: 6696.34 | L12: 6289.94 | M12: 6024.82 | N12: =SUM(B12:M12) | O12: 6420.59 | P12: 5749.78 | Q12: 5741.09 | R12: 6217.05 | S12: 6359.57 | T12: 6618.61 | U12: 6517.08 | AA12: =SUM(O12:U12) | AB12: =SUM(O12:Z12) | AC12: 6517.08 | AD12: 6517.08 | AE12: 6517.08 | AF12: 6517.08 | AG12: 6517.08 | AH12: 6517.08 | AI12: =SUM(AC12:AH12) | AJ12: =SUM(AC12:AH12)+AI12 | AK12: =IF(N12<>0,(AB12-N12)/ABS(N12),0) | AL12: =IF(AB12<>0,(AJ12-AB12)/ABS(AB12),0)
A13: Nursery Pension | B13: 1186.64 | C13: 1102.67 | D13: 1084.37 | E13: 1172.06 | F13: 1236.3 | G13: 1145.18 | H13: 1293.63 | I13: 1252.61 | J13: 1273.7 | K13: 1200.38 | L13: 1188.64 | M13: 1124.16 | N13: =SUM(B13:M13) | O13: 1190.11 | P13: 1065.61 | Q13: 997.11 | R13: 1098.81 | S13: 1034.65 | T13: 1054.41 | U13: 1087.65 | AA13: =SUM(O13:U13) | AB13: =SUM(O13:Z13) | AC13: 1087.65 | AD13: 1087.65 | AE13: 1087.65 | AF13: 1087.65 | AG13: 1087.65 | AH13: 1087.65 | AI13: =SUM(AC13:AH13) | AJ13: =SUM(AC13:AH13)+AI13 | AK13: =IF(N13<>0,(AB13-N13)/ABS(N13),0) | AL13: =IF(AB13<>0,(AJ13-AB13)/ABS(AB13),0)
A14: Uniform | B14: 149.22 | C14: 0 | D14: 79.08 | E14: 0 | F14: 0 | G14: 350.58 | H14: 0 | I14: 0 | J14: 0 | K14: 0 | L14: 77.22 | M14: 1091.59 | N14: =SUM(B14:M14) | O14: 145.8 | P14: 0 | Q14: 0 | R14: 114.42 | S14: 0 | T14: 0 | U14: 0 | AA14: =SUM(O14:U14) | AB14: =SUM(O14:Z14) | AC14: 176 | AD14: 176 | AE14: 176 | AF14: 176 | AG14: 176 | AH14: 176 | AI14: =SUM(AC14:AH14) | AJ14: =SUM(AC14:AH14)+AI14 | AK14: =IF(N14<>0,(AB14-N14)/ABS(N14),0) | AL14: =IF(AB14<>0,(AJ14-AB14)/ABS(AB14),0)
A15: Training | B15: 0 | C15: 30 | D15: 480 | E15: 0 | F15: 18 | G15: 540 | H15: 189.28 | I15: 0 | J15: 0 | K15: 384 | L15: 50 | M15: -156 | N15: =SUM(B15:M15) | O15: 1254 | P15: 100 | Q15: 0 | R15: 335 | S15: -7.87 | T15: 55.86 | U15: 0 | AA15: =SUM(O15:U15) | AB15: =SUM(O15:Z15) | AC15: 500 | AD15: 500 | AE15: 500 | AF15: 500 | AG15: 500 | AH15: 500 | AI15: =SUM(AC15:AH15) | AJ15: =SUM(AC15:AH15)+AI15 | AK15: =IF(N15<>0,(AB15-N15)/ABS(N15),0) | AL15: =IF(AB15<>0,(AJ15-AB15)/ABS(AB15),0)
A16: Staff Welfare | B16: 292.56 | C16: 327.49 | D16: 190 | E16: 238.69 | F16: 147.43 | G16: 436.17 | H16: 265.44 | I16: 187.74 | J16: 173.74 | K16: 173.74 | L16: 327.78 | M16: 302.37 | N16: =SUM(B16:M16) | O16: 0 | P16: 212.72 | Q16: 232.51 | R16: 452.35 | S16: 231.54 | T16: 29.19 | U16: 139.62 | AA16: =SUM(O16:U16) | AB16: =SUM(O16:Z16) | AC16: 360 | AD16: 360 | AE16: 360 | AF16: 360 | AG16: 360 | AH16: 360 | AI16: =SUM(AC16:AH16) | AJ16: =SUM(AC16:AH16)+AI16 | AK16: =IF(N16<>0,(AB16-N16)/ABS(N16),0) | AL16: =IF(AB16<>0,(AJ16-AB16)/ABS(AB16),0)
A17: Recruitment | B17: 0 | C17: 64.8 | D17: 0 | E17: 0 | F17: 0 | G17: 0 | H17: 0 | I17: 0 | J17: 0 | K17: 0 | L17: 0 | M17: 0 | N17: =SUM(B17:M17) | O17: 0 | P17: 0 | Q17: 0 | R17: 0 | S17: 0 | T17: 0 | U17: 0 | V17: 0 | W17: 0 | X17: 0 | Y17: 0 | Z17: 0 | AA17: =SUM(O17:U17) | AB17: =SUM(O17:Z17) | AC17: 0 | AD17: 0 | AE17: 0 | AF17: 0 | AG17: 0 | AH17: 0 | AI17: =SUM(AC17:AH17) | AJ17: =SUM(AC17:AH17)+AI17 | AK17: =IF(N17<>0,(AB17-N17)/ABS(N17),0) | AL17: =IF(AB17<>0,(AJ17-AB17)/ABS(AB17),0)
A18: Rewards & Recognition | B18: 0 | C18: 0 | D18: 0 | E18: 0 | F18: 0 | G18: 0 | H18: 0 | I18: 0 | J18: 0 | K18: 47.96 | L18: 101.16 | M18: 0 | N18: =SUM(B18:M18) | O18: 0 | P18: 0 | Q18: 0 | R18: 0 | S18: 0 | T18: 0 | U18: 0 | V18: 0 | W18: 0 | X18: 0 | Y18: 0 | Z18: 0 | AA18: =SUM(O18:U18) | AB18: =SUM(O18:Z18) | AC18: 150 | AD18: 150 | AE18: 150 | AF18: 150 | AG18: 150 | AH18: 150 | AI18: =SUM(AC18:AH18) | AJ18: =SUM(AC18:AH18)+AI18 | AK18: =IF(N18<>0,(AB18-N18)/ABS(N18),0) | AL18: =IF(AB18<>0,(AJ18-AB18)/ABS(AB18),0)
A19: Temps | B19: 0 | C19: 0 | D19: 0 | E19: 0 | F19: 0 | G19: 0 | H19: 0 | I19: 0 | J19: 0 | K19: 0 | L19: 0 | M19: 0 | N19: =SUM(B19:M19) | O19: 0 | P19: 0 | Q19: 0 | R19: 0 | S19: 0 | T19: 0 | U19: 0 | V19: 0 | W19: 0 | X19: 0 | Y19: 0 | Z19: 0 | AA19: =SUM(O19:U19) | AB19: =SUM(O19:Z19) | AC19: 0 | AD19: 0 | AE19: 0 | AF19: 0 | AG19: 0 | AH19: 0 | AI19: =SUM(AC19:AH19) | AJ19: =SUM(AC19:AH19)+AI19 | AK19: =IF(N19<>0,(AB19-N19)/ABS(N19),0) | AL19: =IF(AB19<>0,(AJ19-AB19)/ABS(AB19),0)
A20: Total Personnel | B20: =B11+B12+B13+B14+B15+B16+B17+B18+B19 | C20: =C11+C12+C13+C14+C15+C16+C17+C18+C19 | D20: =D11+D12+D13+D14+D15+D16+D17+D18+D19 | E20: =E11+E12+E13+E14+E15+E16+E17+E18+E19 | F20: =F11+F12+F13+F14+F15+F16+F17+F18+F19 | G20: =G11+G12+G13+G14+G15+G16+G17+G18+G19 | H20: =H11+H12+H13+H14+H15+H16+H17+H18+H19 | I20: =I11+I12+I13+I14+I15+I16+I17+I18+I19 | ... AJ20: =AJ11+AJ12+AJ13+AJ14+AJ15+AJ16+AJ17+AJ18+AJ19 | AK20: =IF(N20<>0,(AB20-N20)/ABS(N20),0) | AL20: =IF(AB20<>0,(AJ20-AB20)/ABS(AB20),0)
A21: Sal:Rev | B21: =IF(B7>0,B20/B7,0) | C21: =IF(C7>0,C20/C7,0) | D21: =IF(D7>0,D20/D7,0) | E21: =IF(E7>0,E20/E7,0) | F21: =IF(F7>0,F20/F7,0) | G21: =IF(G7>0,G20/G7,0) | H21: =IF(H7>0,H20/H7,0) | I21: =IF(I7>0,I20/I7,0) | ... AJ21: =IF(AJ7>0,AJ20/AJ7,0)
A23: Childcare
A24: Catering Costs | N24: =SUM(B24:M24) | O24: 4148.71 | P24: 4930.31 | Q24: 5124.93 | R24: 4010.78 | S24: 5788.22 | T24: 5150.48 | U24: 4936.23 | V24: 3546.5876 | W24: 4510.5528 | X24: 4607.5224 | Y24: 4439.916 | Z24: 4176.4632 | AA24: =SUM(O24:U24) | AB24: =SUM(O24:Z24) | AC24: 4509.5132 | AD24: 4119.3703 | AE24: 4934.7758 | AF24: 4415.6474 | AG24: 4625.1148 | AH24: 4785.9852 | AI24: =SUM(AC24:AH24) | AJ24: =SUM(AC24:AH24)+AI24 | AK24: =IF(N24<>0,(AB24-N24)/ABS(N24),0) | AL24: =IF(AB24<>0,(AJ24-AB24)/ABS(AB24),0)
A25: Toys and Games | B25: 330.13 | C25: 1111.29 | D25: 135.72 | E25: 172.74 | F25: 1014.7 | G25: 1919.79 | H25: 265.47 | I25: 171.34 | J25: 0 | K25: 183.06 | L25: 257.43 | M25: 59.92 | N25: =SUM(B25:M25) | O25: 91.2 | P25: 89.62 | Q25: 249.67 | R25: 456.76 | S25: 98.94 | T25: 1175.49 | U25: 39.09 | AA25: =SUM(O25:U25) | AB25: =SUM(O25:Z25) | AC25: 100 | AD25: 100 | AE25: 100 | AF25: 100 | AG25: 100 | AH25: 100 | AI25: =SUM(AC25:AH25) | AJ25: =SUM(AC25:AH25)+AI25 | AK25: =IF(N25<>0,(AB25-N25)/ABS(N25),0) | AL25: =IF(AB25<>0,(AJ25-AB25)/ABS(AB25),0)
A26: Art Materials | N26: =SUM(B26:M26) | O26: 0 | P26: 160.57 | Q26: 230.91 | R26: 143.14 | S26: 88.79 | T26: 256.61 | U26: 223.33 | V26: 236.43917 | W26: 300.70352 | X26: 307.16816 | Y26: 295.9944 | Z26: 278.43088 | AA26: =SUM(O26:U26) | AB26: =SUM(O26:Z26) | AC26: 300.63421 | AD26: 274.62469 | AE26: 328.98505 | AF26: 294.37649 | AG26: 308.34099 | AH26: 319.06568 | AI26: =SUM(AC26:AH26) | AJ26: =SUM(AC26:AH26)+AI26 | AK26: =IF(N26<>0,(AB26-N26)/ABS(N26),0) | AL26: =IF(AB26<>0,(AJ26-AB26)/ABS(AB26),0)
A27: Nursery Stationery | B27: 15 | C27: 63.01 | D27: 61.27 | E27: 3.06 | F27: 1.38 | G27: 44.8 | H27: 112.74 | I27: 0 | J27: 104.18 | K27: 88.44 | L27: 41.01 | M27: 38.29 | N27: =SUM(B27:M27) | O27: 6.39 | P27: 72.61 | Q27: 43.57 | R27: 35.07 | S27: 16.02 | T27: 69.76 | U27: 48.33 | AA27: =SUM(O27:U27) | AB27: =SUM(O27:Z27) | AC27: 278 | AD27: 278 | AE27: 278 | AF27: 278 | AG27: 278 | AH27: 278 | AI27: =SUM(AC27:AH27) | AJ27: =SUM(AC27:AH27)+AI27 | AK27: =IF(N27<>0,(AB27-N27)/ABS(N27),0) | AL27: =IF(AB27<>0,(AJ27-AB27)/ABS(AB27),0)
A28: Nursery Equipment | B28: 134.83 | C28: 92.94 | D28: 339.69 | E28: 63.56 | F28: 390.09 | G28: 775.99 | H28: 63.76 | I28: 35.62 | J28: 45.98 | K28: 380.46 | L28: 86.04 | M28: 54.77 | N28: =SUM(B28:M28) | O28: 55.86 | P28: 123.78 | Q28: 0 | R28: 22.45 | S28: 59.08 | T28: 466.76 | U28: 206.96 | AA28: =SUM(O28:U28) | AB28: =SUM(O28:Z28) | AC28: 100 | AD28: 100 | AE28: 100 | AF28: 100 | AG28: 100 | AH28: 100 | AI28: =SUM(AC28:AH28) | AJ28: =SUM(AC28:AH28)+AI28 | AK28: =IF(N28<>0,(AB28-N28)/ABS(N28),0) | AL28: =IF(AB28<>0,(AJ28-AB28)/ABS(AB28),0)
A29: Nursery Consumables | N29: =SUM(B29:M29) | O29: 1014.79 | P29: 667.24 | Q29: 625.97 | R29: 1223.46 | S29: 1072.87 | T29: 248.7 | U29: 985.75 | V29: 472.87835 | W29: 601.40704 | X29: 614.33632 | Y29: 591.9888 | Z29: 556.86176 | AA29: =SUM(O29:U29) | AB29: =SUM(O29:Z29) | AC29: 601.26843 | AD29: 549.24938 | AE29: 657.9701 | AF29: 588.75299 | AG29: 616.68198 | AH29: 638.13135 | AI29: =SUM(AC29:AH29) | AJ29: =SUM(AC29:AH29)+AI29 | AK29: =IF(N29<>0,(AB29-N29)/ABS(N29),0) | AL29: =IF(AB29<>0,(AJ29-AB29)/ABS(AB29),0)
A30: Total Childcare Costs | B30: =B24+B25+B26+B27+B28+B29 | C30: =C24+C25+C26+C27+C28+C29 | D30: =D24+D25+D26+D27+D28+D29 | E30: =E24+E25+E26+E27+E28+E29 | F30: =F24+F25+F26+F27+F28+F29 | G30: =G24+G25+G26+G27+G28+G29 | H30: =H24+H25+H26+H27+H28+H29 | I30: =I24+I25+I26+I27+I28+I29 | ... AJ30: =AJ24+AJ25+AJ26+AJ27+AJ28+AJ29 | AK30: =IF(N30<>0,(AB30-N30)/ABS(N30),0) | AL30: =IF(AB30<>0,(AJ30-AB30)/ABS(AB30),0)
A32: Premises & Admin
A33: Rent | B33: 0 | C33: 0 | D33: 0 | E33: 0 | F33: 0 | G33: 0 | H33: 0 | I33: 0 | J33: 0 | K33: 0 | L33: 0 | M33: 0 | N33: =SUM(B33:M33) | O33: 0 | P33: 0 | Q33: 0 | R33: 0 | S33: 0 | T33: 0 | U33: 0 | V33: 0 | W33: 0 | X33: 0 | Y33: 0 | Z33: 0 | AA33: =SUM(O33:U33) | AB33: =SUM(O33:Z33) | AC33: 0 | AD33: 0 | AE33: 0 | AF33: 0 | AG33: 0 | AH33: 0 | AI33: =SUM(AC33:AH33) | AJ33: =SUM(AC33:AH33)+AI33 | AK33: =IF(N33<>0,(AB33-N33)/ABS(N33),0) | AL33: =IF(AB33<>0,(AJ33-AB33)/ABS(AB33),0)
A34: Business Rates | B34: 3025.75 | C34: 3025.75 | D34: 3025.75 | E34: 3075.63 | F34: 3075.63 | G34: 3075.63 | H34: 3075.63 | I34: 3075.63 | J34: 3075.63 | K34: 3075.63 | L34: 3075.63 | M34: 3075.63 | N34: =SUM(B34:M34) | O34: 3075.61 | P34: 3075.61 | Q34: 3075.61 | R34: 3123.75 | S34: 3123.75 | T34: 3123.75 | U34: 3123.75 | AA34: =SUM(O34:U34) | AB34: =SUM(O34:Z34) | AC34: 3123.75 | AD34: 3123.75 | AE34: 3123.75 | AF34: 3123.75 | AG34: 3123.75 | AH34: 3123.75 | AI34: =SUM(AC34:AH34) | AJ34: =SUM(AC34:AH34)+AI34 | AK34: =IF(N34<>0,(AB34-N34)/ABS(N34),0) | AL34: =IF(AB34<>0,(AJ34-AB34)/ABS(AB34),0)
A35: Utilities | B35: 2790.8 | C35: 2628.84 | D35: 4292.94 | E35: 5529.95 | F35: 1656.64 | G35: 2428.37 | H35: 1773.3 | I35: 1422.35 | J35: 2223.76 | K35: 3805.35 | L35: 3193.73 | M35: 3368.92 | N35: =SUM(B35:M35) | O35: 4087.64 | P35: 4314.61 | Q35: 2945.05 | R35: 2778.49 | S35: 2142.48 | T35: 2285.87 | U35: 1722.41 | AA35: =SUM(O35:U35) | AB35: =SUM(O35:Z35) | AC35: 3138 | AD35: 3138 | AE35: 3138 | AF35: 3138 | AG35: 3138 | AH35: 3138 | AI35: =SUM(AC35:AH35) | AJ35: =SUM(AC35:AH35)+AI35 | AK35: =IF(N35<>0,(AB35-N35)/ABS(N35),0) | AL35: =IF(AB35<>0,(AJ35-AB35)/ABS(AB35),0)
A36: Repairs & Maintenance | B36: 924.68 | C36: 752.58 | D36: 409.33 | E36: 1010.79 | F36: 213.72 | G36: 535.98 | H36: 2248.4 | I36: 2709.69 | J36: 912.31 | K36: 1226.69 | L36: 65.19 | M36: 192.39 | N36: =SUM(B36:M36) | O36: 482.98 | P36: 65.19 | Q36: 81.48 | R36: 217.62 | S36: 546.64 | T36: 445.08 | U36: 1103.45 | AA36: =SUM(O36:U36) | AB36: =SUM(O36:Z36) | AC36: 0 | AD36: 0 | AE36: 0 | AF36: 0 | AG36: 0 | AH36: 0 | AI36: =SUM(AC36:AH36) | AJ36: =SUM(AC36:AH36)+AI36 | AK36: =IF(N36<>0,(AB36-N36)/ABS(N36),0) | AL36: =IF(AB36<>0,(AJ36-AB36)/ABS(AB36),0)
A37: Cleaning | B37: 3992.33 | C37: 3985.5 | D37: 3876.24 | E37: 4757.82 | F37: 3752.54 | G37: 3993.33 | H37: 4752.64 | I37: 8059.97 | J37: 4609.84 | K37: 755.69 | L37: 4164.74 | M37: 4041.48 | N37: =SUM(B37:M37) | O37: 3097.61 | P37: 7311.5 | Q37: 416.9 | R37: 4015.5 | S37: 4246.18 | T37: 4420.44 | U37: 4546.02 | AA37: =SUM(O37:U37) | AB37: =SUM(O37:Z37) | AC37: 4300 | AD37: 4300 | AE37: 4300 | AF37: 4300 | AG37: 4300 | AH37: 4300 | AI37: =SUM(AC37:AH37) | AJ37: =SUM(AC37:AH37)+AI37 | AK37: =IF(N37<>0,(AB37-N37)/ABS(N37),0) | AL37: =IF(AB37<>0,(AJ37-AB37)/ABS(AB37),0)
A38: Waste Disposal | B38: 623.08 | C38: 831.76 | D38: 836.49 | E38: 747.74 | F38: 481.62 | G38: 810.65 | H38: 662.91 | I38: 701.49 | J38: 1035.73 | K38: 720.8 | L38: 715.36 | M38: 834.2 | N38: =SUM(B38:M38) | O38: 715.36 | P38: 715.36 | Q38: 843.86 | R38: 1039.5 | S38: 796.4 | T38: 429.02 | U38: 1016.67 | AA38: =SUM(O38:U38) | AB38: =SUM(O38:Z38) | AC38: 746 | AD38: 746 | AE38: 746 | AF38: 746 | AG38: 746 | AH38: 746 | AI38: =SUM(AC38:AH38) | AJ38: =SUM(AC38:AH38)+AI38 | AK38: =IF(N38<>0,(AB38-N38)/ABS(N38),0) | AL38: =IF(AB38<>0,(AJ38-AB38)/ABS(AB38),0)
A39: Postage/Printing/Stationery | B39: 72.16 | C39: 108.21 | D39: 93.42 | E39: 86.88 | F39: 91.48 | G39: 133.56 | H39: 135.07 | I39: 63.11 | J39: 156.44 | K39: 93.01 | L39: 12.84 | M39: 72.92 | N39: =SUM(B39:M39) | O39: 75.37 | P39: 96.28 | Q39: 268.58 | R39: 106.13 | S39: 149.21 | T39: 172.86 | U39: 64.6 | AA39: =SUM(O39:U39) | AB39: =SUM(O39:Z39) | AC39: 150 | AD39: 150 | AE39: 150 | AF39: 150 | AG39: 150 | AH39: 150 | AI39: =SUM(AC39:AH39) | AJ39: =SUM(AC39:AH39)+AI39 | AK39: =IF(N39<>0,(AB39-N39)/ABS(N39),0) | AL39: =IF(AB39<>0,(AJ39-AB39)/ABS(AB39),0)
A40: Telephone | B40: 0 | C40: 0 | D40: 0 | E40: 0 | F40: 0 | G40: 0 | H40: 0 | I40: 0 | J40: 0 | K40: 0 | L40: 0 | M40: 0 | N40: =SUM(B40:M40) | O40: 0 | P40: 0 | Q40: 0 | R40: 0 | S40: 0 | T40: 0 | U40: 0 | V40: 0 | W40: 0 | X40: 0 | Y40: 0 | Z40: 0 | AA40: =SUM(O40:U40) | AB40: =SUM(O40:Z40) | AC40: 0 | AD40: 0 | AE40: 0 | AF40: 0 | AG40: 0 | AH40: 0 | AI40: =SUM(AC40:AH40) | AJ40: =SUM(AC40:AH40)+AI40 | AK40: =IF(N40<>0,(AB40-N40)/ABS(N40),0) | AL40: =IF(AB40<>0,(AJ40-AB40)/ABS(AB40),0)
A41: Marketing | B41: 0 | C41: 64.8 | D41: 345.62 | E41: 0 | F41: 129.6 | G41: 45 | H41: 0 | I41: 90 | J41: 0 | K41: 0 | L41: 220 | M41: 0 | N41: =SUM(B41:M41) | O41: 264 | P41: 0 | Q41: 0 | R41: 282 | S41: 0 | T41: 0 | U41: 3.75 | AA41: =SUM(O41:U41) | AB41: =SUM(O41:Z41) | AC41: 100 | AD41: 100 | AE41: 100 | AF41: 100 | AG41: 100 | AH41: 100 | AI41: =SUM(AC41:AH41) | AJ41: =SUM(AC41:AH41)+AI41 | AK41: =IF(N41<>0,(AB41-N41)/ABS(N41),0) | AL41: =IF(AB41<>0,(AJ41-AB41)/ABS(AB41),0)
A42: Total Premises & Admin | B42: =B33+B34+B35+B36+B37+B38+B39+B40+B41 | C42: =C33+C34+C35+C36+C37+C38+C39+C40+C41 | D42: =D33+D34+D35+D36+D37+D38+D39+D40+D41 | E42: =E33+E34+E35+E36+E37+E38+E39+E40+E41 | F42: =F33+F34+F35+F36+F37+F38+F39+F40+F41 | G42: =G33+G34+G35+G36+G37+G38+G39+G40+G41 | H42: =H33+H34+H35+H36+H37+H38+H39+H40+H41 | I42: =I33+I34+I35+I36+I37+I38+I39+I40+I41 | ... AJ42: =AJ33+AJ34+AJ35+AJ36+AJ37+AJ38+AJ39+AJ40+AJ41 | AK42: =IF(N42<>0,(AB42-N42)/ABS(N42),0) | AL42: =IF(AB42<>0,(AJ42-AB42)/ABS(AB42),0)
A44: Total Direct Costs | AK44: =IF(N44<>0,(AB44-N44)/ABS(N44),0) | AL44: =IF(AB44<>0,(AJ44-AB44)/ABS(AB44),0)
...

Sheet CED
A1: Cedars | B1: Actuals 2025 | O1: 2026 Actual / Forecast | AC1: 2027 Forecast | AK1: YoY | AL1: YoY
B2: Jan | C2: Feb | D2: Mar | E2: Apr | F2: May | G2: Jun | H2: Jul | I2: Aug | J2: Sep | K2: Oct | L2: Nov | M2: Dec | N2: FY2025 Total | O2: Jan | P2: Feb | Q2: Mar | R2: Apr | S2: May | T2: Jun | U2: Jul | V2: Aug | W2: Sep | X2: Oct | Y2: Nov | Z2: Dec | AA2: YTD | AB2: FY2026 Outlook | AC2: Jan | AD2: Feb | AE2: Mar | AF2: Apr | AG2: May | AH2: Jun | AI2: Jul-Dec Proj. | AJ2: FY2027 | AK2: 25→26 % | AL2: 26→27 %
A3: INCOME
A4: Fee Income Regular | B4: 23814.44 | C4: 20657.57 | D4: 26472.4 | E4: 28682.3 | F4: 21069.85 | G4: 21588.68 | H4: 29637.32 | I4: 22500.55 | J4: 19945.64 | K4: 19659.5 | L4: 18229.14 | M4: 23118.77 | N4: =SUM(B4:M4) | O4: 22240.66 | P4: 18321.22 | Q4: 22883.28 | R4: 22685.93 | S4: 18910.69 | T4: 20776.58 | U4: 25818.48 | AA4: =SUM(O4:U4) | AB4: =SUM(O4:Z4) | AC4: 28315.98 | AD4: 26840.28 | AE4: 31507.8 | AF4: 30543.59 | AG4: 30885.6 | AH4: 33002.04 | AI4: =SUM(AC4:AH4) | AJ4: =SUM(AC4:AH4)+AI4 | AK4: =IF(N4<>0,(AB4-N4)/ABS(N4),0) | AL4: =IF(AB4<>0,(AJ4-AB4)/ABS(AB4),0)
A5: EEEF Embedded | B5: 5791.72 | C5: 14479.3 | D5: 15684.58 | E5: 5185.26 | F5: 5185.26 | G5: 15608.08 | H5: 13375.26 | I5: 0 | J5: 5986.21 | K5: 12205.6 | L5: 12205.6 | M5: 16957.76 | N5: =SUM(B5:M5) | O5: 6629.51 | P5: 17491.45 | Q5: 17491.45 | R5: 12006.04 | S5: 12006.05 | T5: 12927.15 | U5: 12313.08 | AA5: =SUM(O5:U5) | AB5: =SUM(O5:Z5) | AC5: 0 | AD5: 0 | AE5: 0 | AF5: 0 | AG5: 0 | AH5: 0 | AI5: =SUM(AC5:AH5) | AJ5: =SUM(AC5:AH5)+AI5 | AK5: =IF(N5<>0,(AB5-N5)/ABS(N5),0) | AL5: =IF(AB5<>0,(AJ5-AB5)/ABS(AB5),0)
A6: Other Income | B6: 200 | C6: 200 | D6: 300 | E6: 0 | F6: 300 | G6: 300 | H6: 150 | I6: 0 | J6: 0 | K6: 150 | L6: 150 | M6: 150 | N6: =SUM(B6:M6) | O6: 650 | P6: 150 | Q6: 150 | R6: 150 | S6: 150 | T6: 150 | U6: 150 | AA6: =SUM(O6:U6) | AB6: =SUM(O6:Z6) | AC6: 0 | AD6: 0 | AE6: 0 | AF6: 0 | AG6: 0 | AH6: 0 | AI6: =SUM(AC6:AH6) | AJ6: =SUM(AC6:AH6)+AI6 | AK6: =IF(N6<>0,(AB6-N6)/ABS(N6),0) | AL6: =IF(AB6<>0,(AJ6-AB6)/ABS(AB6),0)
A7: Total Income | B7: =B4+B5+B6 | C7: =C4+C5+C6 | D7: =D4+D5+D6 | E7: =E4+E5+E6 | F7: =F4+F5+F6 | G7: =G4+G5+G6 | H7: =H4+H5+H6 | I7: =I4+I5+I6 | ... AJ7: =AJ4+AJ5+AJ6 | AK7: =IF(N7<>0,(AB7-N7)/ABS(N7),0) | AL7: =IF(AB7<>0,(AJ7-AB7)/ABS(AB7),0)
A9: DIRECT COSTS
A10: Personnel
A11: Nursery Salaries | B11: 15964.89 | C11: 15432.95 | D11: 16980.77 | E11: 19492.28 | F11: 19492.07 | G11: 16093.17 | H11: 19196.5 | I11: 14959.37 | J11: 19873.92 | K11: 18038.34 | L11: 18266.77 | M11: 21533.17 | N11: =SUM(B11:M11) | O11: 19941.96 | P11: 18433.95 | Q11: 16301.53 | R11: 22374.13 | S11: 22592.61 | T11: 21699.26 | U11: 22510.48 | AA11: =SUM(O11:U11) | AB11: =SUM(O11:Z11) | AC11: 22510.48 | AD11: 22510.48 | AE11: 22510.48 | AF11: 22510.48 | AG11: 22510.48 | AH11: 22510.48 | AI11: =SUM(AC11:AH11) | AJ11: =SUM(AC11:AH11)+AI11 | AK11: =IF(N11<>0,(AB11-N11)/ABS(N11),0) | AL11: =IF(AB11<>0,(AJ11-AB11)/ABS(AB11),0)
A12: Nursery NI | B12: 1212.08 | C12: 1115.32 | D12: 1300.33 | E12: 2055.72 | F12: 1957.17 | G12: 1471.56 | H12: 1976.99 | I12: 1386.1 | J12: 2097.99 | K12: 1993.75 | L12: 1962.85 | M12: 2264.02 | N12: =SUM(B12:M12) | O12: 2075.7 | P12: 2156.24 | Q12: 2109.88 | R12: 2614.86 | S12: 2663.12 | T12: 2437.78 | U12: 2763.77 | AA12: =SUM(O12:U12) | AB12: =SUM(O12:Z12) | AC12: 2763.77 | AD12: 2763.77 | AE12: 2763.77 | AF12: 2763.77 | AG12: 2763.77 | AH12: 2763.77 | AI12: =SUM(AC12:AH12) | AJ12: =SUM(AC12:AH12)+AI12 | AK12: =IF(N12<>0,(AB12-N12)/ABS(N12),0) | AL12: =IF(AB12<>0,(AJ12-AB12)/ABS(AB12),0)
A13: Nursery Pension | B13: 216.18 | C13: 203.88 | D13: 196.57 | E13: 233.26 | F13: 228.75 | G13: 190.93 | H13: 276.28 | I13: 243.1 | J13: 298.73 | K13: 272.53 | L13: 352.17 | M13: 373.97 | N13: =SUM(B13:M13) | O13: 390.39 | P13: 333.89 | Q13: 284.46 | R13: 420.57 | S13: 427.46 | T13: 446.28 | U13: 478.22 | AA13: =SUM(O13:U13) | AB13: =SUM(O13:Z13) | AC13: 478.22 | AD13: 478.22 | AE13: 478.22 | AF13: 478.22 | AG13: 478.22 | AH13: 478.22 | AI13: =SUM(AC13:AH13) | AJ13: =SUM(AC13:AH13)+AI13 | AK13: =IF(N13<>0,(AB13-N13)/ABS(N13),0) | AL13: =IF(AB13<>0,(AJ13-AB13)/ABS(AB13),0)
A14: Uniform | B14: 0 | C14: 524.28 | D14: 0 | E14: 0 | F14: 100.14 | G14: 100.14 | H14: 0 | I14: 0 | J14: 262.56 | K14: 0 | L14: 0 | M14: 100.14 | N14: =SUM(B14:M14) | O14: 6.99 | P14: 0 | Q14: 0 | R14: 133.87 | S14: 0 | T14: 0 | U14: 0 | AA14: =SUM(O14:U14) | AB14: =SUM(O14:Z14) | AC14: 6.99 | AD14: 6.99 | AE14: 6.99 | AF14: 6.99 | AG14: 6.99 | AH14: 6.99 | AI14: =SUM(AC14:AH14) | AJ14: =SUM(AC14:AH14)+AI14 | AK14: =IF(N14<>0,(AB14-N14)/ABS(N14),0) | AL14: =IF(AB14<>0,(AJ14-AB14)/ABS(AB14),0)
A15: Training | B15: 48 | C15: 78 | D15: 0 | E15: 0 | F15: 0 | G15: 72 | H15: 0 | I15: 0 | J15: 216 | K15: 916 | L15: 10 | M15: 686.49 | N15: =SUM(B15:M15) | O15: 388.79 | P15: 0 | Q15: 24 | R15: 0 | S15: 0 | T15: 0 | U15: 0 | AA15: =SUM(O15:U15) | AB15: =SUM(O15:Z15) | AC15: 100 | AD15: 100 | AE15: 100 | AF15: 100 | AG15: 100 | AH15: 100 | AI15: =SUM(AC15:AH15) | AJ15: =SUM(AC15:AH15)+AI15 | AK15: =IF(N15<>0,(AB15-N15)/ABS(N15),0) | AL15: =IF(AB15<>0,(AJ15-AB15)/ABS(AB15),0)
A16: Staff Welfare | B16: 10 | C16: 108.63 | D16: 61.08 | E16: 109.86 | F16: 137.21 | G16: 52.06 | H16: 92.57 | I16: 92.28 | J16: 92.52 | K16: 68.13 | L16: 161.98 | M16: 194.07 | N16: =SUM(B16:M16) | O16: 125.23 | P16: 203.51 | Q16: 281.37 | R16: 239.69 | S16: 156.06 | T16: 149.88 | U16: 224.47 | AA16: =SUM(O16:U16) | AB16: =SUM(O16:Z16) | AC16: 150 | AD16: 150 | AE16: 150 | AF16: 150 | AG16: 150 | AH16: 150 | AI16: =SUM(AC16:AH16) | AJ16: =SUM(AC16:AH16)+AI16 | AK16: =IF(N16<>0,(AB16-N16)/ABS(N16),0) | AL16: =IF(AB16<>0,(AJ16-AB16)/ABS(AB16),0)
A17: Recruitment | B17: 0 | C17: 5040 | D17: 0 | E17: 0 | F17: 0 | G17: 0 | H17: 0 | I17: 0 | J17: 0 | K17: 0 | L17: 0 | M17: 3650.4 | N17: =SUM(B17:M17) | O17: 0 | P17: 0 | Q17: 0 | R17: 0 | S17: 0 | T17: 0 | U17: 0 | V17: 0 | W17: 0 | X17: 0 | Y17: 0 | Z17: 0 | AA17: =SUM(O17:U17) | AB17: =SUM(O17:Z17) | AC17: 0 | AD17: 0 | AE17: 0 | AF17: 0 | AG17: 0 | AH17: 0 | AI17: =SUM(AC17:AH17) | AJ17: =SUM(AC17:AH17)+AI17 | AK17: =IF(N17<>0,(AB17-N17)/ABS(N17),0) | AL17: =IF(AB17<>0,(AJ17-AB17)/ABS(AB17),0)
A18: Rewards & Recognition | B18: 0 | C18: 0 | D18: 0 | E18: 0 | F18: 0 | G18: 0 | H18: 10 | I18: 10 | J18: 0 | K18: 0 | L18: 0 | M18: 12.99 | N18: =SUM(B18:M18) | O18: 0 | P18: 0 | Q18: 0 | R18: 0 | S18: 0 | T18: 35.95 | U18: 66.9 | AA18: =SUM(O18:U18) | AB18: =SUM(O18:Z18) | AC18: 42 | AD18: 42 | AE18: 42 | AF18: 42 | AG18: 42 | AH18: 42 | AI18: =SUM(AC18:AH18) | AJ18: =SUM(AC18:AH18)+AI18 | AK18: =IF(N18<>0,(AB18-N18)/ABS(N18),0) | AL18: =IF(AB18<>0,(AJ18-AB18)/ABS(AB18),0)
A19: Temps | B19: 0 | C19: 0 | D19: 0 | E19: 0 | F19: 0 | G19: 0 | H19: 0 | I19: 0 | J19: 0 | K19: 0 | L19: 0 | M19: 0 | N19: =SUM(B19:M19) | O19: 0 | P19: 0 | Q19: 0 | R19: 0 | S19: 0 | T19: 0 | U19: 0 | V19: 0 | W19: 0 | X19: 0 | Y19: 0 | Z19: 0 | AA19: =SUM(O19:U19) | AB19: =SUM(O19:Z19) | AC19: 0 | AD19: 0 | AE19: 0 | AF19: 0 | AG19: 0 | AH19: 0 | AI19: =SUM(AC19:AH19) | AJ19: =SUM(AC19:AH19)+AI19 | AK19: =IF(N19<>0,(AB19-N19)/ABS(N19),0) | AL19: =IF(AB19<>0,(AJ19-AB19)/ABS(AB19),0)
A20: Total Personnel | B20: =B11+B12+B13+B14+B15+B16+B17+B18+B19 | C20: =C11+C12+C13+C14+C15+C16+C17+C18+C19 | D20: =D11+D12+D13+D14+D15+D16+D17+D18+D19 | E20: =E11+E12+E13+E14+E15+E16+E17+E18+E19 | F20: =F11+F12+F13+F14+F15+F16+F17+F18+F19 | G20: =G11+G12+G13+G14+G15+G16+G17+G18+G19 | H20: =H11+H12+H13+H14+H15+H16+H17+H18+H19 | I20: =I11+I12+I13+I14+I15+I16+I17+I18+I19 | ... AJ20: =AJ11+AJ12+AJ13+AJ14+AJ15+AJ16+AJ17+AJ18+AJ19 | AK20: =IF(N20<>0,(AB20-N20)/ABS(N20),0) | AL20: =IF(AB20<>0,(AJ20-AB20)/ABS(AB20),0)
A21: Sal:Rev | B21: =IF(B7>0,B20/B7,0) | C21: =IF(C7>0,C20/C7,0) | D21: =IF(D7>0,D20/D7,0) | E21: =IF(E7>0,E20/E7,0) | F21: =IF(F7>0,F20/F7,0) | G21: =IF(G7>0,G20/G7,0) | H21: =IF(H7>0,H20/H7,0) | I21: =IF(I7>0,I20/I7,0) | ... AJ21: =IF(AJ7>0,AJ20/AJ7,0)
A23: Childcare
A24: Catering Costs | N24: =SUM(B24:M24) | O24: 1124.3 | P24: 897.62 | Q24: 1008.18 | R24: 1170.82 | S24: 811.64 | T24: 968.12 | U24: 1225.01 | V24: 559.62 | W24: 610.02 | X24: 657.09 | Y24: 744.51 | Z24: 812.28 | AA24: =SUM(O24:U24) | AB24: =SUM(O24:Z24) | AC24: 849.4794 | AD24: 805.2084 | AE24: 945.234 | AF24: 916.3077 | AG24: 926.568 | AH24: 990.0612 | AI24: =SUM(AC24:AH24) | AJ24: =SUM(AC24:AH24)+AI24 | AK24: =IF(N24<>0,(AB24-N24)/ABS(N24),0) | AL24: =IF(AB24<>0,(AJ24-AB24)/ABS(AB24),0)
