Workbook

Sheet Budget V Actuals
A1: Budget Analysis
A3: 2026 Budget (Ops FinPlan) | B3: Q1 | T3: Q2 | AL3: Q3 | BD3: Q4
B4: Abacus | C4: Bees Knees | D4: Bramleywood | E4: Cedars | F4: Hazebrouck | G4: Kingsclere | H4: Merrydale | I4: Stepping Stones | J4: Happitots | K4: Northumberland | L4: Smart Tots | M4: Lower Earley | N4: Woosehill | O4: Our Den | P4: Finchampstead | Q4: Boot Farm | R4: Saltway | S4: Quarter Total | T4: Abacus | U4: Bees Knees | V4: Bramleywood | W4: Cedars | X4: Hazebrouck | Y4: Kingsclere | Z4: Merrydale | AA4: Stepping Stones | AB4: Happitots | AC4: Northumberland | AD4: Smart Tots | AE4: Lower Earley | AF4: Woosehill | AG4: Our Den | AH4: Finchampstead | AI4: Boot Farm | AJ4: Saltway | AK4: Quarter Total | AL4: Abacus | AM4: Bees Knees | AN4: Bramleywood | AO4: Cedars | AP4: Hazebrouck | AQ4: Kingsclere | AR4: Merrydale | AS4: Stepping Stones | AT4: Happitots | AU4: Northumberland | AV4: Smart Tots | AW4: Lower Earley | AX4: Woosehill | AY4: Our Den | AZ4: Finchampstead | BA4: Boot Farm | BB4: Saltway | BC4: Quarter Total | BD4: Abacus | BE4: Bees Knees | BF4: Bramleywood | BG4: Cedars | BH4: Hazebrouck | BI4: Kingsclere | BJ4: Merrydale | BK4: Stepping Stones | BL4: Happitots | BM4: Northumberland | BN4: Smart Tots | BO4: Lower Earley | BP4: Woosehill | BQ4: Our Den | BR4: Finchampstead | BS4: Boot Farm | BT4: Saltway | BU4: Quarter Total | BV4: Year Total
A5: Total Income | B5: 260830 | C5: 125630 | D5: 563670 | E5: 106810 | F5: 196490 | G5: 91990 | H5: 291750 | I5: 199710 | J5: 192250 | K5: 67480 | L5: 149900 | M5: 112690 | N5: 115620 | O5: 33250 | P5: 39450 | Q5: 157130 | R5: 269610 | S5: =SUM(B5:R5) | T5: 289080 | U5: 136960 | V5: 602667 | W5: 115829 | X5: 216765 | Y5: 100403 | Z5: 308563 | AA5: 209965 | AB5: 213061 | AC5: 77021 | AD5: 161488 | AE5: 123501 | AF5: 128445 | AG5: 41028 | AH5: 50569 | AI5: 166369 | AJ5: 293768 | AK5: =SUM(T5:AJ5) | AL5: 270220 | AM5: 122044 | AN5: 546014 | AO5: 119279 | AP5: 193416 | AQ5: 90431 | AR5: 319479 | AS5: 211677 | AT5: 219255 | AU5: 83356 | AV5: 151026 | AW5: 99904 | AX5: 117375 | AY5: 25707 | AZ5: 60559 | BA5: 141201 | BB5: 272107 | BC5: =SUM(AL5:BB5) | BD5: 294034 | BE5: 125569 | BF5: 585332 | BG5: 126433 | BH5: 212338 | BI5: 95981 | BJ5: 330732 | BK5: 198993 | BL5: 239586 | BM5: 100916 | BN5: 161717 | BO5: 111841 | BP5: 131477 | BQ5: 31543 | BR5: 92357 | BS5: 162850 | BT5: 311515 | BU5: =SUM(BD5:BT5) | BV5: =BU5+BC5+AK5+S5
A6: Total Personnel | B6: 126099 | C6: 65767 | D6: 244486 | E6: 60422 | F6: 85681 | G6: 61987 | H6: 109560 | I6: 98915 | J6: 127573 | K6: 53861 | L6: 92441 | M6: 70972 | N6: 84600 | O6: 20939 | P6: 57407 | Q6: 79138 | R6: 127724 | S6: =SUM(B6:R6) | T6: 132075 | U6: 68350 | V6: 254017 | W6: 62673 | X6: 89313 | Y6: 64380 | Z6: 114145 | AA6: 104283 | AB6: 132338 | AC6: 56614 | AD6: 97542 | AE6: 73628 | AF6: 87870 | AG6: 21772 | AH6: 59738 | AI6: 82603 | AJ6: 133213 | AK6: =SUM(T6:AJ6) | AL6: 132075 | AM6: 68350 | AN6: 254026 | AO6: 62673 | AP6: 89313 | AQ6: 64389 | AR6: 114154 | AS6: 104283 | AT6: 132338 | AU6: 56614 | AV6: 97542 | AW6: 73628 | AX6: 87870 | AY6: 21772 | AZ6: 59738 | BA6: 82603 | BB6: 133213 | BC6: =SUM(AL6:BB6) | BD6: 132075 | BE6: 68350 | BF6: 254035 | BG6: 62673 | BH6: 89331 | BI6: 64398 | BJ6: 114163 | BK6: 104283 | BL6: 132338 | BM6: 56614 | BN6: 97542 | BO6: 73628 | BP6: 87933 | BQ6: 21772 | BR6: 59738 | BS6: 82603 | BT6: 133213 | BU6: =SUM(BD6:BT6) | BV6: =BU6+BC6+AK6+S6
A7: Total Childcare Costs | B7: 10736 | C7: 5074 | D7: 20598 | E7: 4659 | F7: 7380 | G7: 3980 | H7: 11678 | I7: 7490 | J7: 7906 | K7: 2729 | L7: 5849 | M7: 4363 | N7: 4584 | O7: 1503 | P7: 1726 | Q7: 6571 | R7: 10845 | S7: =SUM(B7:R7) | T7: 11875 | U7: 5504 | V7: 22020 | W7: 5001 | X7: 8128 | Y7: 4316 | Z7: 12340 | AA7: 7859 | AB7: 8696 | AC7: 3073 | AD7: 6287 | AE7: 4770 | AF7: 5076 | AG7: 1801 | AH7: 2144 | AI7: 6922 | AJ7: 11763 | AK7: =SUM(T7:AJ7) | AL7: 11130 | AM7: 4938 | AN7: 19998 | AO7: 5133 | AP7: 7305 | AQ7: 3917 | AR7: 12784 | AS7: 7920 | AT7: 8932 | AU7: 3301 | AV7: 5909 | AW7: 3939 | AX7: 4685 | AY7: 1267 | AZ7: 2522 | BA7: 5966 | BB7: 10940 | BC7: =SUM(AL7:BB7) | BD7: 12091 | BE7: 5072 | BF7: 21432 | BG7: 5404 | BH7: 8004 | BI7: 4139 | BJ7: 13241 | BK7: 7464 | BL7: 9704 | BM7: 3933 | BN7: 6314 | BO7: 4386 | BP7: 5225 | BQ7: 1496 | BR7: 3685 | BS7: 6788 | BT7: 12438 | BU7: =SUM(BD7:BT7) | BV7: =BU7+BC7+AK7+S7
A8: Total Premises & Admin | B8: 16555 | C8: 9048 | D8: 38163 | E8: 15032 | F8: 31746 | G8: 11268 | H8: 23828 | I8: 9723 | J8: 19906 | K8: 10561 | L8: 10295 | M8: 10912 | N8: 17759 | O8: 5127 | P8: 13215 | Q8: 22364 | R8: 13615 | S8: =SUM(B8:R8) | T8: 18536 | U8: 14116 | V8: 47366 | W8: 5634 | X8: 29332 | Y8: 11109 | Z8: 24523 | AA8: 9726 | AB8: 16905 | AC8: 11811 | AD8: 17824 | AE8: 14396 | AF8: 20628 | AG8: 4849 | AH8: 13078 | AI8: 19316 | AJ8: 13436 | AK8: =SUM(T8:AJ8) | AL8: 15036 | AM8: 9116 | AN8: 36366 | AO8: 5634 | AP8: 33082 | AQ8: 6609 | AR8: 16023 | AS8: 14726 | AT8: 15405 | AU8: 13811 | AV8: 19074 | AW8: 14896 | AX8: 15628 | AY8: 4849 | AZ8: 11778 | BA8: 21616 | BB8: 14936 | BC8: =SUM(AL8:BB8) | BD8: 15036 | BE8: 9116 | BF8: 34866 | BG8: 5634 | BH8: 29082 | BI8: 6609 | BJ8: 16023 | BK8: 9726 | BL8: 15405 | BM8: 11811 | BN8: 15324 | BO8: 13896 | BP8: 15628 | BQ8: 4849 | BR8: 11778 | BS8: 17316 | BT8: 13436 | BU8: =SUM(BD8:BT8) | BV8: =BU8+BC8+AK8+S8
A9: Total Direct Costs | B9: =SUM(B6:B8) | C9: =SUM(C6:C8) | D9: =SUM(D6:D8) | E9: =SUM(E6:E8) | F9: =SUM(F6:F8) | G9: =SUM(G6:G8) | H9: =SUM(H6:H8) | I9: =SUM(I6:I8) | ... R9: =SUM(R6:R8) | S9: =SUM(B9:R9) | T9: =SUM(T6:T8) | U9: =SUM(U6:U8) | V9: =SUM(V6:V8) | W9: =SUM(W6:W8) | X9: =SUM(X6:X8) | Y9: =SUM(Y6:Y8) | Z9: =SUM(Z6:Z8) | AA9: =SUM(AA6:AA8) | ... AJ9: =SUM(AJ6:AJ8) | AK9: =SUM(T9:AJ9) | AL9: =SUM(AL6:AL8) | AM9: =SUM(AM6:AM8) | AN9: =SUM(AN6:AN8) | AO9: =SUM(AO6:AO8) | AP9: =SUM(AP6:AP8) | AQ9: =SUM(AQ6:AQ8) | AR9: =SUM(AR6:AR8) | AS9: =SUM(AS6:AS8) | ... BB9: =SUM(BB6:BB8) | BC9: =SUM(AL9:BB9) | BD9: =SUM(BD6:BD8) | BE9: =SUM(BE6:BE8) | BF9: =SUM(BF6:BF8) | BG9: =SUM(BG6:BG8) | BH9: =SUM(BH6:BH8) | BI9: =SUM(BI6:BI8) | BJ9: =SUM(BJ6:BJ8) | BK9: =SUM(BK6:BK8) | ... BT9: =SUM(BT6:BT8) | BU9: =SUM(BD9:BT9) | BV9: =BU9+BC9+AK9+S9
A11: CONTRIBUTION | B11: =B5-B9 | C11: =C5-C9 | D11: =D5-D9 | E11: =E5-E9 | F11: =F5-F9 | G11: =G5-G9 | H11: =H5-H9 | I11: =I5-I9 | ... R11: =R5-R9 | S11: =SUM(B11:R11) | T11: =T5-T9 | U11: =U5-U9 | V11: =V5-V9 | W11: =W5-W9 | X11: =X5-X9 | Y11: =Y5-Y9 | Z11: =Z5-Z9 | AA11: =AA5-AA9 | ... AJ11: =AJ5-AJ9 | AK11: =SUM(T11:AJ11) | AL11: =AL5-AL9 | AM11: =AM5-AM9 | AN11: =AN5-AN9 | AO11: =AO5-AO9 | AP11: =AP5-AP9 | AQ11: =AQ5-AQ9 | AR11: =AR5-AR9 | AS11: =AS5-AS9 | ... BB11: =BB5-BB9 | BC11: =SUM(AL11:BB11) | BD11: =BD5-BD9 | BE11: =BE5-BE9 | BF11: =BF5-BF9 | BG11: =BG5-BG9 | BH11: =BH5-BH9 | BI11: =BI5-BI9 | BJ11: =BJ5-BJ9 | BK11: =BK5-BK9 | ... BT11: =BT5-BT9 | BU11: =SUM(BD11:BT11) | BV11: =BU11+BC11+AK11+S11
B12: =B11/B9 | C12: =C11/C9 | D12: =D11/D9 | E12: =E11/E9 | F12: =F11/F9 | G12: =G11/G9 | H12: =H11/H9 | I12: =I11/I9 | ... BV12: =BV11/BV9
A14: 2026 Actuals | B14: Q1 | T14: Q2 | U14: FORECAST DATA | AL14: Q3 | AM14: FORECAST DATA | BD14: Q4 | BE14: FORECAST DATA
B15: Abacus | C15: Bees Knees | D15: Bramleywood | E15: Cedars | F15: Hazebrouck | G15: Kingsclere | H15: Merrydale | I15: Stepping Stones | J15: Happitots | K15: Northumberland | L15: Smart Tots | M15: Lower Earley | N15: Woosehill | O15: Our Den | P15: Finchampstead | Q15: Boot Farm | R15: Saltway | S15: Totals | T15: Abacus | U15: Bees Knees | V15: Bramleywood | W15: Cedars | X15: Hazebrouck | Y15: Kingsclere | Z15: Merrydale | AA15: Stepping Stones | AB15: Happitots | AC15: Northumberland | AD15: Smart Tots | AE15: Lower Earley | AF15: Woosehill | AG15: Our Den | AH15: Finchampstead | AI15: Boot Farm | AJ15: Saltway | AK15: Totals | AL15: Abacus | AM15: Bees Knees | AN15: Bramleywood | AO15: Cedars | AP15: Hazebrouck | AQ15: Kingsclere | AR15: Merrydale | AS15: Stepping Stones | AT15: Happitots | AU15: Northumberland | AV15: Smart Tots | AW15: Lower Earley | AX15: Woosehill | AY15: Our Den | AZ15: Finchampstead | BA15: Boot Farm | BB15: Saltway | BC15: Totals | BD15: Abacus | BE15: Bees Knees | BF15: Bramleywood | BG15: Cedars | BH15: Hazebrouck | BI15: Kingsclere | BJ15: Merrydale | BK15: Stepping Stones | BL15: Happitots | BM15: Northumberland | BN15: Smart Tots | BO15: Lower Earley | BP15: Woosehill | BQ15: Our Den | BR15: Finchampstead | BS15: Boot Farm | BT15: Saltway | BU15: Totals | BV15: Year Total
A16: Total Income | B16: =SUM('[1]ABA P&L'!$O11:$Q11) | C16: =SUM('[1]BK P&L'!$O11:$Q11) | D16: =SUM('[1]BW P&L'!$O11:$Q11) | E16: =SUM('[1]CED P&L'!$O11:$Q11) | F16: =SUM('[1]HB P&L'!$O11:$Q11) | G16: =SUM('[1]KIN P&L'!$O11:$Q11) | H16: =SUM('[1]MER P&L'!$O11:$Q11) | I16: =SUM('[1]SST P&L'!$O11:$Q11) | J16: =SUM('[1]HDN P&L'!$O11:$Q11) | K16: =SUM('[1]NDN P&L'!$O11:$Q11) | L16: =SUM('[1]SDN P&L'!$O11:$Q11) | M16: =SUM('[1]LE P&L'!$O11:$Q11) | N16: =SUM('[1]WH P&L'!$O11:$Q11) | O16: =SUM('[1]HS P&L'!$O11:$Q11) | P16: =SUM('[1]FH P&L'!$O11:$Q11) | Q16: =SUM('[1]HAB P&L'!$O11:$Q11) | R16: =SUM('[1]SALT P&L'!$O11:$Q11) | S16: =SUM(B16:R16) | T16: =SUM('[1]ABA P&L'!$R11:$T11) | U16: =SUM('[1]BK P&L'!$R11:$T11) | V16: =SUM('[1]BW P&L'!$R11:$T11) | W16: =SUM('[1]CED P&L'!$R11:$T11) | X16: =SUM('[1]HB P&L'!$R11:$T11) | Y16: =SUM('[1]KIN P&L'!$R11:$T11) | Z16: =SUM('[1]MER P&L'!$R11:$T11) | AA16: =SUM('[1]SST P&L'!$R11:$T11) | AB16: =SUM('[1]HDN P&L'!$R11:$T11) | AC16: =SUM('[1]NDN P&L'!$R11:$T11) | AD16: =SUM('[1]SDN P&L'!$R11:$T11) | AE16: =SUM('[1]LE P&L'!$R11:$T11) | AF16: =SUM('[1]WH P&L'!$R11:$T11) | AG16: =SUM('[1]HS P&L'!$R11:$T11) | AH16: =SUM('[1]FH P&L'!$R11:$T11) | AI16: =SUM('[1]HAB P&L'!$R11:$T11) | AJ16: =SUM('[1]SALT P&L'!$R11:$T11) | AK16: =SUM(T16:AJ16) | AL16: =SUM('[1]ABA P&L'!$U11:$W11) | AM16: =SUM('[1]BK P&L'!$U11:$W11) | AN16: =SUM('[1]BW P&L'!$U11:$W11) | AO16: =SUM('[1]CED P&L'!$U11:$W11) | AP16: =SUM('[1]HB P&L'!$U11:$W11) | AQ16: =SUM('[1]KIN P&L'!$U11:$W11) | AR16: =SUM('[1]MER P&L'!$U11:$W11) | AS16: =SUM('[1]SST P&L'!$U11:$W11) | AT16: =SUM('[1]HDN P&L'!$U11:$W11) | AU16: =SUM('[1]NDN P&L'!$U11:$W11) | AV16: =SUM('[1]SDN P&L'!$U11:$W11) | AW16: =SUM('[1]LE P&L'!$U11:$W11) | AX16: =SUM('[1]WH P&L'!$U11:$W11) | AY16: =SUM('[1]HS P&L'!$U11:$W11) | AZ16: =SUM('[1]FH P&L'!$U11:$W11) | BA16: =SUM('[1]HAB P&L'!$U11:$W11) | BB16: =SUM('[1]SALT P&L'!$U11:$W11) | BC16: =SUM(AL16:BB16) | BD16: =SUM('[1]ABA P&L'!$X11:$Z11) | BE16: =SUM('[1]BK P&L'!$X11:$Z11) | BF16: =SUM('[1]BW P&L'!$X11:$Z11) | BG16: =SUM('[1]CED P&L'!$X11:$Z11) | BH16: =SUM('[1]HB P&L'!$X11:$Z11) | BI16: =SUM('[1]KIN P&L'!$X11:$Z11) | BJ16: =SUM('[1]MER P&L'!$X11:$Z11) | BK16: =SUM('[1]SST P&L'!$X11:$Z11) | BL16: =SUM('[1]HDN P&L'!$X11:$Z11) | BM16: =SUM('[1]NDN P&L'!$X11:$Z11) | BN16: =SUM('[1]SDN P&L'!$X11:$Z11) | BO16: =SUM('[1]LE P&L'!$X11:$Z11) | BP16: =SUM('[1]WH P&L'!$X11:$Z11) | BQ16: =SUM('[1]HS P&L'!$X11:$Z11) | BR16: =SUM('[1]FH P&L'!$X11:$Z11) | BS16: =SUM('[1]HAB P&L'!$X11:$Z11) | BT16: =SUM('[1]SALT P&L'!$X11:$Z11) | BU16: =SUM(BD16:BT16) | BV16: =BU16+BC16+AK16+S16
A17: Total Personnel | B17: =SUM('[1]ABA P&L'!$O23:$Q23) | C17: =SUM('[1]BK P&L'!$O23:$Q23) | D17: =SUM('[1]BW P&L'!$O23:$Q23) | E17: =SUM('[1]CED P&L'!$O23:$Q23) | F17: =SUM('[1]HB P&L'!$O23:$Q23) | G17: =SUM('[1]KIN P&L'!$O23:$Q23) | H17: =SUM('[1]MER P&L'!$O23:$Q23) | I17: =SUM('[1]SST P&L'!$O23:$Q23) | J17: =SUM('[1]HDN P&L'!$O23:$Q23) | K17: =SUM('[1]NDN P&L'!$O23:$Q23) | L17: =SUM('[1]SDN P&L'!$O23:$Q23) | M17: =SUM('[1]LE P&L'!$O23:$Q23) | N17: =SUM('[1]WH P&L'!$O23:$Q23) | O17: =SUM('[1]HS P&L'!$O23:$Q23) | P17: =SUM('[1]FH P&L'!$O23:$Q23) | Q17: =SUM('[1]HAB P&L'!$O23:$Q23) | R17: =SUM('[1]SALT P&L'!$O23:$Q23) | S17: =SUM(B17:R17) | T17: =SUM('[1]ABA P&L'!$R23:$T23) | U17: =SUM('[1]BK P&L'!$R23:$T23) | V17: =SUM('[1]BW P&L'!$R23:$T23) | W17: =SUM('[1]CED P&L'!$R23:$T23) | X17: =SUM('[1]HB P&L'!$R23:$T23) | Y17: =SUM('[1]KIN P&L'!$R23:$T23) | Z17: =SUM('[1]MER P&L'!$R23:$T23) | AA17: =SUM('[1]SST P&L'!$R23:$T23) | AB17: =SUM('[1]HDN P&L'!$R23:$T23) | AC17: =SUM('[1]NDN P&L'!$R23:$T23) | AD17: =SUM('[1]SDN P&L'!$R23:$T23) | AE17: =SUM('[1]LE P&L'!$R23:$T23) | AF17: =SUM('[1]WH P&L'!$R23:$T23) | AG17: =SUM('[1]HS P&L'!$R23:$T23) | AH17: =SUM('[1]FH P&L'!$R23:$T23) | AI17: =SUM('[1]HAB P&L'!$R23:$T23) | AJ17: =SUM('[1]SALT P&L'!$R23:$T23) | AK17: =SUM(T17:AJ17) | AL17: =SUM('[1]ABA P&L'!$U23:$W23) | AM17: =SUM('[1]BK P&L'!$U23:$W23) | AN17: =SUM('[1]BW P&L'!$U23:$W23) | AO17: =SUM('[1]CED P&L'!$U23:$W23) | AP17: =SUM('[1]HB P&L'!$U23:$W23) | AQ17: =SUM('[1]KIN P&L'!$U23:$W23) | AR17: =SUM('[1]MER P&L'!$U23:$W23) | AS17: =SUM('[1]SST P&L'!$U23:$W23) | AT17: =SUM('[1]HDN P&L'!$U23:$W23) | AU17: =SUM('[1]NDN P&L'!$U23:$W23) | AV17: =SUM('[1]SDN P&L'!$U23:$W23) | AW17: =SUM('[1]LE P&L'!$U23:$W23) | AX17: =SUM('[1]WH P&L'!$U23:$W23) | AY17: =SUM('[1]HS P&L'!$U23:$W23) | AZ17: =SUM('[1]FH P&L'!$U23:$W23) | BA17: =SUM('[1]HAB P&L'!$U23:$W23) | BB17: =SUM('[1]SALT P&L'!$U23:$W23) | BC17: =SUM(AL17:BB17) | BD17: =SUM('[1]ABA P&L'!$X23:$Z23) | BE17: =SUM('[1]BK P&L'!$X23:$Z23) | BF17: =SUM('[1]BW P&L'!$X23:$Z23) | BG17: =SUM('[1]CED P&L'!$X23:$Z23) | BH17: =SUM('[1]HB P&L'!$X23:$Z23) | BI17: =SUM('[1]KIN P&L'!$X23:$Z23) | BJ17: =SUM('[1]MER P&L'!$X23:$Z23) | BK17: =SUM('[1]SST P&L'!$X23:$Z23) | BL17: =SUM('[1]HDN P&L'!$X23:$Z23) | BM17: =SUM('[1]NDN P&L'!$X23:$Z23) | BN17: =SUM('[1]SDN P&L'!$X23:$Z23) | BO17: =SUM('[1]LE P&L'!$X23:$Z23) | BP17: =SUM('[1]WH P&L'!$X23:$Z23) | BQ17: =SUM('[1]HS P&L'!$X23:$Z23) | BR17: =SUM('[1]FH P&L'!$X23:$Z23) | BS17: =SUM('[1]HAB P&L'!$X23:$Z23) | BT17: =SUM('[1]SALT P&L'!$X23:$Z23) | BU17: =SUM(BD17:BT17) | BV17: =BU17+BC17+AK17+S17
A18: Total Childcare Costs | B18: =SUM('[1]ABA P&L'!$O32:$Q32) | C18: =SUM('[1]BK P&L'!$O32:$Q32) | D18: =SUM('[1]BW P&L'!$O32:$Q32) | E18: =SUM('[1]CED P&L'!$O32:$Q32) | F18: =SUM('[1]HB P&L'!$O32:$Q32) | G18: =SUM('[1]KIN P&L'!$O32:$Q32) | H18: =SUM('[1]MER P&L'!$O32:$Q32) | I18: =SUM('[1]SST P&L'!$O32:$Q32) | J18: =SUM('[1]HDN P&L'!$O32:$Q32) | K18: =SUM('[1]NDN P&L'!$O32:$Q32) | L18: =SUM('[1]SDN P&L'!$O32:$Q32) | M18: =SUM('[1]LE P&L'!$O32:$Q32) | N18: =SUM('[1]WH P&L'!$O32:$Q32) | O18: =SUM('[1]HS P&L'!$O32:$Q32) | P18: =SUM('[1]FH P&L'!$O32:$Q32) | Q18: =SUM('[1]HAB P&L'!$O32:$Q32) | R18: =SUM('[1]SALT P&L'!$O32:$Q32) | S18: =SUM(B18:R18) | T18: =SUM('[1]ABA P&L'!$R32:$T32) | U18: =SUM('[1]BK P&L'!$R32:$T32) | V18: =SUM('[1]BW P&L'!$R32:$T32) | W18: =SUM('[1]CED P&L'!$R32:$T32) | X18: =SUM('[1]HB P&L'!$R32:$T32) | Y18: =SUM('[1]KIN P&L'!$R32:$T32) | Z18: =SUM('[1]MER P&L'!$R32:$T32) | AA18: =SUM('[1]SST P&L'!$R32:$T32) | AB18: =SUM('[1]HDN P&L'!$R32:$T32) | AC18: =SUM('[1]NDN P&L'!$R32:$T32) | AD18: =SUM('[1]SDN P&L'!$R32:$T32) | AE18: =SUM('[1]LE P&L'!$R32:$T32) | AF18: =SUM('[1]WH P&L'!$R32:$T32) | AG18: =SUM('[1]HS P&L'!$R32:$T32) | AH18: =SUM('[1]FH P&L'!$R32:$T32) | AI18: =SUM('[1]HAB P&L'!$R32:$T32) | AJ18: =SUM('[1]SALT P&L'!$R32:$T32) | AK18: =SUM(T18:AJ18) | AL18: =SUM('[1]ABA P&L'!$U32:$W32) | AM18: =SUM('[1]BK P&L'!$U32:$W32) | AN18: =SUM('[1]BW P&L'!$U32:$W32) | AO18: =SUM('[1]CED P&L'!$U32:$W32) | AP18: =SUM('[1]HB P&L'!$U32:$W32) | AQ18: =SUM('[1]KIN P&L'!$U32:$W32) | AR18: =SUM('[1]MER P&L'!$U32:$W32) | AS18: =SUM('[1]SST P&L'!$U32:$W32) | AT18: =SUM('[1]HDN P&L'!$U32:$W32) | AU18: =SUM('[1]NDN P&L'!$U32:$W32) | AV18: =SUM('[1]SDN P&L'!$U32:$W32) | AW18: =SUM('[1]LE P&L'!$U32:$W32) | AX18: =SUM('[1]WH P&L'!$U32:$W32) | AY18: =SUM('[1]HS P&L'!$U32:$W32) | AZ18: =SUM('[1]FH P&L'!$U32:$W32) | BA18: =SUM('[1]HAB P&L'!$U32:$W32) | BB18: =SUM('[1]SALT P&L'!$U32:$W32) | BC18: =SUM(AL18:BB18) | BD18: =SUM('[1]ABA P&L'!$X32:$Z32) | BE18: =SUM('[1]BK P&L'!$X32:$Z32) | BF18: =SUM('[1]BW P&L'!$X32:$Z32) | BG18: =SUM('[1]CED P&L'!$X32:$Z32) | BH18: =SUM('[1]HB P&L'!$X32:$Z32) | BI18: =SUM('[1]KIN P&L'!$X32:$Z32) | BJ18: =SUM('[1]MER P&L'!$X32:$Z32) | BK18: =SUM('[1]SST P&L'!$X32:$Z32) | BL18: =SUM('[1]HDN P&L'!$X32:$Z32) | BM18: =SUM('[1]NDN P&L'!$X32:$Z32) | BN18: =SUM('[1]SDN P&L'!$X32:$Z32) | BO18: =SUM('[1]LE P&L'!$X32:$Z32) | BP18: =SUM('[1]WH P&L'!$X32:$Z32) | BQ18: =SUM('[1]HS P&L'!$X32:$Z32) | BR18: =SUM('[1]FH P&L'!$X32:$Z32) | BS18: =SUM('[1]HAB P&L'!$X32:$Z32) | BT18: =SUM('[1]SALT P&L'!$X32:$Z32) | BU18: =SUM(BD18:BT18) | BV18: =BU18+BC18+AK18+S18
A19: Total Premises & Admin | B19: =SUM('[1]ABA P&L'!$O45:$Q45) | C19: =SUM('[1]BK P&L'!$O45:$Q45) | D19: =SUM('[1]BW P&L'!$O45:$Q45) | E19: =SUM('[1]CED P&L'!$O45:$Q45) | F19: =SUM('[1]HB P&L'!$O45:$Q45) | G19: =SUM('[1]KIN P&L'!$O45:$Q45) | H19: =SUM('[1]MER P&L'!$O45:$Q45) | I19: =SUM('[1]SST P&L'!$O45:$Q45) | J19: =SUM('[1]HDN P&L'!$O45:$Q45) | K19: =SUM('[1]NDN P&L'!$O45:$Q45) | L19: =SUM('[1]SDN P&L'!$O45:$Q45) | M19: =SUM('[1]LE P&L'!$O45:$Q45) | N19: =SUM('[1]WH P&L'!$O45:$Q45) | O19: =SUM('[1]HS P&L'!$O45:$Q45) | P19: =SUM('[1]FH P&L'!$O45:$Q45) | Q19: =SUM('[1]HAB P&L'!$O45:$Q45) | R19: =SUM('[1]SALT P&L'!$O45:$Q45) | S19: =SUM(B19:R19) | T19: =SUM('[1]ABA P&L'!$R45:$T45) | U19: =SUM('[1]BK P&L'!$R45:$T45) | V19: =SUM('[1]BW P&L'!$R45:$T45) | W19: =SUM('[1]CED P&L'!$R45:$T45) | X19: =SUM('[1]HB P&L'!$R45:$T45) | Y19: =SUM('[1]KIN P&L'!$R45:$T45) | Z19: =SUM('[1]MER P&L'!$R45:$T45) | AA19: =SUM('[1]SST P&L'!$R45:$T45) | AB19: =SUM('[1]HDN P&L'!$R45:$T45) | AC19: =SUM('[1]NDN P&L'!$R45:$T45) | AD19: =SUM('[1]SDN P&L'!$R45:$T45) | AE19: =SUM('[1]LE P&L'!$R45:$T45) | AF19: =SUM('[1]WH P&L'!$R45:$T45) | AG19: =SUM('[1]HS P&L'!$R45:$T45) | AH19: =SUM('[1]FH P&L'!$R45:$T45) | AI19: =SUM('[1]HAB P&L'!$R45:$T45) | AJ19: =SUM('[1]SALT P&L'!$R45:$T45) | AK19: =SUM(T19:AJ19) | AL19: =SUM('[1]ABA P&L'!$U45:$W45) | AM19: =SUM('[1]BK P&L'!$U45:$W45) | AN19: =SUM('[1]BW P&L'!$U45:$W45) | AO19: =SUM('[1]CED P&L'!$U45:$W45) | AP19: =SUM('[1]HB P&L'!$U45:$W45) | AQ19: =SUM('[1]KIN P&L'!$U45:$W45) | AR19: =SUM('[1]MER P&L'!$U45:$W45) | AS19: =SUM('[1]SST P&L'!$U45:$W45) | AT19: =SUM('[1]HDN P&L'!$U45:$W45) | AU19: =SUM('[1]NDN P&L'!$U45:$W45) | AV19: =SUM('[1]SDN P&L'!$U45:$W45) | AW19: =SUM('[1]LE P&L'!$U45:$W45) | AX19: =SUM('[1]WH P&L'!$U45:$W45) | AY19: =SUM('[1]HS P&L'!$U45:$W45) | AZ19: =SUM('[1]FH P&L'!$U45:$W45) | BA19: =SUM('[1]HAB P&L'!$U45:$W45) | BB19: =SUM('[1]SALT P&L'!$U45:$W45) | BC19: =SUM(AL19:BB19) | BD19: =SUM('[1]ABA P&L'!$X45:$Z45) | BE19: =SUM('[1]BK P&L'!$X45:$Z45) | BF19: =SUM('[1]BW P&L'!$X45:$Z45) | BG19: =SUM('[1]CED P&L'!$X45:$Z45) | BH19: =SUM('[1]HB P&L'!$X45:$Z45) | BI19: =SUM('[1]KIN P&L'!$X45:$Z45) | BJ19: =SUM('[1]MER P&L'!$X45:$Z45) | BK19: =SUM('[1]SST P&L'!$X45:$Z45) | BL19: =SUM('[1]HDN P&L'!$X45:$Z45) | BM19: =SUM('[1]NDN P&L'!$X45:$Z45) | BN19: =SUM('[1]SDN P&L'!$X45:$Z45) | BO19: =SUM('[1]LE P&L'!$X45:$Z45) | BP19: =SUM('[1]WH P&L'!$X45:$Z45) | BQ19: =SUM('[1]HS P&L'!$X45:$Z45) | BR19: =SUM('[1]FH P&L'!$X45:$Z45) | BS19: =SUM('[1]HAB P&L'!$X45:$Z45) | BT19: =SUM('[1]SALT P&L'!$X45:$Z45) | BU19: =SUM(BD19:BT19) | BV19: =BU19+BC19+AK19+S19
A20: Total Direct Costs | B20: =SUM('[1]ABA P&L'!$O46:$Q46) | C20: =SUM('[1]BK P&L'!$O46:$Q46) | D20: =SUM('[1]BW P&L'!$O46:$Q46) | E20: =SUM('[1]CED P&L'!$O46:$Q46) | F20: =SUM('[1]HB P&L'!$O46:$Q46) | G20: =SUM('[1]KIN P&L'!$O46:$Q46) | H20: =SUM('[1]MER P&L'!$O46:$Q46) | I20: =SUM('[1]SST P&L'!$O46:$Q46) | J20: =SUM('[1]HDN P&L'!$O46:$Q46) | K20: =SUM('[1]NDN P&L'!$O46:$Q46) | L20: =SUM('[1]SDN P&L'!$O46:$Q46) | M20: =SUM('[1]LE P&L'!$O46:$Q46) | N20: =SUM('[1]WH P&L'!$O46:$Q46) | O20: =SUM('[1]HS P&L'!$O46:$Q46) | P20: =SUM('[1]FH P&L'!$O46:$Q46) | Q20: =SUM('[1]HAB P&L'!$O46:$Q46) | R20: =SUM('[1]SALT P&L'!$O46:$Q46) | S20: =SUM(B20:R20) | T20: =SUM('[1]ABA P&L'!$R46:$T46) | U20: =SUM('[1]BK P&L'!$R46:$T46) | V20: =SUM('[1]BW P&L'!$R46:$T46) | W20: =SUM('[1]CED P&L'!$R46:$T46) | X20: =SUM('[1]HB P&L'!$R46:$T46) | Y20: =SUM('[1]KIN P&L'!$R46:$T46) | Z20: =SUM('[1]MER P&L'!$R46:$T46) | AA20: =SUM('[1]SST P&L'!$R46:$T46) | AB20: =SUM('[1]HDN P&L'!$R46:$T46) | AC20: =SUM('[1]NDN P&L'!$R46:$T46) | AD20: =SUM('[1]SDN P&L'!$R46:$T46) | AE20: =SUM('[1]LE P&L'!$R46:$T46) | AF20: =SUM('[1]WH P&L'!$R46:$T46) | AG20: =SUM('[1]HS P&L'!$R46:$T46) | AH20: =SUM('[1]FH P&L'!$R46:$T46) | AI20: =SUM('[1]HAB P&L'!$R46:$T46) | AJ20: =SUM('[1]SALT P&L'!$R46:$T46) | AK20: =SUM(T20:AJ20) | AL20: =SUM('[1]ABA P&L'!$U46:$W46) | AM20: =SUM('[1]BK P&L'!$U46:$W46) | AN20: =SUM('[1]BW P&L'!$U46:$W46) | AO20: =SUM('[1]CED P&L'!$U46:$W46) | AP20: =SUM('[1]HB P&L'!$U46:$W46) | AQ20: =SUM('[1]KIN P&L'!$U46:$W46) | AR20: =SUM('[1]MER P&L'!$U46:$W46) | AS20: =SUM('[1]SST P&L'!$U46:$W46) | AT20: =SUM('[1]HDN P&L'!$U46:$W46) | AU20: =SUM('[1]NDN P&L'!$U46:$W46) | AV20: =SUM('[1]SDN P&L'!$U46:$W46) | AW20: =SUM('[1]LE P&L'!$U46:$W46) | AX20: =SUM('[1]WH P&L'!$U46:$W46) | AY20: =SUM('[1]HS P&L'!$U46:$W46) | AZ20: =SUM('[1]FH P&L'!$U46:$W46) | BA20: =SUM('[1]HAB P&L'!$U46:$W46) | BB20: =SUM('[1]SALT P&L'!$U46:$W46) | BC20: =SUM(AL20:BB20) | BD20: =SUM('[1]ABA P&L'!$X46:$Z46) | BE20: =SUM('[1]BK P&L'!$X46:$Z46) | BF20: =SUM('[1]BW P&L'!$X46:$Z46) | BG20: =SUM('[1]CED P&L'!$X46:$Z46) | BH20: =SUM('[1]HB P&L'!$X46:$Z46) | BI20: =SUM('[1]KIN P&L'!$X46:$Z46) | BJ20: =SUM('[1]MER P&L'!$X46:$Z46) | BK20: =SUM('[1]SST P&L'!$X46:$Z46) | BL20: =SUM('[1]HDN P&L'!$X46:$Z46) | BM20: =SUM('[1]NDN P&L'!$X46:$Z46) | BN20: =SUM('[1]SDN P&L'!$X46:$Z46) | BO20: =SUM('[1]LE P&L'!$X46:$Z46) | BP20: =SUM('[1]WH P&L'!$X46:$Z46) | BQ20: =SUM('[1]HS P&L'!$X46:$Z46) | BR20: =SUM('[1]FH P&L'!$X46:$Z46) | BS20: =SUM('[1]HAB P&L'!$X46:$Z46) | BT20: =SUM('[1]SALT P&L'!$X46:$Z46) | BU20: =SUM(BD20:BT20) | BV20: =BU20+BC20+AK20+S20
A22: CONTRIBUTION | B22: =B16-B20 | C22: =C16-C20 | D22: =D16-D20 | E22: =E16-E20 | F22: =F16-F20 | G22: =G16-G20 | H22: =H16-H20 | I22: =I16-I20 | ... R22: =R16-R20 | S22: =SUM(B22:R22) | T22: =T16-T20 | U22: =U16-U20 | V22: =V16-V20 | W22: =W16-W20 | X22: =X16-X20 | Y22: =Y16-Y20 | Z22: =Z16-Z20 | AA22: =AA16-AA20 | ... AJ22: =AJ16-AJ20 | AK22: =SUM(T22:AJ22) | AL22: =AL16-AL20 | AM22: =AM16-AM20 | AN22: =AN16-AN20 | AO22: =AO16-AO20 | AP22: =AP16-AP20 | AQ22: =AQ16-AQ20 | AR22: =AR16-AR20 | AS22: =AS16-AS20 | ... BB22: =BB16-BB20 | BC22: =SUM(AL22:BB22) | BD22: =BD16-BD20 | BE22: =BE16-BE20 | BF22: =BF16-BF20 | BG22: =BG16-BG20 | BH22: =BH16-BH20 | BI22: =BI16-BI20 | BJ22: =BJ16-BJ20 | BK22: =BK16-BK20 | ... BT22: =BT16-BT20 | BU22: =SUM(BD22:BT22) | BV22: =BU22+BC22+AK22+S22
B23: =B22/B20 | C23: =C22/C20 | D23: =D22/D20 | E23: =E22/E20 | F23: =F22/F20 | G23: =G22/G20 | H23: =H22/H20 | I23: =I22/I20 | ... BV23: =BV22/BV20
A25: Budegt V Actuals | B25: Q1 | T25: Q2 | U25: FORECAST DATA | AL25: Q3 | AM25: FORECAST DATA | BD25: Q4 | BE25: FORECAST DATA
B26: Abacus | C26: Bees Knees | D26: Bramleywood | E26: Cedars | F26: Hazebrouck | G26: Kingsclere | H26: Merrydale | I26: Stepping Stones | J26: Happitots | K26: Northumberland | L26: Smart Tots | M26: Lower Earley | N26: Woosehill | O26: Our Den | P26: Finchampstead | Q26: Boot Farm | R26: Saltway | S26: Totals | T26: Abacus | U26: Bees Knees | V26: Bramleywood | W26: Cedars | X26: Hazebrouck | Y26: Kingsclere | Z26: Merrydale | AA26: Stepping Stones | AB26: Happitots | AC26: Northumberland | AD26: Smart Tots | AE26: Lower Earley | AF26: Woosehill | AG26: Our Den | AH26: Finchampstead | AI26: Boot Farm | AJ26: Saltway | AK26: Totals | AL26: Abacus | AM26: Bees Knees | AN26: Bramleywood | AO26: Cedars | AP26: Hazebrouck | AQ26: Kingsclere | AR26: Merrydale | AS26: Stepping Stones | AT26: Happitots | AU26: Northumberland | AV26: Smart Tots | AW26: Lower Earley | AX26: Woosehill | AY26: Our Den | AZ26: Finchampstead | BA26: Boot Farm | BB26: Saltway | BC26: Totals | BD26: Abacus | BE26: Bees Knees | BF26: Bramleywood | BG26: Cedars | BH26: Hazebrouck | BI26: Kingsclere | BJ26: Merrydale | BK26: Stepping Stones | BL26: Happitots | BM26: Northumberland | BN26: Smart Tots | BO26: Lower Earley | BP26: Woosehill | BQ26: Our Den | BR26: Finchampstead | BS26: Boot Farm | BT26: Saltway | BU26: Totals | BV26: Year Total
A27: Income | B27: =B16-B5 | C27: =C16-C5 | D27: =D16-D5 | E27: =E16-E5 | F27: =F16-F5 | G27: =G16-G5 | H27: =H16-H5 | I27: =I16-I5 | ... BV27: =BV16-BV5
A28: Income % | B28: =B27/B5 | C28: =C27/C5 | D28: =D27/D5 | E28: =E27/E5 | F28: =F27/F5 | G28: =G27/G5 | H28: =H27/H5 | I28: =I27/I5 | ... N28: =N27/N5 | P28: =P27/P5 | Q28: =Q27/Q5 | R28: =R27/R5 | S28: =S27/S5 | T28: =T27/T5 | U28: =U27/U5 | V28: =V27/V5 | W28: =W27/W5 | ... BV28: =BV27/BV5
A30: Personnel Costs (negative = increase in cost) | B30: =B6-B17 | C30: =C6-C17 | D30: =D6-D17 | E30: =E6-E17 | F30: =F6-F17 | G30: =G6-G17 | H30: =H6-H17 | I30: =I6-I17 | ... BV30: =BV6-BV17
A31: Personnel Cost change as % | B31: =-B30/B6 | C31: =-C30/C6 | D31: =-D30/D6 | E31: =-E30/E6 | F31: =-F30/F6 | G31: =-G30/G6 | H31: =-H30/H6 | I31: =-I30/I6 | ... N31: =-N30/N6 | P31: =-P30/P6 | Q31: =-Q30/Q6 | R31: =-R30/R6 | S31: =-S30/S6 | T31: =-T30/T6 | U31: =-U30/U6 | V31: =-V30/V6 | W31: =-W30/W6 | ... BV31: =-BV30/BV6
A33: Sal:Rev Budegt
A34: Sal:Rev Actual | B34: =B17/B16 | C34: =C17/C16 | D34: =D17/D16 | E34: =E17/E16 | F34: =F17/F16 | G34: =G17/G16 | H34: =H17/H16 | I34: =I17/I16 | ... N34: =N17/N16 | P34: =P17/P16 | Q34: =Q17/Q16 | R34: =R17/R16 | S34: =S17/S16 | T34: =T17/T16 | U34: =U17/U16 | V34: =V17/V16 | W34: =W17/W16 | ... BV34: =BV17/BV16
A36: Childcare Costs (negative = increase in cost) | B36: =B7-B18 | C36: =C7-C18 | D36: =D7-D18 | E36: =E7-E18 | F36: =F7-F18 | G36: =G7-G18 | H36: =H7-H18 | I36: =I7-I18 | ... BV36: =BV7-BV18
A37: Childcare Cost Change % | B37: =-B36/B7 | C37: =-C36/C7 | D37: =-D36/D7 | E37: =-E36/E7 | F37: =-F36/F7 | G37: =-G36/G7 | H37: =-H36/H7 | I37: =-I36/I7 | ... N37: =-N36/N7 | P37: =-P36/P7 | Q37: =-Q36/Q7 | R37: =-R36/R7 | S37: =-S36/S7 | T37: =-T36/T7 | U37: =-U36/U7 | V37: =-V36/V7 | W37: =-W36/W7 | ... BV37: =-BV36/BV7
A39: Contribution | B39: =B22-B11 | C39: =C22-C11 | D39: =D22-D11 | E39: =E22-E11 | F39: =F22-F11 | G39: =G22-G11 | H39: =H22-H11 | I39: =I22-I11 | ... BV39: =BV22-BV11
A40: Contribution Change % | B40: =B39/B11 | C40: =C39/C11 | D40: =D39/D11 | E40: =E39/E11 | F40: =F39/F11 | G40: =G39/G11 | H40: =H39/H11 | I40: =I39/I11 | ... N40: =N39/N11 | P40: =P39/P11 | Q40: =Q39/Q11 | R40: =R39/R11 | S40: =S39/S11 | T40: =T39/T11 | U40: =U39/U11 | V40: =V39/V11 | W40: =W39/W11 | ... BV40: =BV39/BV11
A43: Comment

Sheet Year On Year Analysis
A1: Year on Year Analysis
A3: 2025 | B3: Q1 | U3: Q2 | AN3: Q3 | BG3: Q4
B4: Abacus | C4: Bees Knees | D4: Bramleywood | E4: Cedars | F4: Hazebrouck | G4: Kingsclere | H4: Merrydale | I4: Stepping Stones | J4: Happitots | K4: Northumberland | L4: Smart Tots | M4: Lower Earley | N4: Woosehill | O4: Our Den | P4: Finchampstead | Q4: Boot Farm | R4: Saltway | S4: Head Office & Misc | T4: Quarter Total | U4: Abacus | V4: Bees Knees | W4: Bramleywood | X4: Cedars | Y4: Hazebrouck | Z4: Kingsclere | AA4: Merrydale | AB4: Stepping Stones | AC4: Happitots | AD4: Northumberland | AE4: Smart Tots | AF4: Lower Earley | AG4: Woosehill | AH4: Our Den | AI4: Finchampstead | AJ4: Boot Farm | AK4: Saltway | AL4: Head Office & Misc | AM4: Quarter Total | AN4: Abacus | AO4: Bees Knees | AP4: Bramleywood | AQ4: Cedars | AR4: Hazebrouck | AS4: Kingsclere | AT4: Merrydale | AU4: Stepping Stones | AV4: Happitots | AW4: Northumberland | AX4: Smart Tots | AY4: Lower Earley | AZ4: Woosehill | BA4: Our Den | BB4: Finchampstead | BC4: Boot Farm | BD4: Saltway | BE4: Head Office & Misc | BF4: Quarter Total | BG4: Abacus | BH4: Bees Knees | BI4: Bramleywood | BJ4: Cedars | BK4: Hazebrouck | BL4: Kingsclere | BM4: Merrydale | BN4: Stepping Stones | BO4: Happitots | BP4: Northumberland | BQ4: Smart Tots | BR4: Lower Earley | BS4: Woosehill | BT4: Our Den | BU4: Finchampstead | BV4: Boot Farm | BW4: Saltway | BX4: Head Office & Misc | BY4: Quarter Total | BZ4: Year Total
A5: INCOME
A7: Fee Income Regular | B7: =SUM('ABA P&L'!$B8:$D8) | C7: =SUM('BK P&L'!$B8:$D8) | D7: =SUM('BW P&L'!$B8:$D8) | E7: =SUM('CED P&L'!$B8:$D8) | F7: =SUM('HB P&L'!$B8:$D8) | G7: =SUM('KIN P&L'!$B8:$D8) | H7: =SUM('MER P&L'!$B8:$D8) | I7: =SUM('SST P&L'!$B8:$D8) | J7: =SUM('HDN P&L'!$B8:$D8) | K7: =SUM('NDN P&L'!$B8:$D8) | L7: =SUM('SDN P&L'!$B8:$D8) | M7: =SUM('LE P&L'!$B8:$D8) | N7: =SUM('WH P&L'!$B8:$D8) | O7: =SUM('HS P&L'!$B8:$D8) | P7: =SUM('FH P&L'!$B8:$D8) | Q7: =SUM('HAB P&L'!$B8:$D8) | R7: =SUM('SALT P&L'!$B8:$D8) | S7: =SUM('KNL HO P&L'!$B8:$D8)+SUM('CCL HO P&L'!$B8:$D8)+SUM('YBHN HO P&L'!$B8:$D8)+SUM('YBN HO P&L'!$B8:$D8)+SUM('Moe2 P&L'!$B8:$D8) | T7: =SUM(B7:S7) | U7: =SUM('ABA P&L'!$E8:$G8) | V7: =SUM('BK P&L'!$E8:$G8) | W7: =SUM('BW P&L'!$E8:$G8) | X7: =SUM('CED P&L'!$E8:$G8) | Y7: =SUM('HB P&L'!$E8:$G8) | Z7: =SUM('KIN P&L'!$E8:$G8) | AA7: =SUM('MER P&L'!$E8:$G8) | AB7: =SUM('SST P&L'!$E8:$G8) | AC7: =SUM('HDN P&L'!$E8:$G8) | AD7: =SUM('NDN P&L'!$E8:$G8) | AE7: =SUM('SDN P&L'!$E8:$G8) | AF7: =SUM('LE P&L'!$E8:$G8) | AG7: =SUM('WH P&L'!$E8:$G8) | AH7: =SUM('HS P&L'!$E8:$G8) | AI7: =SUM('FH P&L'!$E8:$G8) | AJ7: =SUM('HAB P&L'!$E8:$G8) | AK7: =SUM('SALT P&L'!$E8:$G8) | AL7: =SUM('KNL HO P&L'!$E8:$G8)+SUM('CCL HO P&L'!$E8:$G8)+SUM('YBHN HO P&L'!$E8:$G8)+SUM('YBN HO P&L'!$E8:$G8)+SUM('Moe2 P&L'!$E8:$G8) | AM7: =SUM(U7:AL7) | AN7: =SUM('ABA P&L'!$H8:$J8) | AO7: =SUM('BK P&L'!$H8:$J8) | AP7: =SUM('BW P&L'!$H8:$J8) | AQ7: =SUM('CED P&L'!$H8:$J8) | AR7: =SUM('HB P&L'!$H8:$J8) | AS7: =SUM('KIN P&L'!$H8:$J8) | AT7: =SUM('MER P&L'!$H8:$J8) | AU7: =SUM('SST P&L'!$H8:$J8) | AV7: =SUM('HDN P&L'!$H8:$J8) | AW7: =SUM('NDN P&L'!$H8:$J8) | AX7: =SUM('SDN P&L'!$H8:$J8) | AY7: =SUM('LE P&L'!$H8:$J8) | AZ7: =SUM('WH P&L'!$H8:$J8) | BA7: =SUM('HS P&L'!$H8:$J8) | BB7: =SUM('FH P&L'!$H8:$J8) | BC7: =SUM('HAB P&L'!$H8:$J8) | BD7: =SUM('SALT P&L'!$H8:$J8) | BE7: =SUM('KNL HO P&L'!$H8:$J8)+SUM('CCL HO P&L'!$H8:$J8)+SUM('YBHN HO P&L'!$H8:$J8)+SUM('YBN HO P&L'!$H8:$J8)+SUM('Moe2 P&L'!$H8:$J8) | BF7: =SUM(AN7:BE7) | BG7: =SUM('ABA P&L'!$K8:$M8) | BH7: =SUM('BK P&L'!$K8:$M8) | BI7: =SUM('BW P&L'!$K8:$M8) | BJ7: =SUM('CED P&L'!$K8:$M8) | BK7: =SUM('HB P&L'!$K8:$M8) | BL7: =SUM('KIN P&L'!$K8:$M8) | BM7: =SUM('MER P&L'!$K8:$M8) | BN7: =SUM('SST P&L'!$K8:$M8) | BO7: =SUM('HDN P&L'!$K8:$M8) | BP7: =SUM('NDN P&L'!$K8:$M8) | BQ7: =SUM('SDN P&L'!$K8:$M8) | BR7: =SUM('LE P&L'!$K8:$M8) | BS7: =SUM('WH P&L'!$K8:$M8) | BT7: =SUM('HS P&L'!$K8:$M8) | BU7: =SUM('FH P&L'!$K8:$M8) | BV7: =SUM('HAB P&L'!$K8:$M8) | BW7: =SUM('SALT P&L'!$K8:$M8) | BX7: =SUM('KNL HO P&L'!$K8:$M8)+SUM('CCL HO P&L'!$K8:$M8)+SUM('YBHN HO P&L'!$K8:$M8)+SUM('YBN HO P&L'!$K8:$M8)+SUM('Moe2 P&L'!$K8:$M8) | BY7: =SUM(BG7:BX7) | BZ7: =BY7+BF7+AM7+T7
A8: EEEF Embeded | B8: =SUM('ABA P&L'!$B9:$D9) | C8: =SUM('BK P&L'!$B9:$D9) | D8: =SUM('BW P&L'!$B9:$D9) | E8: =SUM('CED P&L'!$B9:$D9) | F8: =SUM('HB P&L'!$B9:$D9) | G8: =SUM('KIN P&L'!$B9:$D9) | H8: =SUM('MER P&L'!$B9:$D9) | I8: =SUM('SST P&L'!$B9:$D9) | J8: =SUM('HDN P&L'!$B9:$D9) | K8: =SUM('NDN P&L'!$B9:$D9) | L8: =SUM('SDN P&L'!$B9:$D9) | M8: =SUM('LE P&L'!$B9:$D9) | N8: =SUM('WH P&L'!$B9:$D9) | O8: =SUM('HS P&L'!$B9:$D9) | P8: =SUM('FH P&L'!$B9:$D9) | Q8: =SUM('HAB P&L'!$B9:$D9) | R8: =SUM('SALT P&L'!$B9:$D9) | S8: =SUM('KNL HO P&L'!$B9:$D9)+SUM('CCL HO P&L'!$B9:$D9)+SUM('YBHN HO P&L'!$B9:$D9)+SUM('YBN HO P&L'!$B9:$D9)+SUM('Moe2 P&L'!$B9:$D9) | T8: =SUM(B8:S8) | U8: =SUM('ABA P&L'!$E9:$G9) | V8: =SUM('BK P&L'!$E9:$G9) | W8: =SUM('BW P&L'!$E9:$G9) | X8: =SUM('CED P&L'!$E9:$G9) | Y8: =SUM('HB P&L'!$E9:$G9) | Z8: =SUM('KIN P&L'!$E9:$G9) | AA8: =SUM('MER P&L'!$E9:$G9) | AB8: =SUM('SST P&L'!$E9:$G9) | AC8: =SUM('HDN P&L'!$E9:$G9) | AD8: =SUM('NDN P&L'!$E9:$G9) | AE8: =SUM('SDN P&L'!$E9:$G9) | AF8: =SUM('LE P&L'!$E9:$G9) | AG8: =SUM('WH P&L'!$E9:$G9) | AH8: =SUM('HS P&L'!$E9:$G9) | AI8: =SUM('FH P&L'!$E9:$G9) | AJ8: =SUM('HAB P&L'!$E9:$G9) | AK8: =SUM('SALT P&L'!$E9:$G9) | AL8: =SUM('KNL HO P&L'!$E9:$G9)+SUM('CCL HO P&L'!$E9:$G9)+SUM('YBHN HO P&L'!$E9:$G9)+SUM('YBN HO P&L'!$E9:$G9)+SUM('Moe2 P&L'!$E9:$G9) | AM8: =SUM(U8:AL8) | AN8: =SUM('ABA P&L'!$H9:$J9) | AO8: =SUM('BK P&L'!$H9:$J9) | AP8: =SUM('BW P&L'!$H9:$J9) | AQ8: =SUM('CED P&L'!$H9:$J9) | AR8: =SUM('HB P&L'!$H9:$J9) | AS8: =SUM('KIN P&L'!$H9:$J9) | AT8: =SUM('MER P&L'!$H9:$J9) | AU8: =SUM('SST P&L'!$H9:$J9) | AV8: =SUM('HDN P&L'!$H9:$J9) | AW8: =SUM('NDN P&L'!$H9:$J9) | AX8: =SUM('SDN P&L'!$H9:$J9) | AY8: =SUM('LE P&L'!$H9:$J9) | AZ8: =SUM('WH P&L'!$H9:$J9) | BA8: =SUM('HS P&L'!$H9:$J9) | BB8: =SUM('FH P&L'!$H9:$J9) | BC8: =SUM('HAB P&L'!$H9:$J9) | BD8: =SUM('SALT P&L'!$H9:$J9) | BE8: =SUM('KNL HO P&L'!$H9:$J9)+SUM('CCL HO P&L'!$H9:$J9)+SUM('YBHN HO P&L'!$H9:$J9)+SUM('YBN HO P&L'!$H9:$J9)+SUM('Moe2 P&L'!$H9:$J9) | BF8: =SUM(AN8:BE8) | BG8: =SUM('ABA P&L'!$K9:$M9) | BH8: =SUM('BK P&L'!$K9:$M9) | BI8: =SUM('BW P&L'!$K9:$M9) | BJ8: =SUM('CED P&L'!$K9:$M9) | BK8: =SUM('HB P&L'!$K9:$M9) | BL8: =SUM('KIN P&L'!$K9:$M9) | BM8: =SUM('MER P&L'!$K9:$M9) | BN8: =SUM('SST P&L'!$K9:$M9) | BO8: =SUM('HDN P&L'!$K9:$M9) | BP8: =SUM('NDN P&L'!$K9:$M9) | BQ8: =SUM('SDN P&L'!$K9:$M9) | BR8: =SUM('LE P&L'!$K9:$M9) | BS8: =SUM('WH P&L'!$K9:$M9) | BT8: =SUM('HS P&L'!$K9:$M9) | BU8: =SUM('FH P&L'!$K9:$M9) | BV8: =SUM('HAB P&L'!$K9:$M9) | BW8: =SUM('SALT P&L'!$K9:$M9) | BX8: =SUM('KNL HO P&L'!$K9:$M9)+SUM('CCL HO P&L'!$K9:$M9)+SUM('YBHN HO P&L'!$K9:$M9)+SUM('YBN HO P&L'!$K9:$M9)+SUM('Moe2 P&L'!$K9:$M9) | BY8: =SUM(BG8:BX8) | BZ8: =BY8+BF8+AM8+T8
A9: Other Income | B9: =SUM('ABA P&L'!$B10:$D10) | C9: =SUM('BK P&L'!$B10:$D10) | D9: =SUM('BW P&L'!$B10:$D10) | E9: =SUM('CED P&L'!$B10:$D10) | F9: =SUM('HB P&L'!$B10:$D10) | G9: =SUM('KIN P&L'!$B10:$D10) | H9: =SUM('MER P&L'!$B10:$D10) | I9: =SUM('SST P&L'!$B10:$D10) | J9: =SUM('HDN P&L'!$B10:$D10) | K9: =SUM('NDN P&L'!$B10:$D10) | L9: =SUM('SDN P&L'!$B10:$D10) | M9: =SUM('LE P&L'!$B10:$D10) | N9: =SUM('WH P&L'!$B10:$D10) | O9: =SUM('HS P&L'!$B10:$D10) | P9: =SUM('FH P&L'!$B10:$D10) | Q9: =SUM('HAB P&L'!$B10:$D10) | R9: =SUM('SALT P&L'!$B10:$D10) | S9: =SUM('KNL HO P&L'!$B10:$D10)+SUM('CCL HO P&L'!$B10:$D10)+SUM('YBHN HO P&L'!$B10:$D10)+SUM('YBN HO P&L'!$B10:$D10)+SUM('Moe2 P&L'!$B10:$D10) | T9: =SUM(B9:S9) | U9: =SUM('ABA P&L'!$E10:$G10) | V9: =SUM('BK P&L'!$E10:$G10) | W9: =SUM('BW P&L'!$E10:$G10) | X9: =SUM('CED P&L'!$E10:$G10) | Y9: =SUM('HB P&L'!$E10:$G10) | Z9: =SUM('KIN P&L'!$E10:$G10) | AA9: =SUM('MER P&L'!$E10:$G10) | AB9: =SUM('SST P&L'!$E10:$G10) | AC9: =SUM('HDN P&L'!$E10:$G10) | AD9: =SUM('NDN P&L'!$E10:$G10) | AE9: =SUM('SDN P&L'!$E10:$G10) | AF9: =SUM('LE P&L'!$E10:$G10) | AG9: =SUM('WH P&L'!$E10:$G10) | AH9: =SUM('HS P&L'!$E10:$G10) | AI9: =SUM('FH P&L'!$E10:$G10) | AJ9: =SUM('HAB P&L'!$E10:$G10) | AK9: =SUM('SALT P&L'!$E10:$G10) | AL9: =SUM('KNL HO P&L'!$E10:$G10)+SUM('CCL HO P&L'!$E10:$G10)+SUM('YBHN HO P&L'!$E10:$G10)+SUM('YBN HO P&L'!$E10:$G10)+SUM('Moe2 P&L'!$E10:$G10) | AM9: =SUM(U9:AL9) | AN9: =SUM('ABA P&L'!$H10:$J10) | AO9: =SUM('BK P&L'!$H10:$J10) | AP9: =SUM('BW P&L'!$H10:$J10) | AQ9: =SUM('CED P&L'!$H10:$J10) | AR9: =SUM('HB P&L'!$H10:$J10) | AS9: =SUM('KIN P&L'!$H10:$J10) | AT9: =SUM('MER P&L'!$H10:$J10) | AU9: =SUM('SST P&L'!$H10:$J10) | AV9: =SUM('HDN P&L'!$H10:$J10) | AW9: =SUM('NDN P&L'!$H10:$J10) | AX9: =SUM('SDN P&L'!$H10:$J10) | AY9: =SUM('LE P&L'!$H10:$J10) | AZ9: =SUM('WH P&L'!$H10:$J10) | BA9: =SUM('HS P&L'!$H10:$J10) | BB9: =SUM('FH P&L'!$H10:$J10) | BC9: =SUM('HAB P&L'!$H10:$J10) | BD9: =SUM('SALT P&L'!$H10:$J10) | BE9: =SUM('KNL HO P&L'!$H10:$J10)+SUM('CCL HO P&L'!$H10:$J10)+SUM('YBHN HO P&L'!$H10:$J10)+SUM('YBN HO P&L'!$H10:$J10)+SUM('Moe2 P&L'!$H10:$J10) | BF9: =SUM(AN9:BE9) | BG9: =SUM('ABA P&L'!$K10:$M10) | BH9: =SUM('BK P&L'!$K10:$M10) | BI9: =SUM('BW P&L'!$K10:$M10) | BJ9: =SUM('CED P&L'!$K10:$M10) | BK9: =SUM('HB P&L'!$K10:$M10) | BL9: =SUM('KIN P&L'!$K10:$M10) | BM9: =SUM('MER P&L'!$K10:$M10) | BN9: =SUM('SST P&L'!$K10:$M10) | BO9: =SUM('HDN P&L'!$K10:$M10) | BP9: =SUM('NDN P&L'!$K10:$M10) | BQ9: =SUM('SDN P&L'!$K10:$M10) | BR9: =SUM('LE P&L'!$K10:$M10) | BS9: =SUM('WH P&L'!$K10:$M10) | BT9: =SUM('HS P&L'!$K10:$M10) | BU9: =SUM('FH P&L'!$K10:$M10) | BV9: =SUM('HAB P&L'!$K10:$M10) | BW9: =SUM('SALT P&L'!$K10:$M10) | BX9: =SUM('KNL HO P&L'!$K10:$M10)+SUM('CCL HO P&L'!$K10:$M10)+SUM('YBHN HO P&L'!$K10:$M10)+SUM('YBN HO P&L'!$K10:$M10)+SUM('Moe2 P&L'!$K10:$M10) | BY9: =SUM(BG9:BX9) | BZ9: =BY9+BF9+AM9+T9
A10: Total Income | B10: =SUM('ABA P&L'!$B11:$D11) | C10: =SUM('BK P&L'!$B11:$D11) | D10: =SUM('BW P&L'!$B11:$D11) | E10: =SUM('CED P&L'!$B11:$D11) | F10: =SUM('HB P&L'!$B11:$D11) | G10: =SUM('KIN P&L'!$B11:$D11) | H10: =SUM('MER P&L'!$B11:$D11) | I10: =SUM('SST P&L'!$B11:$D11) | J10: =SUM('HDN P&L'!$B11:$D11) | K10: =SUM('NDN P&L'!$B11:$D11) | L10: =SUM('SDN P&L'!$B11:$D11) | M10: =SUM('LE P&L'!$B11:$D11) | N10: =SUM('WH P&L'!$B11:$D11) | O10: =SUM('HS P&L'!$B11:$D11) | P10: =SUM('FH P&L'!$B11:$D11) | Q10: =SUM('HAB P&L'!$B11:$D11) | R10: =SUM('SALT P&L'!$B11:$D11) | S10: =SUM('KNL HO P&L'!$B11:$D11)+SUM('CCL HO P&L'!$B11:$D11)+SUM('YBHN HO P&L'!$B11:$D11)+SUM('YBN HO P&L'!$B11:$D11)+SUM('Moe2 P&L'!$B11:$D11) | T10: =SUM(B10:S10) | U10: =SUM('ABA P&L'!$E11:$G11) | V10: =SUM('BK P&L'!$E11:$G11) | W10: =SUM('BW P&L'!$E11:$G11) | X10: =SUM('CED P&L'!$E11:$G11) | Y10: =SUM('HB P&L'!$E11:$G11) | Z10: =SUM('KIN P&L'!$E11:$G11) | AA10: =SUM('MER P&L'!$E11:$G11) | AB10: =SUM('SST P&L'!$E11:$G11) | AC10: =SUM('HDN P&L'!$E11:$G11) | AD10: =SUM('NDN P&L'!$E11:$G11) | AE10: =SUM('SDN P&L'!$E11:$G11) | AF10: =SUM('LE P&L'!$E11:$G11) | AG10: =SUM('WH P&L'!$E11:$G11) | AH10: =SUM('HS P&L'!$E11:$G11) | AI10: =SUM('FH P&L'!$E11:$G11) | AJ10: =SUM('HAB P&L'!$E11:$G11) | AK10: =SUM('SALT P&L'!$E11:$G11) | AL10: =SUM('KNL HO P&L'!$E11:$G11)+SUM('CCL HO P&L'!$E11:$G11)+SUM('YBHN HO P&L'!$E11:$G11)+SUM('YBN HO P&L'!$E11:$G11)+SUM('Moe2 P&L'!$E11:$G11) | AM10: =SUM(U10:AL10) | AN10: =SUM('ABA P&L'!$H11:$J11) | AO10: =SUM('BK P&L'!$H11:$J11) | AP10: =SUM('BW P&L'!$H11:$J11) | AQ10: =SUM('CED P&L'!$H11:$J11) | AR10: =SUM('HB P&L'!$H11:$J11) | AS10: =SUM('KIN P&L'!$H11:$J11) | AT10: =SUM('MER P&L'!$H11:$J11) | AU10: =SUM('SST P&L'!$H11:$J11) | AV10: =SUM('HDN P&L'!$H11:$J11) | AW10: =SUM('NDN P&L'!$H11:$J11) | AX10: =SUM('SDN P&L'!$H11:$J11) | AY10: =SUM('LE P&L'!$H11:$J11) | AZ10: =SUM('WH P&L'!$H11:$J11) | BA10: =SUM('HS P&L'!$H11:$J11) | BB10: =SUM('FH P&L'!$H11:$J11) | BC10: =SUM('HAB P&L'!$H11:$J11) | BD10: =SUM('SALT P&L'!$H11:$J11) | BE10: =SUM('KNL HO P&L'!$H11:$J11)+SUM('CCL HO P&L'!$H11:$J11)+SUM('YBHN HO P&L'!$H11:$J11)+SUM('YBN HO P&L'!$H11:$J11)+SUM('Moe2 P&L'!$H11:$J11) | BF10: =SUM(AN10:BE10) | BG10: =SUM('ABA P&L'!$K11:$M11) | BH10: =SUM('BK P&L'!$K11:$M11) | BI10: =SUM('BW P&L'!$K11:$M11) | BJ10: =SUM('CED P&L'!$K11:$M11) | BK10: =SUM('HB P&L'!$K11:$M11) | BL10: =SUM('KIN P&L'!$K11:$M11) | BM10: =SUM('MER P&L'!$K11:$M11) | BN10: =SUM('SST P&L'!$K11:$M11) | BO10: =SUM('HDN P&L'!$K11:$M11) | BP10: =SUM('NDN P&L'!$K11:$M11) | BQ10: =SUM('SDN P&L'!$K11:$M11) | BR10: =SUM('LE P&L'!$K11:$M11) | BS10: =SUM('WH P&L'!$K11:$M11) | BT10: =SUM('HS P&L'!$K11:$M11) | BU10: =SUM('FH P&L'!$K11:$M11) | BV10: =SUM('HAB P&L'!$K11:$M11) | BW10: =SUM('SALT P&L'!$K11:$M11) | BX10: =SUM('KNL HO P&L'!$K11:$M11)+SUM('CCL HO P&L'!$K11:$M11)+SUM('YBHN HO P&L'!$K11:$M11)+SUM('YBN HO P&L'!$K11:$M11)+SUM('Moe2 P&L'!$K11:$M11) | BY10: =SUM(BG10:BX10) | BZ10: =BY10+BF10+AM10+T10
A11: DIRECTCOSTS | B11: =SUM('ABA P&L'!$B12:$D12) | C11: =SUM('BK P&L'!$B12:$D12) | D11: =SUM('BW P&L'!$B12:$D12) | E11: =SUM('CED P&L'!$B12:$D12) | F11: =SUM('HB P&L'!$B12:$D12) | G11: =SUM('KIN P&L'!$B12:$D12) | H11: =SUM('MER P&L'!$B12:$D12) | I11: =SUM('SST P&L'!$B12:$D12) | J11: =SUM('HDN P&L'!$B12:$D12) | K11: =SUM('NDN P&L'!$B12:$D12) | L11: =SUM('SDN P&L'!$B12:$D12) | M11: =SUM('LE P&L'!$B12:$D12) | N11: =SUM('WH P&L'!$B12:$D12) | O11: =SUM('HS P&L'!$B12:$D12) | P11: =SUM('FH P&L'!$B12:$D12) | Q11: =SUM('HAB P&L'!$B12:$D12) | R11: =SUM('SALT P&L'!$B12:$D12) | S11: =SUM('KNL HO P&L'!$B12:$D12)+SUM('CCL HO P&L'!$B12:$D12)+SUM('YBHN HO P&L'!$B12:$D12)+SUM('YBN HO P&L'!$B12:$D12)+SUM('Moe2 P&L'!$B12:$D12) | T11: =SUM(B11:S11) | U11: =SUM('ABA P&L'!$E12:$G12) | V11: =SUM('BK P&L'!$E12:$G12) | W11: =SUM('BW P&L'!$E12:$G12) | X11: =SUM('CED P&L'!$E12:$G12) | Y11: =SUM('HB P&L'!$E12:$G12) | Z11: =SUM('KIN P&L'!$E12:$G12) | AA11: =SUM('MER P&L'!$E12:$G12) | AB11: =SUM('SST P&L'!$E12:$G12) | AC11: =SUM('HDN P&L'!$E12:$G12) | AD11: =SUM('NDN P&L'!$E12:$G12) | AE11: =SUM('SDN P&L'!$E12:$G12) | AF11: =SUM('LE P&L'!$E12:$G12) | AG11: =SUM('WH P&L'!$E12:$G12) | AH11: =SUM('HS P&L'!$E12:$G12) | AI11: =SUM('FH P&L'!$E12:$G12) | AJ11: =SUM('HAB P&L'!$E12:$G12) | AK11: =SUM('SALT P&L'!$E12:$G12) | AL11: =SUM('KNL HO P&L'!$E12:$G12)+SUM('CCL HO P&L'!$E12:$G12)+SUM('YBHN HO P&L'!$E12:$G12)+SUM('YBN HO P&L'!$E12:$G12)+SUM('Moe2 P&L'!$E12:$G12) | AM11: =SUM(U11:AL11) | AN11: =SUM('ABA P&L'!$H12:$J12) | AO11: =SUM('BK P&L'!$H12:$J12) | AP11: =SUM('BW P&L'!$H12:$J12) | AQ11: =SUM('CED P&L'!$H12:$J12) | AR11: =SUM('HB P&L'!$H12:$J12) | AS11: =SUM('KIN P&L'!$H12:$J12) | AT11: =SUM('MER P&L'!$H12:$J12) | AU11: =SUM('SST P&L'!$H12:$J12) | AV11: =SUM('HDN P&L'!$H12:$J12) | AW11: =SUM('NDN P&L'!$H12:$J12) | AX11: =SUM('SDN P&L'!$H12:$J12) | AY11: =SUM('LE P&L'!$H12:$J12) | AZ11: =SUM('WH P&L'!$H12:$J12) | BA11: =SUM('HS P&L'!$H12:$J12) | BB11: =SUM('FH P&L'!$H12:$J12) | BC11: =SUM('HAB P&L'!$H12:$J12) | BD11: =SUM('SALT P&L'!$H12:$J12) | BE11: =SUM('KNL HO P&L'!$H12:$J12)+SUM('CCL HO P&L'!$H12:$J12)+SUM('YBHN HO P&L'!$H12:$J12)+SUM('YBN HO P&L'!$H12:$J12)+SUM('Moe2 P&L'!$H12:$J12) | BF11: =SUM(AN11:BE11) | BG11: =SUM('ABA P&L'!$K12:$M12) | BH11: =SUM('BK P&L'!$K12:$M12) | BI11: =SUM('BW P&L'!$K12:$M12) | BJ11: =SUM('CED P&L'!$K12:$M12) | BK11: =SUM('HB P&L'!$K12:$M12) | BL11: =SUM('KIN P&L'!$K12:$M12) | BM11: =SUM('MER P&L'!$K12:$M12) | BN11: =SUM('SST P&L'!$K12:$M12) | BO11: =SUM('HDN P&L'!$K12:$M12) | BP11: =SUM('NDN P&L'!$K12:$M12) | BQ11: =SUM('SDN P&L'!$K12:$M12) | BR11: =SUM('LE P&L'!$K12:$M12) | BS11: =SUM('WH P&L'!$K12:$M12) | BT11: =SUM('HS P&L'!$K12:$M12) | BU11: =SUM('FH P&L'!$K12:$M12) | BV11: =SUM('HAB P&L'!$K12:$M12) | BW11: =SUM('SALT P&L'!$K12:$M12) | BX11: =SUM('KNL HO P&L'!$K12:$M12)+SUM('CCL HO P&L'!$K12:$M12)+SUM('YBHN HO P&L'!$K12:$M12)+SUM('YBN HO P&L'!$K12:$M12)+SUM('Moe2 P&L'!$K12:$M12) | BY11: =SUM(BG11:BX11) | BZ11: =BY11+BF11+AM11+T11
A12: Personnel | B12: =SUM('ABA P&L'!$B15:$D15) | C12: =SUM('BK P&L'!$B15:$D15) | D12: =SUM('BW P&L'!$B15:$D15) | E12: =SUM('CED P&L'!$B15:$D15) | F12: =SUM('HB P&L'!$B15:$D15) | G12: =SUM('KIN P&L'!$B15:$D15) | H12: =SUM('MER P&L'!$B15:$D15) | I12: =SUM('SST P&L'!$B15:$D15) | J12: =SUM('HDN P&L'!$B15:$D15) | K12: =SUM('NDN P&L'!$B15:$D15) | L12: =SUM('SDN P&L'!$B15:$D15) | M12: =SUM('LE P&L'!$B15:$D15) | N12: =SUM('WH P&L'!$B15:$D15) | O12: =SUM('HS P&L'!$B15:$D15) | P12: =SUM('FH P&L'!$B15:$D15) | Q12: =SUM('HAB P&L'!$B15:$D15) | R12: =SUM('SALT P&L'!$B15:$D15) | S12: =SUM('KNL HO P&L'!$B15:$D15)+SUM('CCL HO P&L'!$B15:$D15)+SUM('YBHN HO P&L'!$B15:$D15)+SUM('YBN HO P&L'!$B15:$D15)+SUM('Moe2 P&L'!$B15:$D15) | T12: =SUM(B12:S12) | U12: =SUM('ABA P&L'!$E15:$G15) | V12: =SUM('BK P&L'!$E15:$G15) | W12: =SUM('BW P&L'!$E15:$G15) | X12: =SUM('CED P&L'!$E15:$G15) | Y12: =SUM('HB P&L'!$E15:$G15) | Z12: =SUM('KIN P&L'!$E15:$G15) | AA12: =SUM('MER P&L'!$E15:$G15) | AB12: =SUM('SST P&L'!$E15:$G15) | AC12: =SUM('HDN P&L'!$E15:$G15) | AD12: =SUM('NDN P&L'!$E15:$G15) | AE12: =SUM('SDN P&L'!$E15:$G15) | AF12: =SUM('LE P&L'!$E15:$G15) | AG12: =SUM('WH P&L'!$E15:$G15) | AH12: =SUM('HS P&L'!$E15:$G15) | AI12: =SUM('FH P&L'!$E15:$G15) | AJ12: =SUM('HAB P&L'!$E15:$G15) | AK12: =SUM('SALT P&L'!$E15:$G15) | AL12: =SUM('KNL HO P&L'!$E15:$G15)+SUM('CCL HO P&L'!$E15:$G15)+SUM('YBHN HO P&L'!$E15:$G15)+SUM('YBN HO P&L'!$E15:$G15)+SUM('Moe2 P&L'!$E15:$G15) | AM12: =SUM(U12:AL12) | AN12: =SUM('ABA P&L'!$H15:$J15) | AO12: =SUM('BK P&L'!$H15:$J15) | AP12: =SUM('BW P&L'!$H15:$J15) | AQ12: =SUM('CED P&L'!$H15:$J15) | AR12: =SUM('HB P&L'!$H15:$J15) | AS12: =SUM('KIN P&L'!$H15:$J15) | AT12: =SUM('MER P&L'!$H15:$J15) | AU12: =SUM('SST P&L'!$H15:$J15) | AV12: =SUM('HDN P&L'!$H15:$J15) | AW12: =SUM('NDN P&L'!$H15:$J15) | AX12: =SUM('SDN P&L'!$H15:$J15) | AY12: =SUM('LE P&L'!$H15:$J15) | AZ12: =SUM('WH P&L'!$H15:$J15) | BA12: =SUM('HS P&L'!$H15:$J15) | BB12: =SUM('FH P&L'!$H15:$J15) | BC12: =SUM('HAB P&L'!$H15:$J15) | BD12: =SUM('SALT P&L'!$H15:$J15) | BE12: =SUM('KNL HO P&L'!$H15:$J15)+SUM('CCL HO P&L'!$H15:$J15)+SUM('YBHN HO P&L'!$H15:$J15)+SUM('YBN HO P&L'!$H15:$J15)+SUM('Moe2 P&L'!$H15:$J15) | BF12: =SUM(AN12:BE12) | BG12: =SUM('ABA P&L'!$K15:$M15) | BH12: =SUM('BK P&L'!$K15:$M15) | BI12: =SUM('BW P&L'!$K15:$M15) | BJ12: =SUM('CED P&L'!$K15:$M15) | BK12: =SUM('HB P&L'!$K15:$M15) | BL12: =SUM('KIN P&L'!$K15:$M15) | BM12: =SUM('MER P&L'!$K15:$M15) | BN12: =SUM('SST P&L'!$K15:$M15) | BO12: =SUM('HDN P&L'!$K15:$M15) | BP12: =SUM('NDN P&L'!$K15:$M15) | BQ12: =SUM('SDN P&L'!$K15:$M15) | BR12: =SUM('LE P&L'!$K15:$M15) | BS12: =SUM('WH P&L'!$K15:$M15) | BT12: =SUM('HS P&L'!$K15:$M15) | BU12: =SUM('FH P&L'!$K15:$M15) | BV12: =SUM('HAB P&L'!$K15:$M15) | BW12: =SUM('SALT P&L'!$K15:$M15) | BX12: =SUM('KNL HO P&L'!$K15:$M15)+SUM('CCL HO P&L'!$K15:$M15)+SUM('YBHN HO P&L'!$K15:$M15)+SUM('YBN HO P&L'!$K15:$M15)+SUM('Moe2 P&L'!$K15:$M15) | BY12: =SUM(BG12:BX12) | BZ12: =BY12+BF12+AM12+T12
A13: Nursery Salaries | B13: =SUM('ABA P&L'!$B16:$D16) | C13: =SUM('BK P&L'!$B16:$D16) | D13: =SUM('BW P&L'!$B16:$D16) | E13: =SUM('CED P&L'!$B16:$D16) | F13: =SUM('HB P&L'!$B16:$D16) | G13: =SUM('KIN P&L'!$B16:$D16) | H13: =SUM('MER P&L'!$B16:$D16) | I13: =SUM('SST P&L'!$B16:$D16) | J13: =SUM('HDN P&L'!$B16:$D16) | K13: =SUM('NDN P&L'!$B16:$D16) | L13: =SUM('SDN P&L'!$B16:$D16) | M13: =SUM('LE P&L'!$B16:$D16) | N13: =SUM('WH P&L'!$B16:$D16) | O13: =SUM('HS P&L'!$B16:$D16) | P13: =SUM('FH P&L'!$B16:$D16) | Q13: =SUM('HAB P&L'!$B16:$D16) | R13: =SUM('SALT P&L'!$B16:$D16) | S13: =SUM('KNL HO P&L'!$B16:$D16)+SUM('CCL HO P&L'!$B16:$D16)+SUM('YBHN HO P&L'!$B16:$D16)+SUM('YBN HO P&L'!$B16:$D16)+SUM('Moe2 P&L'!$B16:$D16) | T13: =SUM(B13:S13) | U13: =SUM('ABA P&L'!$E16:$G16) | V13: =SUM('BK P&L'!$E16:$G16) | W13: =SUM('BW P&L'!$E16:$G16) | X13: =SUM('CED P&L'!$E16:$G16) | Y13: =SUM('HB P&L'!$E16:$G16) | Z13: =SUM('KIN P&L'!$E16:$G16) | AA13: =SUM('MER P&L'!$E16:$G16) | AB13: =SUM('SST P&L'!$E16:$G16) | AC13: =SUM('HDN P&L'!$E16:$G16) | AD13: =SUM('NDN P&L'!$E16:$G16) | AE13: =SUM('SDN P&L'!$E16:$G16) | AF13: =SUM('LE P&L'!$E16:$G16) | AG13: =SUM('WH P&L'!$E16:$G16) | AH13: =SUM('HS P&L'!$E16:$G16) | AI13: =SUM('FH P&L'!$E16:$G16) | AJ13: =SUM('HAB P&L'!$E16:$G16) | AK13: =SUM('SALT P&L'!$E16:$G16) | AL13: =SUM('KNL HO P&L'!$E16:$G16)+SUM('CCL HO P&L'!$E16:$G16)+SUM('YBHN HO P&L'!$E16:$G16)+SUM('YBN HO P&L'!$E16:$G16)+SUM('Moe2 P&L'!$E16:$G16) | AM13: =SUM(U13:AL13) | AN13: =SUM('ABA P&L'!$H16:$J16) | AO13: =SUM('BK P&L'!$H16:$J16) | AP13: =SUM('BW P&L'!$H16:$J16) | AQ13: =SUM('CED P&L'!$H16:$J16) | AR13: =SUM('HB P&L'!$H16:$J16) | AS13: =SUM('KIN P&L'!$H16:$J16) | AT13: =SUM('MER P&L'!$H16:$J16) | AU13: =SUM('SST P&L'!$H16:$J16) | AV13: =SUM('HDN P&L'!$H16:$J16) | AW13: =SUM('NDN P&L'!$H16:$J16) | AX13: =SUM('SDN P&L'!$H16:$J16) | AY13: =SUM('LE P&L'!$H16:$J16) | AZ13: =SUM('WH P&L'!$H16:$J16) | BA13: =SUM('HS P&L'!$H16:$J16) | BB13: =SUM('FH P&L'!$H16:$J16) | BC13: =SUM('HAB P&L'!$H16:$J16) | BD13: =SUM('SALT P&L'!$H16:$J16) | BE13: =SUM('KNL HO P&L'!$H16:$J16)+SUM('CCL HO P&L'!$H16:$J16)+SUM('YBHN HO P&L'!$H16:$J16)+SUM('YBN HO P&L'!$H16:$J16)+SUM('Moe2 P&L'!$H16:$J16) | BF13: =SUM(AN13:BE13) | BG13: =SUM('ABA P&L'!$K16:$M16) | BH13: =SUM('BK P&L'!$K16:$M16) | BI13: =SUM('BW P&L'!$K16:$M16) | BJ13: =SUM('CED P&L'!$K16:$M16) | BK13: =SUM('HB P&L'!$K16:$M16) | BL13: =SUM('KIN P&L'!$K16:$M16) | BM13: =SUM('MER P&L'!$K16:$M16) | BN13: =SUM('SST P&L'!$K16:$M16) | BO13: =SUM('HDN P&L'!$K16:$M16) | BP13: =SUM('NDN P&L'!$K16:$M16) | BQ13: =SUM('SDN P&L'!$K16:$M16) | BR13: =SUM('LE P&L'!$K16:$M16) | BS13: =SUM('WH P&L'!$K16:$M16) | BT13: =SUM('HS P&L'!$K16:$M16) | BU13: =SUM('FH P&L'!$K16:$M16) | BV13: =SUM('HAB P&L'!$K16:$M16) | BW13: =SUM('SALT P&L'!$K16:$M16) | BX13: =SUM('KNL HO P&L'!$K16:$M16)+SUM('CCL HO P&L'!$K16:$M16)+SUM('YBHN HO P&L'!$K16:$M16)+SUM('YBN HO P&L'!$K16:$M16)+SUM('Moe2 P&L'!$K16:$M16) | BY13: =SUM(BG13:BX13) | BZ13: =BY13+BF13+AM13+T13
A14: Nursery NI | B14: =SUM('ABA P&L'!$B17:$D17) | C14: =SUM('BK P&L'!$B17:$D17) | D14: =SUM('BW P&L'!$B17:$D17) | E14: =SUM('CED P&L'!$B17:$D17) | F14: =SUM('HB P&L'!$B17:$D17) | G14: =SUM('KIN P&L'!$B17:$D17) | H14: =SUM('MER P&L'!$B17:$D17) | I14: =SUM('SST P&L'!$B17:$D17) | J14: =SUM('HDN P&L'!$B17:$D17) | K14: =SUM('NDN P&L'!$B17:$D17) | L14: =SUM('SDN P&L'!$B17:$D17) | M14: =SUM('LE P&L'!$B17:$D17) | N14: =SUM('WH P&L'!$B17:$D17) | O14: =SUM('HS P&L'!$B17:$D17) | P14: =SUM('FH P&L'!$B17:$D17) | Q14: =SUM('HAB P&L'!$B17:$D17) | R14: =SUM('SALT P&L'!$B17:$D17) | S14: =SUM('KNL HO P&L'!$B17:$D17)+SUM('CCL HO P&L'!$B17:$D17)+SUM('YBHN HO P&L'!$B17:$D17)+SUM('YBN HO P&L'!$B17:$D17)+SUM('Moe2 P&L'!$B17:$D17) | T14: =SUM(B14:S14) | U14: =SUM('ABA P&L'!$E17:$G17) | V14: =SUM('BK P&L'!$E17:$G17) | W14: =SUM('BW P&L'!$E17:$G17) | X14: =SUM('CED P&L'!$E17:$G17) | Y14: =SUM('HB P&L'!$E17:$G17) | Z14: =SUM('KIN P&L'!$E17:$G17) | AA14: =SUM('MER P&L'!$E17:$G17) | AB14: =SUM('SST P&L'!$E17:$G17) | AC14: =SUM('HDN P&L'!$E17:$G17) | AD14: =SUM('NDN P&L'!$E17:$G17) | AE14: =SUM('SDN P&L'!$E17:$G17) | AF14: =SUM('LE P&L'!$E17:$G17) | AG14: =SUM('WH P&L'!$E17:$G17) | AH14: =SUM('HS P&L'!$E17:$G17) | AI14: =SUM('FH P&L'!$E17:$G17) | AJ14: =SUM('HAB P&L'!$E17:$G17) | AK14: =SUM('SALT P&L'!$E17:$G17) | AL14: =SUM('KNL HO P&L'!$E17:$G17)+SUM('CCL HO P&L'!$E17:$G17)+SUM('YBHN HO P&L'!$E17:$G17)+SUM('YBN HO P&L'!$E17:$G17)+SUM('Moe2 P&L'!$E17:$G17) | AM14: =SUM(U14:AL14) | AN14: =SUM('ABA P&L'!$H17:$J17) | AO14: =SUM('BK P&L'!$H17:$J17) | AP14: =SUM('BW P&L'!$H17:$J17) | AQ14: =SUM('CED P&L'!$H17:$J17) | AR14: =SUM('HB P&L'!$H17:$J17) | AS14: =SUM('KIN P&L'!$H17:$J17) | AT14: =SUM('MER P&L'!$H17:$J17) | AU14: =SUM('SST P&L'!$H17:$J17) | AV14: =SUM('HDN P&L'!$H17:$J17) | AW14: =SUM('NDN P&L'!$H17:$J17) | AX14: =SUM('SDN P&L'!$H17:$J17) | AY14: =SUM('LE P&L'!$H17:$J17) | AZ14: =SUM('WH P&L'!$H17:$J17) | BA14: =SUM('HS P&L'!$H17:$J17) | BB14: =SUM('FH P&L'!$H17:$J17) | BC14: =SUM('HAB P&L'!$H17:$J17) | BD14: =SUM('SALT P&L'!$H17:$J17) | BE14: =SUM('KNL HO P&L'!$H17:$J17)+SUM('CCL HO P&L'!$H17:$J17)+SUM('YBHN HO P&L'!$H17:$J17)+SUM('YBN HO P&L'!$H17:$J17)+SUM('Moe2 P&L'!$H17:$J17) | BF14: =SUM(AN14:BE14) | BG14: =SUM('ABA P&L'!$K17:$M17) | BH14: =SUM('BK P&L'!$K17:$M17) | BI14: =SUM('BW P&L'!$K17:$M17) | BJ14: =SUM('CED P&L'!$K17:$M17) | BK14: =SUM('HB P&L'!$K17:$M17) | BL14: =SUM('KIN P&L'!$K17:$M17) | BM14: =SUM('MER P&L'!$K17:$M17) | BN14: =SUM('SST P&L'!$K17:$M17) | BO14: =SUM('HDN P&L'!$K17:$M17) | BP14: =SUM('NDN P&L'!$K17:$M17) | BQ14: =SUM('SDN P&L'!$K17:$M17) | BR14: =SUM('LE P&L'!$K17:$M17) | BS14: =SUM('WH P&L'!$K17:$M17) | BT14: =SUM('HS P&L'!$K17:$M17) | BU14: =SUM('FH P&L'!$K17:$M17) | BV14: =SUM('HAB P&L'!$K17:$M17) | BW14: =SUM('SALT P&L'!$K17:$M17) | BX14: =SUM('KNL HO P&L'!$K17:$M17)+SUM('CCL HO P&L'!$K17:$M17)+SUM('YBHN HO P&L'!$K17:$M17)+SUM('YBN HO P&L'!$K17:$M17)+SUM('Moe2 P&L'!$K17:$M17) | BY14: =SUM(BG14:BX14) | BZ14: =BY14+BF14+AM14+T14
A15: Nursery Pension | B15: =SUM('ABA P&L'!$B18:$D18) | C15: =SUM('BK P&L'!$B18:$D18) | D15: =SUM('BW P&L'!$B18:$D18) | E15: =SUM('CED P&L'!$B18:$D18) | F15: =SUM('HB P&L'!$B18:$D18) | G15: =SUM('KIN P&L'!$B18:$D18) | H15: =SUM('MER P&L'!$B18:$D18) | I15: =SUM('SST P&L'!$B18:$D18) | J15: =SUM('HDN P&L'!$B18:$D18) | K15: =SUM('NDN P&L'!$B18:$D18) | L15: =SUM('SDN P&L'!$B18:$D18) | M15: =SUM('LE P&L'!$B18:$D18) | N15: =SUM('WH P&L'!$B18:$D18) | O15: =SUM('HS P&L'!$B18:$D18) | P15: =SUM('FH P&L'!$B18:$D18) | Q15: =SUM('HAB P&L'!$B18:$D18) | R15: =SUM('SALT P&L'!$B18:$D18) | S15: =SUM('KNL HO P&L'!$B18:$D18)+SUM('CCL HO P&L'!$B18:$D18)+SUM('YBHN HO P&L'!$B18:$D18)+SUM('YBN HO P&L'!$B18:$D18)+SUM('Moe2 P&L'!$B18:$D18) | T15: =SUM(B15:S15) | U15: =SUM('ABA P&L'!$E18:$G18) | V15: =SUM('BK P&L'!$E18:$G18) | W15: =SUM('BW P&L'!$E18:$G18) | X15: =SUM('CED P&L'!$E18:$G18) | Y15: =SUM('HB P&L'!$E18:$G18) | Z15: =SUM('KIN P&L'!$E18:$G18) | AA15: =SUM('MER P&L'!$E18:$G18) | AB15: =SUM('SST P&L'!$E18:$G18) | AC15: =SUM('HDN P&L'!$E18:$G18) | AD15: =SUM('NDN P&L'!$E18:$G18) | AE15: =SUM('SDN P&L'!$E18:$G18) | AF15: =SUM('LE P&L'!$E18:$G18) | AG15: =SUM('WH P&L'!$E18:$G18) | AH15: =SUM('HS P&L'!$E18:$G18) | AI15: =SUM('FH P&L'!$E18:$G18) | AJ15: =SUM('HAB P&L'!$E18:$G18) | AK15: =SUM('SALT P&L'!$E18:$G18) | AL15: =SUM('KNL HO P&L'!$E18:$G18)+SUM('CCL HO P&L'!$E18:$G18)+SUM('YBHN HO P&L'!$E18:$G18)+SUM('YBN HO P&L'!$E18:$G18)+SUM('Moe2 P&L'!$E18:$G18) | AM15: =SUM(U15:AL15) | AN15: =SUM('ABA P&L'!$H18:$J18) | AO15: =SUM('BK P&L'!$H18:$J18) | AP15: =SUM('BW P&L'!$H18:$J18) | AQ15: =SUM('CED P&L'!$H18:$J18) | AR15: =SUM('HB P&L'!$H18:$J18) | AS15: =SUM('KIN P&L'!$H18:$J18) | AT15: =SUM('MER P&L'!$H18:$J18) | AU15: =SUM('SST P&L'!$H18:$J18) | AV15: =SUM('HDN P&L'!$H18:$J18) | AW15: =SUM('NDN P&L'!$H18:$J18) | AX15: =SUM('SDN P&L'!$H18:$J18) | AY15: =SUM('LE P&L'!$H18:$J18) | AZ15: =SUM('WH P&L'!$H18:$J18) | BA15: =SUM('HS P&L'!$H18:$J18) | BB15: =SUM('FH P&L'!$H18:$J18) | BC15: =SUM('HAB P&L'!$H18:$J18) | BD15: =SUM('SALT P&L'!$H18:$J18) | BE15: =SUM('KNL HO P&L'!$H18:$J18)+SUM('CCL HO P&L'!$H18:$J18)+SUM('YBHN HO P&L'!$H18:$J18)+SUM('YBN HO P&L'!$H18:$J18)+SUM('Moe2 P&L'!$H18:$J18) | BF15: =SUM(AN15:BE15) | BG15: =SUM('ABA P&L'!$K18:$M18) | BH15: =SUM('BK P&L'!$K18:$M18) | BI15: =SUM('BW P&L'!$K18:$M18) | BJ15: =SUM('CED P&L'!$K18:$M18) | BK15: =SUM('HB P&L'!$K18:$M18) | BL15: =SUM('KIN P&L'!$K18:$M18) | BM15: =SUM('MER P&L'!$K18:$M18) | BN15: =SUM('SST P&L'!$K18:$M18) | BO15: =SUM('HDN P&L'!$K18:$M18) | BP15: =SUM('NDN P&L'!$K18:$M18) | BQ15: =SUM('SDN P&L'!$K18:$M18) | BR15: =SUM('LE P&L'!$K18:$M18) | BS15: =SUM('WH P&L'!$K18:$M18) | BT15: =SUM('HS P&L'!$K18:$M18) | BU15: =SUM('FH P&L'!$K18:$M18) | BV15: =SUM('HAB P&L'!$K18:$M18) | BW15: =SUM('SALT P&L'!$K18:$M18) | BX15: =SUM('KNL HO P&L'!$K18:$M18)+SUM('CCL HO P&L'!$K18:$M18)+SUM('YBHN HO P&L'!$K18:$M18)+SUM('YBN HO P&L'!$K18:$M18)+SUM('Moe2 P&L'!$K18:$M18) | BY15: =SUM(BG15:BX15) | BZ15: =BY15+BF15+AM15+T15
A16: Uniform | B16: =SUM('ABA P&L'!$B19:$D19) | C16: =SUM('BK P&L'!$B19:$D19) | D16: =SUM('BW P&L'!$B19:$D19) | E16: =SUM('CED P&L'!$B19:$D19) | F16: =SUM('HB P&L'!$B19:$D19) | G16: =SUM('KIN P&L'!$B19:$D19) | H16: =SUM('MER P&L'!$B19:$D19) | I16: =SUM('SST P&L'!$B19:$D19) | J16: =SUM('HDN P&L'!$B19:$D19) | K16: =SUM('NDN P&L'!$B19:$D19) | L16: =SUM('SDN P&L'!$B19:$D19) | M16: =SUM('LE P&L'!$B19:$D19) | N16: =SUM('WH P&L'!$B19:$D19) | O16: =SUM('HS P&L'!$B19:$D19) | P16: =SUM('FH P&L'!$B19:$D19) | Q16: =SUM('HAB P&L'!$B19:$D19) | R16: =SUM('SALT P&L'!$B19:$D19) | S16: =SUM('KNL HO P&L'!$B19:$D19)+SUM('CCL HO P&L'!$B19:$D19)+SUM('YBHN HO P&L'!$B19:$D19)+SUM('YBN HO P&L'!$B19:$D19)+SUM('Moe2 P&L'!$B19:$D19) | T16: =SUM(B16:S16) | U16: =SUM('ABA P&L'!$E19:$G19) | V16: =SUM('BK P&L'!$E19:$G19) | W16: =SUM('BW P&L'!$E19:$G19) | X16: =SUM('CED P&L'!$E19:$G19) | Y16: =SUM('HB P&L'!$E19:$G19) | Z16: =SUM('KIN P&L'!$E19:$G19) | AA16: =SUM('MER P&L'!$E19:$G19) | AB16: =SUM('SST P&L'!$E19:$G19) | AC16: =SUM('HDN P&L'!$E19:$G19) | AD16: =SUM('NDN P&L'!$E19:$G19) | AE16: =SUM('SDN P&L'!$E19:$G19) | AF16: =SUM('LE P&L'!$E19:$G19) | AG16: =SUM('WH P&L'!$E19:$G19) | AH16: =SUM('HS P&L'!$E19:$G19) | AI16: =SUM('FH P&L'!$E19:$G19) | AJ16: =SUM('HAB P&L'!$E19:$G19) | AK16: =SUM('SALT P&L'!$E19:$G19) | AL16: =SUM('KNL HO P&L'!$E19:$G19)+SUM('CCL HO P&L'!$E19:$G19)+SUM('YBHN HO P&L'!$E19:$G19)+SUM('YBN HO P&L'!$E19:$G19)+SUM('Moe2 P&L'!$E19:$G19) | AM16: =SUM(U16:AL16) | AN16: =SUM('ABA P&L'!$H19:$J19) | AO16: =SUM('BK P&L'!$H19:$J19) | AP16: =SUM('BW P&L'!$H19:$J19) | AQ16: =SUM('CED P&L'!$H19:$J19) | AR16: =SUM('HB P&L'!$H19:$J19) | AS16: =SUM('KIN P&L'!$H19:$J19) | AT16: =SUM('MER P&L'!$H19:$J19) | AU16: =SUM('SST P&L'!$H19:$J19) | AV16: =SUM('HDN P&L'!$H19:$J19) | AW16: =SUM('NDN P&L'!$H19:$J19) | AX16: =SUM('SDN P&L'!$H19:$J19) | AY16: =SUM('LE P&L'!$H19:$J19) | AZ16: =SUM('WH P&L'!$H19:$J19) | BA16: =SUM('HS P&L'!$H19:$J19) | BB16: =SUM('FH P&L'!$H19:$J19) | BC16: =SUM('HAB P&L'!$H19:$J19) | BD16: =SUM('SALT P&L'!$H19:$J19) | BE16: =SUM('KNL HO P&L'!$H19:$J19)+SUM('CCL HO P&L'!$H19:$J19)+SUM('YBHN HO P&L'!$H19:$J19)+SUM('YBN HO P&L'!$H19:$J19)+SUM('Moe2 P&L'!$H19:$J19) | BF16: =SUM(AN16:BE16) | BG16: =SUM('ABA P&L'!$K19:$M19) | BH16: =SUM('BK P&L'!$K19:$M19) | BI16: =SUM('BW P&L'!$K19:$M19) | BJ16: =SUM('CED P&L'!$K19:$M19) | BK16: =SUM('HB P&L'!$K19:$M19) | BL16: =SUM('KIN P&L'!$K19:$M19) | BM16: =SUM('MER P&L'!$K19:$M19) | BN16: =SUM('SST P&L'!$K19:$M19) | BO16: =SUM('HDN P&L'!$K19:$M19) | BP16: =SUM('NDN P&L'!$K19:$M19) | BQ16: =SUM('SDN P&L'!$K19:$M19) | BR16: =SUM('LE P&L'!$K19:$M19) | BS16: =SUM('WH P&L'!$K19:$M19) | BT16: =SUM('HS P&L'!$K19:$M19) | BU16: =SUM('FH P&L'!$K19:$M19) | BV16: =SUM('HAB P&L'!$K19:$M19) | BW16: =SUM('SALT P&L'!$K19:$M19) | BX16: =SUM('KNL HO P&L'!$K19:$M19)+SUM('CCL HO P&L'!$K19:$M19)+SUM('YBHN HO P&L'!$K19:$M19)+SUM('YBN HO P&L'!$K19:$M19)+SUM('Moe2 P&L'!$K19:$M19) | BY16: =SUM(BG16:BX16) | BZ16: =BY16+BF16+AM16+T16
